Workbook

Sheet Status
C2: W=Working, C=Complete, R=Risk
B3: Target | C3: 45408 | D3: 45408 | E3: 45443 | F3: 45460 | G3: 45460 | H3: 45586
B4: INTERFACE | C4: ANA-50 Functional Spec | D4: TAR-040 Technical Spec | E4: DES-020 Test Env. Ready | F4: TES-070 Test Plan/Script | G4: TES-070 Test Data | H4: Test Signoff | I4: Latest Comment | J4: Next Steps(s)
B5: Concur Invoice | C5: W | D5: W | E5: W | F5: Laying out unit tests | I5: [Jun-7] We have 3 test POs. Need the business to enter and receive the POs. Then Shared Services will enter the vendor invoice to complete the 3-way match to test the XML BOD back to M3. [Jun-13] Sent email to team asking them to complete test
B6: Concur Travel & Expense
B7: Salesforce | C7: C | D7: C | E7: W | F7: W | G7: W | I7: [Jun-14] Next step is to review test plan with Torborjn
B8: SPS Commerce EDI | C8: W | D8: W | E8: W | I8: [Jun-14] Rich Ospry engaged to assist with technical information, has already started providing information needed to SPS Commerce. [June28 Matt] ANA ready for Barnes review/approval. | J8: [Apr-26] - Kick off meeting with SPS Commerce Apr-30 10:30a EDT. Cheska set up weekly meetings.
B9: PNC Bank (AR) | C9: R | D9: W | I9: [Jun-14] Meeting scheduled Mon Jun 17 to see what additional is needed to complete the ANA and begin setup of test enironement | J9: [Apr-26] Meeting scheduled for May-1 8a EDT with Shared Service, JBA ERP, Infor to discuss process detail
B10: Shared Service (AP) Bank of America | C10: R | D10: W | I10: [Jun-14] Meeting scheduled Mon Jun 17 to see what additional is needed to complete the ANA and begin setup of test enironement | J10: [Apr-26] Meeting scheduled for May-1 8a EDT with Shared Service, JBA ERP, Infor to discuss process detail
B11: Cforia | C11: R | D11: W | E11: W | I11: [Jun-14] Kevin has started query to provide open A/R balance. Amy McGuire to run open balance out of M3. We may need to get Kevin/Dean access to run report out of M3 as open balance can change | J11: [Apr-26] Kevin to refine queries for output files. Work with Cforia to send to test environment.
B12: Fedex | C12: C | D12: W | E12: W | I12: [Jun-14] Jack Adoline reviewing in place of Aaron departure. | J12: [Apr-26] Connectivity to test/prod workstations | K12: Export to correct location, FEDEX>IN, UPS>IN. Can we send prod to both current ERP and M3
B13: UPS | C13: C | D13: W | E13: W | I13: [Jun-14] Jack Adoline reviewing in place of Aaron departure. | J13: [Apr-26] Connectivity to test/prod workstations
B14: Credit Card Processing - CenPOS | C14: W | D14: W | E14: W | I14: [May-15] Uploaded demo environment connection information from CenPOS to Infor site and notified team. Next step is to plug into interface and verify works with M3 test environment. Need to meet with Optimziely vendor CONSID to determine steps needed to connect to e-commerce/Optimizely | J14: [Apr-26] Seems we're already an Evalon\US Bank customer. Work with reps to get gateway access. | K14: CenPOS setup screen from Daniel. Test account setup.
B15: Optimizely | C15: C | D15: W | E15: W | I15: [May-15] ANA under review, questions being answered. Test environment for data feeds to be setup early June. ANA for orders was written. ANA [June28 Matt] Optimizely ANA approved by Amy B. | J15: [Apr-26] Dean to put updated specification on Infor sharepoint.

Sheet Sheet1
A3: Count of Interface ID | B3: Column Labels
A4: Row Labels | B4: 3 - Speccing (ANA-050) | C4: 4 - Tech Spec (TAR-040) | D4: 5 - Development | E4: 6 - Development Testing | F4: Business Testing | G4: (blank) | H4: Grand Total
A5: BoA Shared Service (AP) | D5: 2 | H5: 2
A6: CenPos | F6: 2 | H6: 2
A7: Cforia | B7: 5 | H7: 5
A8: Concur | B8: 2 | C8: 3 | E8: 1 | H8: 6
A9: Fedex | C9: 2 | H9: 2
A10: Optimizely | B10: 5 | C10: 1 | H10: 6
A11: Salesforce | F11: 2 | H11: 2
A12: SPS Commerce EDI | B12: 1 | C12: 4 | E12: 1 | G12: 1 | H12: 7
A13: UPS | C13: 2 | H13: 2
A14: (SPS) PNC Bank (AR) | B14: 2 | H14: 2
A15: PNC Bank (AR) (SPS) | B15: 1 | H15: 1
A16: Grand Total | B16: 16 | C16: 12 | D16: 2 | E16: 2 | F16: 4 | G16: 1 | H16: 37
B21: m | C21: t | D21: w | E21: th | F21: f
B22: BoA | C22: SPS | D22: ups | E22: optimizely
B23: Cforia | D23: fedex | E23: CenPos
B24: Concur
B25: (SPS) PNC Bank (AR)
B26: PNC Bank (AR) (SPS)

Sheet List
A1: Partner/System | B1: Interface ID | C1: Interface | D1: 100% Complete | E1: Stream | F1: Accountable | G1: Barnes Functional | H1: Barnes technical | I1: Status | J1: Action | K1: Process Status | L1: SPS Status | M1: SPS Variable | N1: Totals # of days | O1: SPS + Status | P1: Estimated Completion Date | Q1: Infor FC | R1: 3P Development | S1: Functional Spec ANA-050 | T1: Action - Approved | U1: ANA-050 Date Due | V1: Date Complete | W1: Infor Tech Consultant | X1: Interface spec TAR-040 | Y1: Action | Z1: Date Approved | AA1: Date Due | AB1: Date Completed | AC1: Dev Start | AD1: Dev Complate | AE1: TES-070 | AF1: Testing | AG1: Action | AH1: Testing Start | AI1: Testing Completed | AJ1: DES-030 Deployment | AK1: DES-030 Notes | AL1: Comment/Notes | AM1: Next action, who and date
A2: (SPS) PNC Bank (AR) | B2: FIN001 | C2: PNC Lockbox EDI 823 checks | D2: No | E2: Finance | F2: Infor | G2: Kim | H2: Jeff | I2: Pre Development | J2: SPS | K2: Speccing (ANA-050) | N2: =VLOOKUP(K2,'Drop Down'!$I$2:$K$14,3,FALSE) -> 30 | O2: =SUM(M2:N2) -> 30 | P2: =TODAY()+O2 -> 46325 | Q2: Dennis | S2: WIP | T2: Kim | U2: 45562 | W2: TBD | AL2: 09/16 Dennis to completing review of EDI 823 and 820 mappings by EOD 09/20. ANA-050 to follow completion approx 09/25. 08/27 Dennis had a meeting with PNC and Barnes and SPS. PNC Bank discussed the scope with Barnes 08/08 Dennis initiated weekly recurring calls to track progress. Dean to get the JBA and PNC together to discuss the current process and required specs. | AM2: PNC Bank(Wendella) & SPS Commerce (Courney/Zach) +Dennis for ANA-050 | AN2: Testing in progress by Barnes | AQ2: =CONCATENATE(B2, " ", A2, " ",C2, " ", E2) -> FIN001 (SPS) PNC Bank (AR) PNC Lockbox EDI 823 checks Finance | AR2: CON001 Concur SupplierInvoice Finance
A3: (SPS) PNC Bank (AR) | B3: FIN005 | C3: PNC Lockbox EDI820 flat file ACH ad wires | D3: No | E3: Finance | F3: Infor | G3: Kim | H3: Jeff | I3: Pre Development | J3: SPS | K3: Speccing (ANA-050) | N3: =VLOOKUP(K3,'Drop Down'!$I$2:$K$14,3,FALSE) -> 30 | O3: =SUM(M3:N3) -> 30 | P3: =TODAY()+O3 -> 46325 | Q3: Dennis | S3: WIP | U3: 45562 | W3: TBD | AL3: 09/16 Dennis to completing review of EDI 823 and 820 mappings by EOD 09/20. ANA-050 to follow completion approx 09/25. 08/27 Dennis had a meeting with PNC and Barnes and SPS. PNC Bank discussed the scope with Barnes New file that we found out 20230123, sample file in share point, modified for barnes, we should get stdEDI 820 from bank. Via SPS Commerce? | AM3: PNC Bank(Wendella) & SPS Commerce (Courney/Zach) +Dennis for ANA-050 | AQ3: =CONCATENATE(B3, " ", A3, " ",C3, " ", E3) -> FIN005 (SPS) PNC Bank (AR) PNC Lockbox EDI820 flat file ACH ad wires Finance | AR3: CON002 Concur Goods Receipts Finance
A4: BoA Shared Service (AP) | B4: FIN003 | C4: Check Run Header | D4: No | E4: Finance | F4: Infor | G4: Kim | H4: Jeff | I4: Pending Approval | J4: Finance | K4: Development | N4: =VLOOKUP(K4,'Drop Down'!$I$2:$K$14,3,FALSE) -> 15 | O4: =SUM(M4:N4) -> 15 | P4: =TODAY()+O4 -> 46310 | Q4: Carlo | S4: Completed | W4: Isaiah John Tolentino | X4: Completed | AC4: 45548 | AD4: 45576 | AL4: September 25. Dev almost complete. Sent to Carlo for validation. Carlo need to reply ASAP for dev to continue. Sep 13. Dev started. Redy by Oct 11 8/27 - Carlo sent ANA-50 for approval to Finance 20 Aug - Dean needs to approve Ahmed start func spec after PNC | AM4: Carlo Alcazar | AQ4: =CONCATENATE(B4, " ", A4, " ",C4, " ", E4) -> FIN003 BoA Shared Service (AP) Check Run Header Finance | AR4: CON003 Concur PO Header Finance
A5: BoA Shared Service (AP) | B5: FIN004 | C5: Check Run Details | D5: No | E5: Finance | F5: Infor | G5: Kim | H5: Jeff | I5: Pending Approval | J5: Finance | K5: Development | N5: =VLOOKUP(K5,'Drop Down'!$I$2:$K$14,3,FALSE) -> 15 | O5: =SUM(M5:N5) -> 15 | P5: =TODAY()+O5 -> 46310 | Q5: Carlo | S5: Completed | W5: Isaiah John Tolentino | X5: Completed | AC5: 45548 | AD5: 45576 | AL5: September 25. Dev almost complete. Sent to Carlo for validation. Carlo need to reply ASAP for dev to continue. Sep 13. Dev started. Redy by Oct 11 8/27 - Carlo sent ANA-50 for approval to Finance 20 Aug - Dean needs to approve Ahmed start func spec after PNC | AM5: Carlo Alcazar | AQ5: =CONCATENATE(B5, " ", A5, " ",C5, " ", E5) -> FIN004 BoA Shared Service (AP) Check Run Details Finance | AR5: CON004 Concur PO Lines Finance
A6: CenPos | B6: CNP001 | C6: Payment Authorization | D6: Yes | E6: OTC | F6: Infor | G6: Amy B / Louis | H6: Dean | I6: Testing | J6: Finance | K6: Business Testing | N6: =VLOOKUP(K6,'Drop Down'!$I$2:$K$14,3,FALSE) -> 2 | O6: =SUM(M6:N6) -> 2 | P6: =TODAY()+O6 -> 46297 | Q6: Hubert | S6: NA | W6: N/A | X6: NA | AK6: NA | AL6: August - Infor Standard Integration (OOB) Unknown date > existing Infor CenPos code. this team to verify that it works for Barnes. Hubert/Cheska to test CenPos. 7/18. only Dev person is needed if Hubert/Cheska see need for a change. Unknown date > H5 script, manage in UI. Waiting for contact at Barnes and Worldpay | AM6: Infor (Hubert/Daniel) | AQ6: =CONCATENATE(B6, " ", A6, " ",C6, " ", E6) -> CNP001 CenPos Payment Authorization OTC | AR6: CON005 Concur Vendor Infor Finance
A7: CenPos | B7: CNP002 | C7: Payment Capture | D7: Yes | E7: OTC | F7: Infor | G7: Amy B / Louis | H7: Dean | I7: Testing | J7: Finance | K7: Business Testing | N7: =VLOOKUP(K7,'Drop Down'!$I$2:$K$14,3,FALSE) -> 2 | O7: =SUM(M7:N7) -> 2 | P7: =TODAY()+O7 -> 46297 | Q7: Hubert | S7: NA | W7: N/A | X7: NA | AK7: NA | AL7: August - Infor Standard Integration (OOB) Unknown date > existing Infor CenPos code. this team to verify that it works for Barnes. Hubert/Cheska to test CenPos. 7/18. only Dev person is needed if Hubert/Cheska see need for a change. H5 script, manage in UI. Waiting for contact at Barnes and Worldpay | AM7: Infor (Hubert/Daniel) | AN7: Testing in progress by Barnes | AQ7: =CONCATENATE(B7, " ", A7, " ",C7, " ", E7) -> CNP002 CenPos Payment Capture OTC | AR7: SFDC01 Salesforce Item OTC
A8: Salesforce | B8: SFDC02 | C8: Customer | E8: OTC | F8: Barnes | G8: Robert | H8: Torbjörn | I8: Out of Scope | K8: Out of Scope | N8: =VLOOKUP(K8,'Drop Down'!$I$2:$K$14,3,FALSE) -> 60 | O8: =SUM(M8:N8) -> 60 | P8: =TODAY()+O8 -> 46355 | S8: NA | T8: 45349 | W8: Martin | Y8: Martin | AH8: Daniel/Martin | AK8: Martin | AL8: ANA-050 started ready for review Feb 2 20240126: Meeting anc coclusion is no integration between M3 ans SF. All is going between SF _ Azure •3/20 no longer needed | AM8: Martin | AQ8: =CONCATENATE(B8, " ", A8, " ",C8, " ", E8) -> SFDC02 Salesforce Customer OTC | AR8: SFDC02 Salesforce Customer OTC
A9: Salesforce | B9: SFDC03 | C9: ShipToPartyMaster / Addresses | E9: OTC | F9: Barnes | G9: Robert | H9: Torbjörn | I9: Out of Scope | K9: Out of Scope | N9: =VLOOKUP(K9,'Drop Down'!$I$2:$K$14,3,FALSE) -> 60 | O9: =SUM(M9:N9) -> 60 | P9: =TODAY()+O9 -> 46355 | S9: NA | T9: 45349 | W9: Martin | Y9: Martin | AH9: Daniel/Martin | AK9: Martin | AL9: Credti limit was Removed from scope during CRP. Payment terms on Customer is enought, replaced by ShipToPartyMaster / Addresses. Martin start ANA-050 Jan 29 20240126: Meeting and conclusion is this will not be done in M3CE. Barnes handle the int between SF- AZureDB •3/20 no longer needed | AM9: Martin | AQ9: =CONCATENATE(B9, " ", A9, " ",C9, " ", E9) -> SFDC03 Salesforce ShipToPartyMaster / Addresses OTC | AR9: SFDC03 Salesforce Customer Credit OTC
A10: Cforia | B10: CFO001 | C10: Customer Payments & Credits | D10: No | E10: Finance | F10: Barnes | G10: Kim | H10: Dean | I10: Not Started | K10: Speccing (ANA-050) | N10: =VLOOKUP(K10,'Drop Down'!$I$2:$K$14,3,FALSE) -> 30 | O10: =SUM(M10:N10) -> 30 | P10: =TODAY()+O10 -> 46325 | Q10: Rachelle | S10: WIP | U10: 45565 | W10: Martin | Y10: Dean | AK10: Dean | AL10: 09/16 New Infor finance resource Rachelle Malahito onboarded this week to start work on CFORIA ANA-050 Barnes Kevin Alexander starting on this. Barnes Cforia test environment | AN10: Testing in progress by Barnes | AQ10: =CONCATENATE(B10, " ", A10, " ",C10, " ", E10) -> CFO001 Cforia Customer Payments & Credits Finance | AR10: SFDC04 Salesforce Item Pricing OTC
A11: Cforia | B11: CFO002 | C11: Customer Order | D11: No | E11: Finance | F11: Barnes | G11: Kim | H11: Dean | I11: Not Started | K11: Speccing (ANA-050) | N11: =VLOOKUP(K11,'Drop Down'!$I$2:$K$14,3,FALSE) -> 30 | O11: =SUM(M11:N11) -> 30 | P11: =TODAY()+O11 -> 46325 | Q11: Rachelle | S11: WIP | U11: 45565 | W11: Martin | Y11: Dean | AK11: Dean | AL11: 09/16 New Infor finance resource Rachelle Malahito onboarded this week to start work on CFORIA ANA-050 Barnes Kevin Alexander starting on this | AQ11: =CONCATENATE(B11, " ", A11, " ",C11, " ", E11) -> CFO002 Cforia Customer Order Finance | AR11: EDI001 SPS Commerce EDI EDI Sales Order OTC
A12: Cforia | B12: CFO003 | C12: Customer Master | D12: No | E12: Finance | F12: Barnes | G12: Kim | H12: Dean | I12: Not Started | K12: Speccing (ANA-050) | N12: =VLOOKUP(K12,'Drop Down'!$I$2:$K$14,3,FALSE) -> 30 | O12: =SUM(M12:N12) -> 30 | P12: =TODAY()+O12 -> 46325 | Q12: Rachelle | S12: WIP | U12: 45565 | W12: Martin | Y12: Dean | AK12: Dean | AL12: 09/16 New Infor finance resource Rachelle Malahito onboarded this week to start work on CFORIA ANA-050 Barnes Kevin Alexander starting on this | AQ12: =CONCATENATE(B12, " ", A12, " ",C12, " ", E12) -> CFO003 Cforia Customer Master Finance | AR12: EDI002 SPS Commerce EDI EDI Shipment OTC
A13: Cforia | B13: CFO004 | C13: Invoice Payment History | D13: No | E13: Finance | F13: Barnes | G13: Kim | H13: Dean | I13: Not Started | K13: Speccing (ANA-050) | N13: =VLOOKUP(K13,'Drop Down'!$I$2:$K$14,3,FALSE) -> 30 | O13: =SUM(M13:N13) -> 30 | P13: =TODAY()+O13 -> 46325 | Q13: Rachelle | S13: WIP | U13: 45565 | W13: Martin | Y13: Dean | AK13: Dean | AL13: 09/16 New Infor finance resource Rachelle Malahito onboarded this week to start work on CFORIA ANA-050 Barnes Kevin Alexander starting on this | AQ13: =CONCATENATE(B13, " ", A13, " ",C13, " ", E13) -> CFO004 Cforia Invoice Payment History Finance | AR13: EDI003 SPS Commerce EDI EDI Sales Order Ack OTC
A14: Cforia | B14: CFO005 | C14: Invoice Copies IDM (PDF) | D14: No | E14: Finance | F14: Barnes | G14: Kim | H14: Dean | I14: Not Started | K14: Speccing (ANA-050) | N14: =VLOOKUP(K14,'Drop Down'!$I$2:$K$14,3,FALSE) -> 30 | O14: =SUM(M14:N14) -> 30 | P14: =TODAY()+O14 -> 46325 | Q14: Rachelle | S14: WIP | U14: 45565 | W14: Martin | Y14: Karin | AK14: Karin | AL14: 09/16 New Infor finance resource Rachelle Malahito onboarded this week to start work on CFORIA ANA-050 Barnes Kevin Alexander starting on this | AQ14: =CONCATENATE(B14, " ", A14, " ",C14, " ", E14) -> CFO005 Cforia Invoice Copies IDM (PDF) Finance | AR14: EDI004 SPS Commerce EDI EDI Invoice OTC
A15: Concur | B15: CON002 | C15: Goods Receipts | D15: No | E15: Finance | F15: Barnes | G15: Kim | H15: Kevin | I15: Pre Development | K15: Development Testing | N15: =VLOOKUP(K15,'Drop Down'!$I$2:$K$14,3,FALSE) -> 12 | O15: =SUM(M15:N15) -> 12 | P15: =TODAY()+O15 -> 46307 | Q15: Dennis | S15: WIP | U15: 45555 | W15: Martin | Y15: Dean | AF15: Business | AK15: Dean | AL15: 09/16 Dennis to complete re-write of ANA-050 by 09/20. This ANA-050 consolidates CON001 002 003 004 and 005 into one document. 8/27 - Currently being tested by Amy/Kimberly Aug 20 Jimmy asked Dean for a test meeting. Metrics from Kim on current ASR match rate (cases we can improve in M3). Unit test plan - try full cycle. Dean to setup meeting Kim/Kevin 8/23: Meeting scheduled for 8/26 | AM15: Start week feb 5 | AQ15: =CONCATENATE(B15, " ", A15, " ",C15, " ", E15) -> CON002 Concur Goods Receipts Finance | AR15: EDI005 SPS Commerce EDI EDI Shipment Schedule EDI 862 OTC
A16: Concur | B16: CON003 | C16: PO Header | D16: No | E16: Finance | F16: Barnes | G16: Kim | H16: Kevin | I16: Pre Development | K16: Tech Spec (TAR-040) | N16: =VLOOKUP(K16,'Drop Down'!$I$2:$K$14,3,FALSE) -> 25 | O16: =SUM(M16:N16) -> 25 | P16: =TODAY()+O16 -> 46320 | Q16: Dennis | S16: WIP | U16: 45555 | W16: Martin | Y16: Dean | AF16: Business | AK16: Dean | AL16: 09/16 Dennis to complete re-write of ANA-050 by 09/20. This ANA-050 consolidates CON001 002 003 004 and 005 into one document. 8/27 - Currently being tested by Amy/Kimberly Aug 20 Jimmy asked Dean for a test meeting. Metrics from Kim on current ASR match rate (cases we can improve in M3). Unit test plan - try full cycle. Dean to setup meeting Kim/Kevin 8/23: Meeting scheduled for 8/26
A17: Concur | B17: CON004 | C17: PO Lines | D17: No | E17: Finance | F17: Barnes | G17: Kim | H17: Kevin | I17: Pre Development | K17: Tech Spec (TAR-040) | N17: =VLOOKUP(K17,'Drop Down'!$I$2:$K$14,3,FALSE) -> 25 | O17: =SUM(M17:N17) -> 25 | P17: =TODAY()+O17 -> 46320 | Q17: Dennis | S17: WIP | U17: 45555 | W17: Martin | Y17: Dean | AF17: Business | AK17: Dean | AL17: 09/16 Dennis to complete re-write of ANA-050 by 09/20. This ANA-050 consolidates CON001 002 003 004 and 005 into one document. 8/27 - Currently being tested by Amy/Kimberly Aug 20 Jimmy asked Dean for a test meeting. Metrics from Kim on current ASR match rate (cases we can improve in M3). Unit test plan - try full cycle. Dean to setup meeting Kim/Kevin 8/23: Meeting scheduled for 8/26 | AQ17: =CONCATENATE(B17, " ", A17, " ",C17, " ", E17) -> CON004 Concur PO Lines Finance | AR17: EDI006 SPS Commerce EDI Planning Schedule EDI 830 OTC
A18: SPS Commerce EDI | B18: EDI007 | C18: Application Advice EDI 824 | E18: OTC | F18: Infor | G18: Melissa | H18: Jeff | I18: Out of Scope | K18: Out of Scope | N18: =VLOOKUP(K18,'Drop Down'!$I$2:$K$14,3,FALSE) -> 60 | O18: =SUM(M18:N18) -> 60 | P18: =TODAY()+O18 -> 46355 | Q18: Cheska | S18: N/A | T18: N/A | U18: N/A | V18: N/A | W18: Martin | X18: N/A | Z18: N/A | AA18: N/A | AB18: N/A | AI18: N/A | AJ18: N/A | AK18: N/A | AL18: 8/6/24: this is not part of the SPS Contract so no dev on any side. Review 824, 860 and 997 and in SPS Commerce Portal so no DEV on infor side •Barnes working to get contract with SPS | AM18: N/A | AQ18: =CONCATENATE(B18, " ", A18, " ",C18, " ", E18) -> EDI007 SPS Commerce EDI Application Advice EDI 824 OTC | AR18: EDI007 SPS Commerce EDI Application Advice EDI 824 OTC
A19: Concur | B19: CON005 | C19: Vendor Infor | D19: No | E19: Finance | F19: Barnes | G19: Kim | H19: Kevin | I19: Pre Development | K19: Tech Spec (TAR-040) | N19: =VLOOKUP(K19,'Drop Down'!$I$2:$K$14,3,FALSE) -> 25 | O19: =SUM(M19:N19) -> 25 | P19: =TODAY()+O19 -> 46320 | Q19: Dennis | S19: WIP | U19: 45555 | W19: Martin | Y19: Dean | AF19: Business | AK19: Dean | AL19: 09/16 Dennis to complete re-write of ANA-050 by 09/20. This ANA-050 consolidates CON001 002 003 004 and 005 into one document. 8/27 - Currently being tested by Amy/Kimberly Aug 20 Jimmy asked Dean for a test meeting. Metrics from Kim on current ASR match rate (cases we can improve in M3). Unit test plan - try full cycle. Dean to setup meeting Kim/Kevin 8/23: Meeting scheduled for 8/26 | AN19: PNC to provide a PM and Resource. Create Scope of Work, Send Approval to Barnes. | AQ19: =CONCATENATE(B19, " ", A19, " ",C19, " ", E19) -> CON005 Concur Vendor Infor Finance | AR19: FIN001 PNC Bank (AR) PNC Lockbok Finance
A20: Concur | B20: CON001 | C20: SupplierInvoice | D20: Yes | E20: Finance | F20: Infor | G20: Kim | H20: Kevin | I20: Testing | K20: Speccing (ANA-050) | N20: =VLOOKUP(K20,'Drop Down'!$I$2:$K$14,3,FALSE) -> 30 | O20: =SUM(M20:N20) -> 30 | P20: =TODAY()+O20 -> 46325 | Q20: Dennis | S20: WIP | U20: 45555 | W20: Jen | X20: Completed | Z20: Completed | AC20: Completed | AD20: 45415 | AF20: Business | AG20: Amy Kimberly | AL20: 09/16 Dennis to complete re-write of ANA-050 by 09/20. This ANA-050 consolidates CON001 002 003 004 and 005 into one document. 8/27 - Currently being tested by Amy/Kimberly Aug 20 Jimmy asked Dean for a test meeting. Metrics from Kim on current ASR match rate (cases we can improve in M3). Unit test plan - try full cycle. Dean to setup meeting Kim/Kevin 8/23: Meeting scheduled for 8/26 | AM20: Kimberly/Amy +Dennis ANA-050 | AN20: -PNC to provide a PM and Resource. Create Scope of Work, Send Approval to Barnes. -Dennis to finalize field mappings for ANA-50 | AQ20: =CONCATENATE(B20, " ", A20, " ",C20, " ", E20) -> CON001 Concur SupplierInvoice Finance | AR20: FIN002 PNC Bank (AR) PNC Matcher file Finance
A21: Concur | B21: CONO06 | C21: T&E expense posting | D21: No | E21: Finance | F21: Infor | G21: Kim | H21: Kevin | I21: Pre Development | K21: Speccing (ANA-050) | Q21: Rachelle | S21: WIP | U21: 45565 | W21: Martin | AL21: 09/16 New Infor finance resource Rachelle Malahito onboarded this week to start work on CONCUR Expenses ANA-050 | AM21: Rachelle ANA-050 | AN21: PNC to provide a PM and Resource. Create Scope of Work, Send Approval to Barnes. | AQ21: =CONCATENATE(B21, " ", A21, " ",C21, " ", E21) -> CONO06 Concur T&E expense posting Finance
A22: Fedex | B22: FED001 | C22: FedEx Tracking Number Update | D22: No | E22: Supply chain | F22: Infor | G22: Lori | H22: Jeff | I22: Pre Development | K22: Tech Spec (TAR-040) | N22: =VLOOKUP(K22,'Drop Down'!$I$2:$K$14,3,FALSE) -> 25 | O22: =SUM(M22:N22) -> 25 | P22: =TODAY()+O22 -> 46320 | Q22: Cheska | R22: WIP | S22: Completed | T22: 45457 | U22: Completed | V22: 45407 | W22: Martin | X22: Pending Approval | Y22: Dean | AF22: Business | AG22: Dean | AL22: 9/25 - Sample File provided by Dean, Cheska to update ANA-50. Questions: Where is the Custom PO Number in the sample file? it is missing. We begin development once ANA-50 is updated for FedEx and Question answered 9/18 - open questions re database pull from Dean, cheska to reply 8/29 - Daniel has replied that there is only a configuration in both systems to convert the files from CSV to XML, awaiting dean's reply 8/27 - Sent follow up to Dean for the requested connection details. Dean will try to do it next week if not busy. Aug 20 Martin have tested but need test data and test from server 8/6/24: need to have the picking list editted to reflect the barcode scan, will follow up with Peter and Karin for their time | AM22: Barnes (Dean) | AN22: Need to approve ANA-50 | AQ22: =CONCATENATE(B22, " ", A22, " ",C22, " ", E22) -> FED001 Fedex FedEx Tracking Number Update Supply chain | AR22: FIN003 Shared Service (AP) Check Run Header Finance
A23: Fedex | B23: FED002 | C23: FedEx Shipping information | D23: Yes | E23: Supply chain | F23: Barnes | G23: Dan | H23: Jeff | I23: Pre Development | K23: Tech Spec (TAR-040) | N23: =VLOOKUP(K23,'Drop Down'!$I$2:$K$14,3,FALSE) -> 25 | O23: =SUM(M23:N23) -> 25 | P23: =TODAY()+O23 -> 46320 | T23: to Sonja, review 3/26 | Y23: Jeff | AK23: Jeff | AN23: Need to approve ANA-50 | AQ23: =CONCATENATE(B23, " ", A23, " ",C23, " ", E23) -> FED002 Fedex FedEx Shipping information Supply chain | AR23: FIN004 Shared Service (AP) Check Run Details Finance
A24: Optimizely | B24: OPT006 | C24: Order (email) | D24: No | E24: OTC | F24: Infor | G24: Amy B / Beth W | H24: Dean | I24: Pre Development | K24: Tech Spec (TAR-040) | N24: =VLOOKUP(K24,'Drop Down'!$I$2:$K$14,3,FALSE) -> 25 | O24: =SUM(M24:N24) -> 25 | P24: =TODAY()+O24 -> 46320 | Q24: Cheska | R24: WIP | S24: Completed | T24: 45470 | U24: Completed | V24: 45430 | W24: Martin | X24: Completed | AC24: Completed | AF24: Business | AL24: 9/18/ - ready to test, consid to transform file to xml 8/29/24: build from infor side done, ready to test as long as there is an XML file ready to be ingested. 8/20/24: low prioirty on the list, but ready to test as long as consid can map to the XML 8/6/24: no work needed from Infor end, the work is on Consid. Shall we bring Order in Scope or stick to email? possible BODs usage? | AM24: Barnes | AQ24: =CONCATENATE(B24, " ", A24, " ",C24, " ", E24) -> OPT006 Optimizely Order (email) OTC | AR24: CFO001 Cforia Customer Payments & Credits Finance
A25: Optimizely | B25: OPT001 | C25: Customer and Addresses | D25: No | E25: OTC | F25: Barnes | G25: Amy B / Beth W | H25: Jeff | I25: Not Started | K25: Speccing (ANA-050) | N25: =VLOOKUP(K25,'Drop Down'!$I$2:$K$14,3,FALSE) -> 30 | O25: =SUM(M25:N25) -> 30 | P25: =TODAY()+O25 -> 46325 | Q25: Hubert | S25: Completed | Y25: Dean | AK25: Dean | AL25: extract azure data for use in optimizely, working call 3/25 | AQ25: =CONCATENATE(B25, " ", A25, " ",C25, " ", E25) -> OPT001 Optimizely Customer and Addresses OTC | AR25: CFO002 Cforia Customer Order Finance
A26: Optimizely | B26: OPT002 | C26: Items | D26: No | E26: OTC | F26: Barnes | G26: Amy B / Beth W | H26: Jeff | I26: Not Started | K26: Speccing (ANA-050) | N26: =VLOOKUP(K26,'Drop Down'!$I$2:$K$14,3,FALSE) -> 30 | O26: =SUM(M26:N26) -> 30 | P26: =TODAY()+O26 -> 46325 | Q26: Hubert | S26: Completed | Y26: Dean | AK26: Dean | AL26: ANA050 ready Sep 4 working call 3/25 | AQ26: =CONCATENATE(B26, " ", A26, " ",C26, " ", E26) -> OPT002 Optimizely Items OTC | AR26: CFO003 Cforia Customer Master Finance
A27: Optimizely | B27: OPT003 | C27: Std Price, Cust price, Disc | D27: No | E27: OTC | F27: Barnes | G27: Amy B / Beth W | H27: Jeff | I27: Not Started | K27: Speccing (ANA-050) | N27: =VLOOKUP(K27,'Drop Down'!$I$2:$K$14,3,FALSE) -> 30 | O27: =SUM(M27:N27) -> 30 | P27: =TODAY()+O27 -> 46325 | Q27: Hubert | S27: Completed | Y27: Dean | AK27: Dean | AL27: ANA050 ready Sep 4 working call 3/25 | AQ27: =CONCATENATE(B27, " ", A27, " ",C27, " ", E27) -> OPT003 Optimizely Std Price, Cust price, Disc OTC | AR27: CFO004 Cforia Invoice Payment History Finance
A28: Optimizely | B28: OPT004 | C28: Tax exemption | D28: No | E28: OTC | F28: Barnes | G28: Amy B / Beth W | H28: Jeff | I28: Not Started | K28: Speccing (ANA-050) | N28: =VLOOKUP(K28,'Drop Down'!$I$2:$K$14,3,FALSE) -> 30 | O28: =SUM(M28:N28) -> 30 | P28: =TODAY()+O28 -> 46325 | Q28: Hubert | S28: Completed | Y28: Dean | AK28: Dean | AL28: ANA050 ready Sep 4 working call 3/25 | AQ28: =CONCATENATE(B28, " ", A28, " ",C28, " ", E28) -> OPT004 Optimizely Tax exemption OTC | AR28: CFO005 Cforia Invoice Copies IDM (PDF) Finance
A29: Optimizely | B29: OPT005 | C29: Stock | D29: No | E29: OTC | F29: Barnes | G29: Amy B / Beth W | H29: Jeff | I29: Not Started | K29: Speccing (ANA-050) | N29: =VLOOKUP(K29,'Drop Down'!$I$2:$K$14,3,FALSE) -> 30 | O29: =SUM(M29:N29) -> 30 | P29: =TODAY()+O29 -> 46325 | Q29: Hubert | S29: Completed | Y29: Dean | AK29: Dean | AL29: ANA050 ready Sep 4 Sent sample of M3_InventoryCountReport to Dean 240201, working call 3/25 | AM29: Can we use BOD? | AN29: Dean will try provide mappings for FedEx next week. Currently busy this week. Dean to provide connection details for shared folder | AQ29: =CONCATENATE(B29, " ", A29, " ",C29, " ", E29) -> OPT005 Optimizely Stock OTC | AR29: FED001 Fedex FedEx Tracking Number Update Supply chain
A30: PNC Bank (AR) (SPS) | B30: FIN002 | C30: PNC Matcher file | D30: No | E30: Finance | F30: Infor | G30: Kim | H30: Jeff | I30: Pre Development | K30: Speccing (ANA-050) | N30: =VLOOKUP(K30,'Drop Down'!$I$2:$K$14,3,FALSE) -> 30 | O30: =SUM(M30:N30) -> 30 | P30: =TODAY()+O30 -> 46325 | Q30: Dennis | S30: WIP | U30: 45562 | W30: Martin | AL30: 09/16 Dennis to complete ANA-050 draft by 09/25 08/27 Dennis had a meeting with PNC and Barnes and SPS. PNC Bank discussed the scope with Barnes 08/08 Dennis initiated weekly recurring calls to track progress. Dean to get the JBA and PNC together to discuss the current process and required specs. | AM30: PNC Bank & Infor(Dennis) | AQ30: =CONCATENATE(B30, " ", A30, " ",C30, " ", E30) -> FIN002 PNC Bank (AR) (SPS) PNC Matcher file Finance | AR30: FED002 Fedex FedEx Shipping information Supply chain
A31: Salesforce | B31: SFDC01 | C31: Item | D31: No | E31: OTC | F31: Infor | G31: Torbjörn | H31: Torbjörn | I31: Testing | K31: Business Testing | N31: =VLOOKUP(K31,'Drop Down'!$I$2:$K$14,3,FALSE) -> 2 | O31: =SUM(M31:N31) -> 2 | P31: =TODAY()+O31 -> 46297 | Q31: Jen | S31: Completed | T31: 45349 | W31: Jen | X31: Completed | Z31: Completed | AF31: Business | AG31: Torbjorn | AI31: Pending Confirmation | AL31: DES-030 ready. DEVFMC should be ready Sep 27 and PartCopy Oct 04 Sept 13 - setting up a new Salesforce environment for testing. Also changing Dev environment, which is the last step. August 27 - Successful Testing with Torbjorn. Testing session planned for Aug 27 with Torbjorn Aug 8 issue fixed and new test session with Torbjörn this week. April 11 - Torbjorn for validation Apri 10 - doc this week, Jen tested Wednesday | AM31: Torbjorn | AN31: Dean to provide connection details for shared folder | AQ31: =CONCATENATE(B31, " ", A31, " ",C31, " ", E31) -> SFDC01 Salesforce Item OTC | AR31: UPS001 UPS UPS Tracking Number Update Supply chain
A32: Salesforce | B32: SFDC04 | C32: Item Pricing | D32: No | E32: OTC | F32: Infor | G32: Torbjörn | H32: Torbjörn | I32: Testing | K32: Business Testing | N32: =VLOOKUP(K32,'Drop Down'!$I$2:$K$14,3,FALSE) -> 2 | O32: =SUM(M32:N32) -> 2 | P32: =TODAY()+O32 -> 46297 | Q32: Jen | S32: Completed | T32: 45349 | W32: Jen | X32: Completed | Z32: Completed | AF32: Business | AG32: Torbjorn | AI32: Pending Confirmation | AL32: DES-030 Ready. DEVFMC should be ready Sep 27 and PartCopy Oct 04 Sept 13 - setting up a new Salesforce environment for testing. Also changing Dev environment, which is the last step. August 27 - Successful Testing with Torbjorn. Testing session planned for Aug 27 with Torbjorn Aug 8 issue fixed and new test session with Torbjörn this week. July 30 -0 pending further testing by Torbjorn April 28 - TST070. Then Hubert to test afert getting access. April 11 - Torbjorn for validate 4/11 April 10 doc this week, jen test wed 4/10 2 Feb - ANA-050 started ready for review Feb 2 | AM32: Torbjorn | AQ32: =CONCATENATE(B32, " ", A32, " ",C32, " ", E32) -> SFDC04 Salesforce Item Pricing OTC | AR32: UPS002 UPS UPS Shipping Information Supply chain
A33: SPS Commerce EDI | B33: EDI001 | C33: EDI Sales Order 850 | D33: No | E33: OTC | F33: Infor | G33: Melissa | H33: Jeff | I33: Testing | K33: Development Testing | L33: Testing | M33: 10 | N33: =VLOOKUP(K33,'Drop Down'!$I$2:$K$14,3,FALSE) -> 12 | O33: =SUM(M33:N33) -> 22 | P33: =TODAY()+O33 -> 46317 | Q33: Cheska | R33: Complete | S33: Completed | T33: 45460 | U33: Completed | V33: 45430 | W33: Martin | AB33: 45460 | AF33: Technical | AH33: 45461 | AL33: 9/18/24: tested Grainger, SPS to send down MSC and PACCAR 8/29/24: asked SPS commerce to send down one trading partner for testing, cheska to check if there are any issues and process file until invoice. 8/20/24: paased initial test ready to test for SIT 8/16/24: ready to test we need raw files we need more raw files to drop 8/7/24:: infor mec mapping changes done, Infor functional to test 8/6/24: build completed from SPS commerce side, a few mapping needs to be done from infor tech Jeff has a quote from SPS Commerce, need to schedule follow up meeting to review details with Daniel and team •Barnes working to get contract with SPS | AM33: SIT | AN33: Contact Hubert Santos on updates from testing the standard implementation | AQ33: =CONCATENATE(B33, " ", A33, " ",C33, " ", E33) -> EDI001 SPS Commerce EDI EDI Sales Order 850 OTC | AR33: WOR001 Worldpay Payment Authorization OTC
A34: SPS Commerce EDI | B34: EDI002 | C34: EDI Shipment 856 | D34: No | E34: OTC | F34: Infor | G34: Melissa | H34: Jeff | I34: Pre Development | K34: Tech Spec (TAR-040) | M34: 20 | N34: =VLOOKUP(K34,'Drop Down'!$I$2:$K$14,3,FALSE) -> 25 | O34: =SUM(M34:N34) -> 45 | P34: =TODAY()+O34 -> 46340 | Q34: Cheska | R34: Complete | S34: Completed | T34: Complete | U34: Completed | W34: Martin | X34: WIP | AL34: 9/18/24: tested Grainger, SPS to send down MSC and PACCAR 8/29/24: asked SPS commerce to send down one trading partner for testing, cheska to check if there are any issues and process file until invoice 8/20/24: waiting for SPS commerce to give feedback on structure 8/16/24: completed build from SPS, infor sent out a test xml, waiting for SPS to validate if it passed through or not. 8/9/24: ANA050 uploaded to be reviewed by Barnes 8/6/24: currently with SPS commerce development. This EDI 856 would need to make use of dummy standard packaging to work, this has been agreed on with Sonja, Amy and Melissa. May want to add FYX consultant to team •Barnes working to get contract with SPS | AM34: Infor | AN34: Contact Hubert Santos on updates from testing the standard implementation | AQ34: =CONCATENATE(B34, " ", A34, " ",C34, " ", E34) -> EDI002 SPS Commerce EDI EDI Shipment 856 OTC | AR34: WOR002 Worldpay Payment Capture OTC
A35: SPS Commerce EDI | B35: EDI003 | C35: EDI Sales Order Ack | D35: No | E35: OTC | F35: Infor | G35: Melissa | H35: Jeff | I35: Development | K35: Speccing (ANA-050) | M35: 20 | N35: =VLOOKUP(K35,'Drop Down'!$I$2:$K$14,3,FALSE) -> 30 | O35: =SUM(M35:N35) -> 50 | P35: =TODAY()+O35 -> 46345 | Q35: Cheska | R35: Complete | S35: Completed | T35: Complete | U35: Completed | W35: Martin | AL35: 9/18/24: tested Grainger, SPS to send down MSC and PACCAR 8/29/24: finished development from SPS end, WIP development from Infor. 8/20/24: need to align development from Infor end 8/7/24: meeting with barnes finished, need to send acknowledgement codes. need to validate with Martin if the current standard bod is using the newest version of the 855 mapping uploaded in concierge. 8/6/24: to be discussed on 8/7/24 with Barnes •Barnes working to get contract with SPS | AM35: Infor | AQ35: =CONCATENATE(B35, " ", A35, " ",C35, " ", E35) -> EDI003 SPS Commerce EDI EDI Sales Order Ack OTC | AR35: OPT001 Optimizely Customer and Addresses OTC
A36: SPS Commerce EDI | B36: EDI004 | C36: EDI Invoice | D36: No | E36: OTC | F36: Infor | G36: Melissa | H36: Jeff | I36: Development | K36: Tech Spec (TAR-040) | M36: 20 | N36: =VLOOKUP(K36,'Drop Down'!$I$2:$K$14,3,FALSE) -> 25 | O36: =SUM(M36:N36) -> 45 | P36: =TODAY()+O36 -> 46340 | Q36: Cheska | R36: Complete | S36: Completed | T36: 45519 | U36: Completed | W36: Martin | AL36: 9/18/24: tested Grainger, SPS to send down MSC and PACCAR 8/29/ 24: development done from SPS, testing in progress. asked SPS commerce to send down one trading partner for testing, cheska to check if there are any issues and process file until invoice 8/20/24: SPS to confirm if build is done 8/16/24: ANA050 approved 8/12/24: ANA050 completed, current build is with SPS Commerce 8/6/24: SPS commerce is doing the build as of today •Barnes working to get contract with SPS | AM36: Infor | AQ36: =CONCATENATE(B36, " ", A36, " ",C36, " ", E36) -> EDI004 SPS Commerce EDI EDI Invoice OTC | AR36: OPT002 Optimizely Items OTC
A37: SPS Commerce EDI | B37: EDI005 | C37: EDI Shipment Schedule EDI 862 | D37: No | E37: OTC | F37: Infor | G37: Melissa | H37: Jeff | I37: Pre Development | K37: Tech Spec (TAR-040) | M37: 20 | N37: =VLOOKUP(K37,'Drop Down'!$I$2:$K$14,3,FALSE) -> 25 | O37: =SUM(M37:N37) -> 45 | P37: =TODAY()+O37 -> 46340 | Q37: Cheska | R37: Complete | S37: Completed | T37: 45460 | U37: Completed | V37: 45474 | W37: Martin | AL37: 9/18/24: tested Grainger, SPS to send down MSC and PACCAR 8/29/24: asked SPS commerce to send down one trading partner for testing, cheska to check if there are any issues and process file until invoice 8/20/24: SPS clarifications cleared, need to send down test data 8/16/24: need more raw data to test 8/7/24:: infor mec mapping changes done, Infor functional to test SPS to send more data for more customers 8/6/24: SPS dev completed, SPS commerce to send in more data for more testing Barnes working to get contract with SPS | AM37: Infor | AQ37: =CONCATENATE(B37, " ", A37, " ",C37, " ", E37) -> EDI005 SPS Commerce EDI EDI Shipment Schedule EDI 862 OTC | AR37: OPT003 Optimizely Std Price, Cust price, Disc OTC
A38: SPS Commerce EDI | B38: TBD | C38: DSV | AQ38: =CONCATENATE(B38, " ", A38, " ",C38, " ", E38) -> TBD SPS Commerce EDI DSV | AR38: OPT004 Optimizely Tax exemption OTC
A39: SPS Commerce EDI | B39: EDI006 | C39: Planning Schedule EDI 830 | D39: No | E39: OTC | F39: Infor | G39: Melissa | H39: Jeff | I39: Pre Development | K39: Tech Spec (TAR-040) | L39: Testing | M39: 10 | N39: =VLOOKUP(K39,'Drop Down'!$I$2:$K$14,3,FALSE) -> 25 | O39: =SUM(M39:N39) -> 35 | P39: =TODAY()+O39 -> 46330 | Q39: Cheska | R39: Complete | S39: Completed | T39: 45460 | U39: Completed | V39: 45483 | W39: Martin | AH39: 45492 | AL39: 9/18/24: tested Grainger, SPS to send down MSC and PACCAR 8/29/24: asked SPS commerce to send down one trading partner for testing, cheska to check if there are any issues and process file until invoice 8/20/24: SPS clarifications cleared, need to send down test data 8/16/24: need more raw data to test 8/7/24:: infor mec mapping changes done, Infor functional to test SPS to send more data for more customers 8/6/24: SPS dev completed, SPS commerce to send in more data for more testing , only firmed orders are integrated. •Barnes working to get contract with SPS | AM39: Infor | AQ39: =CONCATENATE(B39, " ", A39, " ",C39, " ", E39) -> EDI006 SPS Commerce EDI Planning Schedule EDI 830 OTC | AR39: OPT005 Optimizely Stock OTC
A40: UPS | B40: UPS002 | C40: UPS Shipping Information | D40: No | E40: Supply chain | F40: Barnes | G40: Dan | H40: Jeff | I40: Pre Development | K40: Tech Spec (TAR-040) | N40: =VLOOKUP(K40,'Drop Down'!$I$2:$K$14,3,FALSE) -> 25 | O40: =SUM(M40:N40) -> 25 | P40: =TODAY()+O40 -> 46320 | Q40: Cheska | R40: WIP | S40: Completed | T40: 45457 | U40: Completed | V40: 45407 | X40: Completed | AK40: Jeff | AN40: Contact Cheska(Infor) for latest updates | AQ40: =CONCATENATE(B40, " ", A40, " ",C40, " ", E40) -> UPS002 UPS UPS Shipping Information Supply chain | AR40: OPT006 Optimizely Order (email) OTC
...

Sheet Action Items
A1: Date Added | B1: Integration | C1: Priority | D1: Action | E1: Owner | F1: Due Date | G1: Status | H1: Comment | J1: =TODAY() -> 46295
A2: 45303 | B2: SPS Commerce EDI | D2: Determine if need to add FYX to project team 1/19: Jeff determined not needed | E2: Jeff | F2: 45310 | G2: Closed
A3: 45303 | B3: Optimizely | D3: Add Petter E to weekly meetings? | E3: Petter S | F3: 45310 | G3: Closed
A4: 45303 | B4: Worldpay | D4: Should Petter be added to Worldpay integration? He was working on Worldpay account creation | E4: Petter S | F4: 45310 | G4: Closed
A5: 45303 | B5: SPS Commerce EDI | D5: Jeff has a quote from SPS Commerce, need to schedule follow up meeting to review details with Daniel and team | E5: Jeff | F5: 45317 | G5: Closed
A6: 45310 | B6: Concur | D6: Schedule Barnes/Infor Meeting for week of 1/22 to align team | E6: Daniel | F6: 45317 | G6: Closed
A7: 45366 | B7: All | D7: Switch testing to 910 | E7: Daniel | F7: 45387 | G7: Closed | H7: =CONCATENATE(Table1[[#This Row],[Integration]], ", ", Table1[[#This Row],[Action]], ", ", Table1[[#This Row],[Owner]]) -> All, Switch testing to 910, Daniel
A8: 45366 | B8: All | D8: Need service account created in M3 for file drop | E8: Jeff | F8: 45373 | G8: closed | H8: =CONCATENATE(Table1[[#This Row],[Integration]], ", ", Table1[[#This Row],[Action]], ", ", Table1[[#This Row],[Owner]]) -> All, Need service account created in M3 for file drop, Jeff
A9: 45310 | B9: Worldpay | D9: Need info from Erik on contact info within Barnes/Worldpay | E9: Jeff | F9: 45317 | G9: Closed
A10: 45317 | B10: PNC Lockbox EDI820 flat file ACH ad wires | D10: Can we add PNC lockbox 820 to SPS commerce - Add Kim and Dean 2/2: Jeff will instruct SPS to include this | E10: Jeff | F10: 45324 | G10: closed
A11: 45324 | B11: Concur | D11: Emailed Steve to add to packaging standard / packing slip | E11: Sonja | F11: 45345 | G11: closed | H11: =CONCATENATE(Table1[[#This Row],[Integration]], ", ", Table1[[#This Row],[Action]], ", ", Table1[[#This Row],[Owner]]) -> Concur, Emailed Steve to add to packaging standard / packing slip , Sonja
A12: 45324 | B12: Concur | D12: Sync of data to Azure | E12: Petter | F12: 45330 | G12: Closed
A13: 45527 | B13: Concur | D13: Create Deployment Spec | E13: Dean | F13: 45627
A14: 45527 | B14: Salesforce | D14: Need to assign Torbjorn and Martin for Deployment | E14: Martin/Torbjorn | F14: 45627
A15: 45324 | B15: Concur | D15: Need to specify which fields from supplier invoice need to match (Delivery note field - PPS300) | E15: Daniel | F15: 45331 | G15: closed
A16: 45310 | B16: Fedex / UPS | D16: Need sample files to test 2/16: Jeff will send files going up today. | E16: Jeff | F16: 45317 | G16: Closed | H16: =CONCATENATE(Table1[[#This Row],[Integration]], ", ", Table1[[#This Row],[Action]], ", ", Table1[[#This Row],[Owner]]) -> Fedex / UPS, Need sample files to test 2/16: Jeff will send files going up today. , Jeff
A17: 45527 | B17: Concur | D17: Need test script for integration | E17: Dan Tuller | F17: 45566
A18: 45310 | B18: Fedex / UPS | C18: 1 | D18: Draft functional spec ready to review with Barnes | E18: Cheska | F18: 45366 | G18: closed | H18: =CONCATENATE(Table1[[#This Row],[Integration]], ", ", Table1[[#This Row],[Action]], ", ", Table1[[#This Row],[Owner]]) -> Fedex / UPS, Draft functional spec ready to review with Barnes, Cheska
A19: 45527 | B19: (SPS) PNC Bank (AR) | D19: Need to complete ANA-050 | E19: Dennis | F19: 45538
A20: 45345 | B20: Concur | D20: Setup SFTP for data transfer | E20: Karin | F20: 45352 | G20: Closed | H20: =CONCATENATE(Table1[[#This Row],[Integration]], ", ", Table1[[#This Row],[Action]], ", ", Table1[[#This Row],[Owner]]) -> Concur, Setup SFTP for data transfer, Karin
A21: 45530 | B21: (SPS) PNC Bank (AR) | D21: Complete TAR | F21: 45538
A22: 45359 | B22: Fedex / UPS | D22: Need to review mapping to/from JBA | E22: Cheska | F22: 45366 | G22: closed | H22: =CONCATENATE(Table1[[#This Row],[Integration]], ", ", Table1[[#This Row],[Action]], ", ", Table1[[#This Row],[Owner]]) -> Fedex / UPS, Need to review mapping to/from JBA, Cheska
A23: 45310 | B23: Salesforce | D23: Martin working on specs, will review with functional team when ready with Barnes | E23: Martin | F23: 45338 | G23: closed
A24: 45324 | B24: Salesforce | C24: 1 | D24: Need to review with Torbjörn when he returns | E24: Martin | F24: 45342 | G24: closed | H24: =CONCATENATE(Table1[[#This Row],[Integration]], ", ", Table1[[#This Row],[Action]], ", ", Table1[[#This Row],[Owner]]) -> Salesforce, Need to review with Torbjörn when he returns, Martin
A25: 45338 | B25: Salesforce | C25: 1 | D25: Daniel sent out functional spec, need Barnes review/approval | E25: Dean | F25: 45345 | G25: closed | H25: =CONCATENATE(Table1[[#This Row],[Integration]], ", ", Table1[[#This Row],[Action]], ", ", Table1[[#This Row],[Owner]]) -> Salesforce, Daniel sent out functional spec, need Barnes review/approval, Dean
A26: 45530 | B26: BoA Shared Service (AP) | D26: Complete TAR | E26: Isaiha | F26: 45548
A27: 45527 | B27: BoA Shared Service (AP) (details | D27: Need to complete ANA-050 | E27: Dennis | F27: 45538
A28: 45373 | B28: Optimizely | D28: Send M3 Project Timeline to Optimizely | E28: Sonja | F28: 45379 | G28: closed
A29: 45310 | B29: Worldpay | D29: Need a call with Worldpay to understand technical details & setup account - Jeff, Amy B, Daniel, Catherine L, Sonja | E29: Annastasia | F29: 45345 | G29: closed | H29: =CONCATENATE(Table1[[#This Row],[Integration]], ", ", Table1[[#This Row],[Action]], ", ", Table1[[#This Row],[Owner]]) -> Worldpay, Need a call with Worldpay to understand technical details & setup account - Jeff, Amy B, Daniel, Catherine L, Sonja, Annastasia
A30: 45338 | B30: Worldpay | D30: functional spec | E30: Daniel | F30: 45366 | G30: closed | H30: =CONCATENATE(Table1[[#This Row],[Integration]], ", ", Table1[[#This Row],[Action]], ", ", Table1[[#This Row],[Owner]]) -> Worldpay, functional spec, Daniel
A31: 45310 | B31: BoA Shared Service (AP) (header) | C31: 3 | D31: Will start functional spec after Cforia | E31: Dennis | F31: 45538
A32: 45530 | B32: BoA Shared Service (AP) (header) | D32: Complete TAR | E32: isiaha | F32: 45538
A33: 45530 | B33: CenPos | D33: ready for testing | E33: Hubert | F33: 45538
A34: 45366 | B34: Fedex / UPS | D34: Schedule functional spec review 4/12 was reviewed, but need functional Barnes approval. Will add Lori to meeting | E34: Sonja | F34: 45401 | G34: closed | H34: Dean to get signoff from Aaron
A35: 45359 | B35: Salesforce | D35: Identify new functional lead to replace lindsey listing Robert as replacement until another is identified | E35: Sonja | F35: 45366 | G35: closed
A36: 45310 | B36: Cforia | C36: 4 | D36: Start functional spec in Feb, not started, will start after Concur & PNC | E36: Dennis | F36: 45538 | G36: Not Started | H36: =CONCATENATE(Table1[[#This Row],[Integration]], ", ", Table1[[#This Row],[Action]], ", ", Table1[[#This Row],[Owner]]) -> Cforia, Start functional spec in Feb, not started, will start after Concur & PNC, Dennis
A37: 45366 | B37: Fedex / UPS | D37: Jeff to set up test machine with both UPS and Fedex, send machine name to Dean 8/26: Dean has machine name and IP address | E37: Jeff | F37: 45373 | G37: closed | H37: UPS - Jeff - Still in registration process, Jeff will send IP
A38: 45317 | B38: Cforia | C38: 4 | D38: Kevin is starting the technical spec, next step to find missing fields | E38: Kevin | F38: 45538 | G38: Started | H38: =CONCATENATE(Table1[[#This Row],[Integration]], ", ", Table1[[#This Row],[Action]], ", ", Table1[[#This Row],[Owner]]) -> Cforia, Kevin is starting the technical spec, next step to find missing fields, Kevin
A39: 45317 | B39: Concur | C39: 1 | D39: Jane W is starting technical spec, mapping in process | E39: Jane | F39: 45538 | G39: Started | H39: =CONCATENATE(Table1[[#This Row],[Integration]], ", ", Table1[[#This Row],[Action]], ", ", Table1[[#This Row],[Owner]]) -> Concur, Jane W is starting technical spec, mapping in process, Jane
A40: 45366 | B40: SPS Commerce EDI | D40: Finalize agreement with SPS | E40: Sonja | F40: 45373 | G40: Closed
...

Sheet Sheet2
C1: CON001 Concur SupplierInvoice Finance | D1: CON001
C2: CON001 - ANA-50 - Func Spec | D2: CON002 | I2: CON001 | J2: - ANA-50 - Func Spec | M2: =CONCATENATE(I2," ",J2) -> CON001 - ANA-50 - Func Spec
C3: CON001 - TAR-040 - Tech Spec | D3: CON003 | I3: CON001 | J3: - TAR-040 - Tech Spec | M3: =CONCATENATE(I3," ",J3) -> CON001 - TAR-040 - Tech Spec
C4: CON001 - TES-070 - Tech Spec | D4: CON004 | I4: CON001 | J4: - TES-070 - Tech Spec | M4: =CONCATENATE(I4," ",J4) -> CON001 - TES-070 - Tech Spec
C5: CON001 - DES-030 - Tech Spec | D5: CON005 | I5: CON001 | J5: - DES-030 - Tech Spec | M5: =CONCATENATE(I5," ",J5) -> CON001 - DES-030 - Tech Spec
C6: CON002 Concur Goods Receipts Finance | D6: SFDC01 | I6: CON002 | J6: - ANA-50 - Func Spec | M6: =CONCATENATE(I6," ",J6) -> CON002 - ANA-50 - Func Spec
C7: CON002 - ANA-50 - Func Spec | D7: SFDC02 | I7: CON002 | J7: - TAR-040 - Tech Spec | M7: =CONCATENATE(I7," ",J7) -> CON002 - TAR-040 - Tech Spec
C8: CON002 - TAR-040 - Tech Spec | D8: SFDC03 | I8: CON002 | J8: - TES-070 - Tech Spec | M8: =CONCATENATE(I8," ",J8) -> CON002 - TES-070 - Tech Spec
C9: CON002 - TES-070 - Tech Spec | D9: SFDC04 | I9: CON002 | J9: - DES-030 - Tech Spec | M9: =CONCATENATE(I9," ",J9) -> CON002 - DES-030 - Tech Spec
C10: CON002 - DES-030 - Tech Spec | D10: EDI001 | I10: CON003 | J10: - ANA-50 - Func Spec | M10: =CONCATENATE(I10," ",J10) -> CON003 - ANA-50 - Func Spec
C11: CON003 Concur PO Header Finance | D11: EDI002 | I11: CON003 | J11: - TAR-040 - Tech Spec | M11: =CONCATENATE(I11," ",J11) -> CON003 - TAR-040 - Tech Spec
C12: CON003 - ANA-50 - Func Spec | D12: EDI003 | I12: CON003 | J12: - TES-070 - Tech Spec | M12: =CONCATENATE(I12," ",J12) -> CON003 - TES-070 - Tech Spec
C13: CON003 - TAR-040 - Tech Spec | D13: EDI004 | I13: CON003 | J13: - DES-030 - Tech Spec | M13: =CONCATENATE(I13," ",J13) -> CON003 - DES-030 - Tech Spec
C14: CON003 - TES-070 - Tech Spec | I14: CON004 | J14: - ANA-50 - Func Spec | M14: =CONCATENATE(I14," ",J14) -> CON004 - ANA-50 - Func Spec
C15: CON003 - DES-030 - Tech Spec | I15: CON004 | J15: - TAR-040 - Tech Spec | M15: =CONCATENATE(I15," ",J15) -> CON004 - TAR-040 - Tech Spec
C16: CON004 Concur PO Lines Finance | I16: CON004 | J16: - TES-070 - Tech Spec | M16: =CONCATENATE(I16," ",J16) -> CON004 - TES-070 - Tech Spec
C17: CON004 - ANA-50 - Func Spec | I17: CON004 | J17: - DES-030 - Tech Spec | M17: =CONCATENATE(I17," ",J17) -> CON004 - DES-030 - Tech Spec
C18: CON004 - TAR-040 - Tech Spec | I18: CON005 | J18: - ANA-50 - Func Spec | M18: =CONCATENATE(I18," ",J18) -> CON005 - ANA-50 - Func Spec
C19: CON004 - TES-070 - Tech Spec | I19: CON005 | J19: - TAR-040 - Tech Spec | M19: =CONCATENATE(I19," ",J19) -> CON005 - TAR-040 - Tech Spec
C20: CON004 - DES-030 - Tech Spec | I20: CON005 | J20: - TES-070 - Tech Spec | M20: =CONCATENATE(I20," ",J20) -> CON005 - TES-070 - Tech Spec
C21: CON005 Concur Vendor Infor Finance | I21: CON005 | J21: - DES-030 - Tech Spec | M21: =CONCATENATE(I21," ",J21) -> CON005 - DES-030 - Tech Spec
C22: CON005 - ANA-50 - Func Spec | I22: SFDC01 | J22: - ANA-50 - Func Spec | M22: =CONCATENATE(I22," ",J22) -> SFDC01 - ANA-50 - Func Spec
C23: CON005 - TAR-040 - Tech Spec | I23: SFDC01 | J23: - TAR-040 - Tech Spec | M23: =CONCATENATE(I23," ",J23) -> SFDC01 - TAR-040 - Tech Spec
C24: CON005 - TES-070 - Tech Spec | I24: SFDC01 | J24: - TES-070 - Tech Spec | M24: =CONCATENATE(I24," ",J24) -> SFDC01 - TES-070 - Tech Spec
C25: CON005 - DES-030 - Tech Spec | I25: SFDC01 | J25: - DES-030 - Tech Spec | M25: =CONCATENATE(I25," ",J25) -> SFDC01 - DES-030 - Tech Spec
... C56: EDI003 SPS Commerce EDI EDI Sales Order Ack OTC | I56: EDI005 | J56: - TES-070 - Tech Spec | M56: =CONCATENATE(I56," ",J56) -> EDI005 - TES-070 - Tech Spec
C57: EDI003 - ANA-50 - Func Spec | G57: EDI005 | I57: EDI005 | J57: - DES-030 - Tech Spec | M57: =CONCATENATE(I57," ",J57) -> EDI005 - DES-030 - Tech Spec
C58: EDI003 - TAR-040 - Tech Spec | G58: EDI006 | I58: EDI006 | J58: - ANA-50 - Func Spec | M58: =CONCATENATE(I58," ",J58) -> EDI006 - ANA-50 - Func Spec
C59: EDI003 - TES-070 - Tech Spec | G59: EDI007 | I59: EDI006 | J59: - TAR-040 - Tech Spec | M59: =CONCATENATE(I59," ",J59) -> EDI006 - TAR-040 - Tech Spec
C60: EDI003 - DES-030 - Tech Spec | G60: FIN001 | I60: EDI006 | J60: - TES-070 - Tech Spec | M60: =CONCATENATE(I60," ",J60) -> EDI006 - TES-070 - Tech Spec
C61: EDI004 SPS Commerce EDI EDI Invoice OTC | G61: FIN002 | I61: EDI006 | J61: - DES-030 - Tech Spec | M61: =CONCATENATE(I61," ",J61) -> EDI006 - DES-030 - Tech Spec
C62: EDI004 - ANA-50 - Func Spec | G62: FIN003 | I62: EDI007 | J62: - ANA-50 - Func Spec | M62: =CONCATENATE(I62," ",J62) -> EDI007 - ANA-50 - Func Spec
C63: EDI004 - TAR-040 - Tech Spec | G63: FIN004 | I63: EDI007 | J63: - TAR-040 - Tech Spec | M63: =CONCATENATE(I63," ",J63) -> EDI007 - TAR-040 - Tech Spec
C64: EDI004 - TES-070 - Tech Spec | G64: CFO001 | I64: EDI007 | J64: - TES-070 - Tech Spec | M64: =CONCATENATE(I64," ",J64) -> EDI007 - TES-070 - Tech Spec
C65: EDI004 - DES-030 - Tech Spec | G65: CFO002 | I65: EDI007 | J65: - DES-030 - Tech Spec | M65: =CONCATENATE(I65," ",J65) -> EDI007 - DES-030 - Tech Spec
C66: EDI005 SPS Commerce EDI EDI Shipment Schedule EDI 862 OTC | G66: CFO003 | I66: FIN001 | J66: - ANA-50 - Func Spec | M66: =CONCATENATE(I66," ",J66) -> FIN001 - ANA-50 - Func Spec
C67: EDI005 - ANA-50 - Func Spec | I67: FIN001 | J67: - TAR-040 - Tech Spec | M67: =CONCATENATE(I67," ",J67) -> FIN001 - TAR-040 - Tech Spec
C68: EDI005 - TAR-040 - Tech Spec | I68: FIN001 | J68: - TES-070 - Tech Spec | M68: =CONCATENATE(I68," ",J68) -> FIN001 - TES-070 - Tech Spec
C69: EDI005 - TES-070 - Tech Spec | I69: FIN001 | J69: - DES-030 - Tech Spec | M69: =CONCATENATE(I69," ",J69) -> FIN001 - DES-030 - Tech Spec
C70: EDI005 - DES-030 - Tech Spec | I70: FIN002 | J70: - ANA-50 - Func Spec | M70: =CONCATENATE(I70," ",J70) -> FIN002 - ANA-50 - Func Spec
...

Sheet Barnes Project Plan
A1: Interface | B1: Priority | C1: Phase | D1: Category | E1: Task | F1: Status | G1: Due Date | H1: Org | I1: Owner | J1: Note
A2: Bank of America (AP) | C2: 0 - Doc | D2: 0 - ANA-050 | E2: ANA-050 - Ready for Review | F2: Complete | G2: 45534 | H2: I | I2: Carlo Alcazar
A3: Bank of America (AP) | B3: * | C3: 0 - Doc | D3: 1 - ANA-050 | E3: ANA-050 - Signoff | F3: Complete | G3: 45541 | H3: B | I3: Kim Diorio | J3: Agreed approved in Meeting 9/23/2024
A4: Bank of America (AP) | C4: 0 - Doc | D4: 2 - TAR-040 | E4: TAR-040 - Ready for Review | F4: Complete | G4: 45548 | H4: I | I4: Isaiah Tolentino
A5: Bank of America (AP) | C5: 0 - Doc | D5: 3 - TEST-070 | E5: Unit Test Plan | F5: Not Started | G5: 45583 | H5: B | I5: Kim Diorio
A6: Bank of America (AP) | C6: 0 - Doc | D6: 4- DOC COMPLETE | F6: In Progress
A7: Bank of America (AP) | C7: 1 - Dev | D7: Dev | E7: Header file for checks | F7: Complete | H7: I | I7: Isaiah Tolentino | J7: 10/2 Wed - Martin on 9/30 9a call
A8: Bank of America (AP) | B8: * | C8: 1 - Dev | D8: Dev | E8: Detail file for checks | F8: Complete | G8: 45562 | H8: I | I8: Isaiah Tolentino | J8: 10/2 Wed - Martin on 9/30 9a call
A9: Bank of America (AP) | B9: * | C9: 1 - Dev | D9: Dev | E9: Header file for ACH | F9: Complete | G9: 45562 | H9: I | I9: Isaiah Tolentino | J9: 10/2 Wed - Martin on 9/30 9a call
A10: Bank of America (AP) | B10: * | C10: 1 - Dev | D10: Dev | E10: Detail file for ACH | F10: Complete | G10: 45562 | H10: I | I10: Isaiah Tolentino | J10: 10/2 Wed - Martin on 9/30 9a call
A11: Bank of America (AP) | C11: 1 - Deb | D11: Dev | E11: Send sample files to Barnes | F11: In Progress | G11: 45566 | H11: I | I11: Isaiah Tolentino
A12: Bank of America (AP) | B12: * | C12: 1 - Dev | D12: Dev | E12: SSIS: Transfer files to Industrial JBA box for transmission (weekly) | F12: Await files | G12: 45576 | H12: B | I12: Kevin Alexander
A13: Bank of America (AP) | C13: 2 - Test | D13: UAT | E13: UAT Ready | F13: On Track | G13: 45583 | H13: B | I13: Dean Amo
A14: Bank of America (AP) | C14: 2 - Test | D14: Unit Test 001 | E14: Makes it to Barnes Industrial AS/400 - users are able to confirm the details | F14: Not Started | G14: 45583 | H14: B | I14: Kim Diorio
A15: Bank of America (AP) | B15: Risk | C15: 2 - Test | D15: Unit Test 002 | E15: Test transmission to bank has long lead time | F15: Not Started | G15: 45583 | H15: B | I15: Kim Diorio
A16: CenPOS | C16: 0 - Doc | D16: 0 - ANA-050 | E16: ANA-050 - Ready for Review | F16: Not Required | H16: I
A17: CenPOS | C17: 0 - Doc | D17: 1 - ANA-050 | E17: ANA-050 - Signoff | F17: Not Required | H17: I
A18: CenPOS | C18: 0 - Doc | D18: 2 - TAR-040 | E18: TAR-040 Reviewed and approved | F18: Not Required | H18: I
A19: CenPOS | B19: * | C19: 0 - Doc | D19: 3 - TEST-070 | E19: Unit Test Plan - CenPOS - contact Hubert for M3 functional questions | F19: Overdue | G19: 45548 | H19: B | I19: Amy Burgard | J19: *Meeting scheduled Thur 9/26
A20: CenPOS | C20: 0 - Doc | D20: 4- DOC COMPLETE
A21: CenPOS | B21: Low | C21: 1 - Dev | D21: Dev | E21: Review test portal login | F21: Complete | G21: 45562 | H21: B | I21: Dean Amo
A22: CenPOS | B22: Low | C22: 1 - Dev | D22: Dev | E22: Change service account from @infor.com to @asraymond.com | F22: In Progress | G22: 45562 | H22: B | I22: Dean Amo | J22: Need a DL_CenPos_Administration@onebarnes.com
A23: CenPOS | B23: Low | C23: 1 - Dev | D23: Dev | E23: Update M3 CenPOS connector configuration after account change | F23: Not Started | I23: Hubert Santos
A24: CenPOS | C24: 2 - Test | D24: UAT | E24: Ready for testing | F24: Complete | G24: 45444 | H24: I | I24: Daniel Lindblad
A25: CenPOS | C25: 2 - Test | D25: Unit Test 001 | E25: Charge customer order to test credit card | F25: Complete - Success | H25: B | I25: Amy, Melissa
A26: Cforia | B26: * | C26: 0 - Doc | D26: 0 - ANA-050 | E26: ANA-050 - Ready for Review | F26: Overdue | G26: 45548 | H26: B | I26: Dennis Garrero, Rachelle | J26: 9/30/2024 - New Due Date. 10/9/2024 latest due date from 9/26.
A27: Cforia | B27: * | C27: 0 - Doc | D27: 1 - ANA-050 | E27: ANA-050 - Sign off | F27: Await Dependancy | G27: 45569 | H27: B | I27: Kim Diorio / Kevin Alexander
A28: Cforia | B28: * | C28: 0 - Doc | D28: 2 - TAR-040 | E28: TAR-040 Reviewed and approved | F28: Await Dependancy | G28: 45569 | H28: I | I28: Carlo Alcazar | J28: Awaiting ANA-050
A29: Cforia | C29: 0 - Doc | D29: 3 - TEST-070 | E29: Unit Test Plan | F29: Not Started | G29: 45590 | H29: B | I29: Dean / Kim | J29: *Need output of open A/R report from M3 -Dennis tried on call, output not working
A30: Cforia | C30: 0 - Doc | D30: 4 - DOC COMPLETE
A31: Cforia | C31: 00 - Doc Req | D31: 2 - TAR-040 | E31: Meeting for missing AR details | F31: Complete | H31: T | I31: Dennis / Kevin | J31: Search 'Acc Re' in M3 for open A/R screens
A32: Cforia | B32: * | C32: 1 - Dev | D32: Dev | E32: Modify DW Job, BGIDW_M3_ASR to include AR files | F32: In Progress | G32: 45583 | H32: B | I32: Kevin Alexander
A33: Cforia | C33: 1 - Dev | D33: Dev | E33: Contact Cdoria - ensure test environment is ready | G33: 45569 | H33: B | I33: Kevin Alexander
A34: Cforia | C34: 1 - Dev | D34: Dev | E34: Build ARCASH.TXT exoport | F34: In Progress | G34: 45590 | H34: B | I34: Kevin Alexander
A35: Cforia | C35: 1 - Dev | D35: Dev | E35: Build ARCUST.TXT exoport | F35: In Progress | G35: 45590 | H35: B | I35: Kevin Alexander
A36: Cforia | C36: 1 - Dev | D36: Dev | E36: Build AREXTI.TXT exoport | F36: In Progress | G36: 45590 | H36: B | I36: Kevin Alexander
A37: Cforia | C37: 1 - Dev | D37: Dev | E37: Build ARMAST.TXT exoport | F37: In Progress | G37: 45590 | H37: B | I37: Kevin Alexander
A38: Cforia | C38: 1 - Dev | D38: Dev | E38: Build ARTRAN.TXT exoport | F38: In Progress | G38: 45590 | H38: B | I38: Kevin Alexander
A39: Cforia | C39: 1 - Dev | D39: Dev - Enahnce | E39: Invoice PDF to archive folder | F39: Not Started | H39: B | I39: Karin Fransson
C40: 1 - Dev | D40: Dev | E40: Transmit to Cforia | F40: Not Started | G40: 45597 | H40: B | I40: Kevin Alexander
...

Sheet Barnes UAT Pivot
A1: Phase | B1: 2 - Test
A3: Row Labels | B3: Category | C3: Task | D3: Status | E3: Due Date | F3: Dev Owner | G3: Next Action Due
A4: Bank of America (AP) | B4: UAT | C4: UAT Ready | D4: On Track | E4: 45583 | F4: Dean Amo | G4: 10/2 - Isiah to deliver 4 files on: ACH header/detail, check header/detail
A5: CenPOS | B5: UAT | C5: Ready for testing | D5: Complete | E5: 45444 | F5: Daniel Lindblad
A6: Cforia | B6: UAT | C6: UAT Ready | D6: Late | E6: 45600 | F6: Dean Amo | G6: 10/9 - ANA-050. 10/25 - Kevin - Balance extracts to M3 Open A/R
A7: Concur - Invoice | B7: UAT | C7: UAT Ready | D7: Late | E7: 45597 | F7: Dean Amo | G7: 9/27 - Dean/Kim/Jesse - Ticket open with Concur, waiting for resource to be assigned. Data not loading under policy.
A8: Concur - Travel & Expense | B8: UAT | C8: UAT Ready | D8: Late | E8: 45590 | F8: Dean Amo | G8: 9/27 - ANA to be reviewed 9/30 - that could get us back on track. Need to understand schedule.
A9: FedEx | B9: UAT | C9: UAT Ready | D9: On Track - Issue | E9: 45586 | F9: Dean Amo | G9: 9/27 - FedEx not filling. A. Need production review, B. Call FedEx Support, C. Try another machine.
A10: Optimizely - Current State | B10: UAT | C10: UAT Ready | D10: On Track | E10: 45572 | F10: Dean Amo
A11: Optimizely - Order Auto. | B11: UAT | C11: UAT Ready | D11: On Track | E11: 45593 | F11: Dean Amo
A12: PNC Bank (AR) | B12: UAT | C12: UAT Ready | D12: On Track - Issue | E12: 45600 | F12: Dean Amo | G12: Need matcher file - higher priorty than ANA
A13: Salesforce | B13: UAT | C13: UAT Ready | D13: Complete | E13: 45544 | F13: Daniel Lindblad
A14: SPS Commerce - EDI | B14: UAT | C14: UAT Phase 1 Ready: PACCAR, Granger, Caterpillar, PNC | D14: Late | E14: 45600 | F14: Keith Sims | G14: 9/27 - Keith Assessing
C15: UAT Phase 2 Ready: All EDI | D15: Late | E15: 45663 | F15: Keith Sims | G15: 9/27 - Keith Assessing
