Workbook

Sheet Overview
A1: ADP / UKG -> SAP Concur Employee Import: Mapping Guide
A2: Generated 2026-09-29 from ADP_Concur_Map.py, ADP_Concur_Db.py and ADP_Concur_Config.json. Map-table tabs are a snapshot of the live database (~/sqlite/doppio.db).
A4: How the data flows
A5: 1. Import | B5: The workbook is loaded (ADP_Concur_Import.py). The ADP export (sheet '1' / 'ADP') and the UKG export are merged on File Number / Employee Number into ADP_Concur_Employees; 'source' says which system sent each row. The map tabs load into their own ADP_Concur_*Map tables, and the 305/350/360/700 template tabs load into ADP_Concur_Layouts.
A6: 2. Derive | B6: ADP_Concur_derive() recomputes the derived columns (the workbook's AC..AO for ADP, AZ..BL for UKG) from the map tables. It runs after every import or map edit, and it rebuilds the exception list.
A7: 3. Build records | B7: build_record() fills each Concur record position from FIELD_MAP, then applies the per-source overrides, the conditional copies and the config blank_fields. A position with no mapping is written empty.
A8: 4. Extract | B8: One comma-delimited file: a 100 (Import Settings) line first, then the 305s, 350s, 360s and 700s ('by_type' order). The 305s are sorted so an approver comes before the people who report to them, and the other record types follow that order. Employees with any 'error' exception are left out.
A10: Sources
A11: ADP | B11: Uses the ADP rules. Record types: 305, 350, 360, 700
A12: UKG | B12: Uses the UKG rules (derive_ukg). Record types: 305, 360, 700 (UKG has no 350).
A13: Added by hand | B13: Keyed into the app. Uses the ADP rules and can carry its own password.
A15: Current scope (config)
A16: Record 305 | B16: Everyone included (active and terminated)
A17: Record 350 | B17: Not written - left out of the extract
A18: Record 360 | B18: Only employees with Invoice Access = Y
A19: Record 700 | B19: Only employees with Invoice Access = Y
A21: Tabs in this guide
A22: Source Columns | B22: Every ADP and UKG export column and the database field it loads into.
A23: Derived Fields | B23: Each calculated value: the rule for ADP and for UKG, the map table it uses, and what it returns when the lookup finds nothing.
A24: Record 100 | B24: The Import Settings line.
A25: Record 305/350/360/700 | B25: Every position of each Concur record and what fills it, for ADP and for UKG.
A26: Map Tables | B26: What each lookup table is keyed on and what it returns.
A27: Map - * | B27: The current contents of each lookup table.
A28: Config | B28: The settings that change the output, with the current value and the code default.
A29: Validation | B29: The checks that raise exceptions, and whether each one keeps the employee out of the file.
A31: Colour legend
A32: Yellow row | B32: ADP and UKG fill this position differently.
A33: Green row | B33: A constant, the same for every employee.
A34: Grey row | B34: Not mapped: the position is written empty.
A35: [name] | B35: The database column (ADP_Concur_Employees) the value is read from.

Sheet Source Columns
A1: Source Columns -> Database
A2: Where each export column lands in ADP_Concur_Employees. Columns with the same meaning share one database field. Yellow = the same field under a different name in each system.
A4: Database Field | B4: ADP Col | C4: ADP Export Heading | D4: UKG Col | E4: UKG Export Heading
A5: payroll_company_code | B5: A | C5: Payroll Company Code | D5: A | E5: Company Code
A6: legal_first_name | B6: B | C6: Legal First Name
A7: middle_initial | B7: C | C7: Middle Initial
A8: legal_last_name | B8: D | C8: Legal Last Name
A9: preferred_first_name | B9: E | C9: Preferred or Chosen First Name
A10: preferred_last_name | B10: F | C10: Preferred or Chosen Last Name
A11: reports_to_legal_name | B11: G | C11: Reports To Legal Name | D11: S | E11: Supervisor Name (Last Suffix, First MI)
A12: supervisor_id_raw | B12: H | C12: Supervisor ID | D12: R | E12: Supervisor Employee Number
A13: work_email | B13: I | C13: Work Contact: Work Email | D13: AQ | E13: E-mail Address
A14: personal_email | B14: J | C14: Personal Contact: Personal Email
A15: job_title | B15: K | C15: Job Title Description | D15: K | E15: Job
A16: hire_date | B16: L | C16: Hire Date | D16: V | E16: Last Hire Date
A17: termination_date | B17: M | C17: Termination Date
A18: rehire_date | B18: N | C18: Rehire Date
A19: position_status | B19: O | C19: Position Status | D19: X | E19: Employment Status
A20: file_number | B20: P | C20: File Number | D20: D | E20: Employee Number
A21: pay_frequency | B21: Q | C21: Pay Frequency
A22: employee_type | B22: R | C22: Employee Type | D22: E | E22: Employment Type
A23: business_unit_code | B23: S | C23: Business Unit Code
A24: business_unit_desc | B24: T | C24: Business Unit Description
A25: home_department_desc | B25: U | C25: Home Department Description
A26: home_department_code | B26: V | C26: Home Department Code
A27: location_desc | B27: W | C27: Location Description
A28: language_desc | B28: X | C28: Language Description
A29: language_code | B29: Y | C29: Language Code
A30: legal_country_code | B30: Z | C30: Legal / Preferred Address: Country Code | D30: AM | E30: Country Code
A31: pay_grade_code | B31: AA | C31: Pay Grade Code | D31: Q | E31: Salary Grade
A32: pay_grade_desc | B32: AB | C32: Pay Grade Description
A33: pay_group_code | D33: B | E33: Pay Group Code
A34: pay_group | D34: C | E34: Pay Group
A35: employee_name_raw | D35: F | E35: Employee Name (Last Suffix, First MI)
A36: job_code | D36: G | E36: Job Code
A37: job_family | D37: J | E37: Job Family
A38: alternate_title | D38: L | E38: Alternate Title
A39: seniority_date | D39: O | E39: Seniority Date
A40: site_location | D40: T | E40: Site Location
A41: site_location_code | D41: U | E41: Site Location Code
...

Sheet Derived Fields
A1: Derived Fields
A2: Calculated by ADP_Concur_derive() and stored on ADP_Concur_Employees. ADP Col / UKG Col are the derived-block columns on each export sheet.
A4: Database Field | B4: Label | C4: ADP Col | D4: ADP Rule | E4: Workbook Formula (ADP) | F4: UKG Col | G4: UKG Rule | H4: Map Table(s) | I4: Value When Not Found
A5: supervisor_id | B5: SupervisorID Formatted | C5: AC | D5: The Supervisor Map (keyed on the employee's File Number) wins. Otherwise characters 4-9 of the ADP Supervisor ID: 'KSY211756' -> '211756'. | E5: =IF(ISBLANK(H5),VLOOKUP(P5,'Supervisor Map'!A:D,4,FALSE),MID(H5,4,6)) (the app lets the map win over ADP as well) | F5: AZ | G5: The Supervisor Map wins. Otherwise the Supervisor Employee Number exactly as UKG sends it (=R2). | H5: Supervisor Map | I5: Blank. A warning if the person is active; blank on purpose means top of the hierarchy.
A6: org_unit_1 | B6: Org Unit 1 | C6: AD | D6: Org Map, looked up by Business Unit Description, returns Org Unit 1 (the first matching row wins). | E6: =IFERROR(VLOOKUP(T5,'Org Map'!A:E,4),"BU Description Not Mapped") | F6: BA / 305 P | G6: UKG Company Map, looked up by Site Location Code, returns Concur Company Code. | H6: Org Map (ADP); UKG Company Map (UKG) | I6: ADP: "BU Description Not Mapped"; UKG: "Site Location Not Mapped"
A7: concur_expense_group | B7: Concur Expense Group | C7: - | D7: The same value as Org Unit 1. | E7: 305 AP = ADP!AD | F7: 305 AP | G7: UKG Company Map, looked up by Site Location Code, returns Expense Group Code. | H7: UKG Company Map | I7: UKG: "Site Location Not Mapped"
A8: concur_ledger_code | B8: Ledger Code | C8: - | D8: The same value as Org Unit 1. | E8: 305 L = ADP!AD | F8: 305 L | G8: UKG Company Map, looked up by Site Location Code, returns Ledger Code. (The workbook formula uses column index 7, which is past the end of the table. The app uses the Ledger Code column, as the heading intends.) | H8: UKG Company Map | I8: UKG: "Ledger Code Not Matched"
A9: concur_custom_5 | B9: Custom 5 Code | C9: - | D9: The same value as Org Unit 1. | E9: 305 Z = ADP!AD | F9: 305 Z | G9: UKG Company Map, looked up by Site Location Code, returns Custom 5 Code. (The workbook uses index 8; the app uses the Custom 5 Code column.) | H9: UKG Company Map | I9: UKG: "Custom 5 Not Matched"
A10: org_unit_2 | B10: Org Unit 2 | C10: AE | D10: Org Map, looked up by Home Department Code, returns Org Unit 2. The app uses an exact match; the workbook formula does an approximate match. | E10: =IFERROR(VLOOKUP(V5,'Org Map'!C:E,3),"Home Department Code Not Mapped") | F10: BB | G10: Site Location Code 0077 or 177 (NGP Sweden) gives "0000". Otherwise Org Level 3 Code, and a blank becomes "000". | H10: Org Map (ADP only) | I10: ADP: "Home Department Code Not Mapped"; UKG: never unmapped
A11: concur_profile | B11: Concur Profile | C11: AF | D11: Salary Map, looked up by Pay Grade Code, returns the Expense Map value. | E11: =IFERROR(VLOOKUP(AA5,'Salary Map'!A:D,3,FALSE),"Salary Code Not Mapped") | F11: BC | G11: Salary Map, looked up by the trimmed Salary Grade, returns the Expense Map value. | H11: Salary Map | I11: "Salary Code Not Mapped"
A12: travel_profile | B12: Travel Profile | C12: AG | D12: Salary Map, looked up by Pay Grade Code, returns the Travel Map value, used as it appears in the map (e.g. 'General US'). | E12: =IFERROR(VLOOKUP(AA5,'Salary Map'!A:D,4,FALSE),"Salary Code Not Mapped") | F12: BD | G12: Same as ADP, using the trimmed Salary Grade. | H12: Salary Map | I12: "Salary Code Not Mapped"
A13: invoice_limit | B13: Invoice Approval Limit | C13: AH | D13: Salary Map, looked up by Pay Grade Code, returns the Invoice Approval amount. | E13: =IFERROR(VLOOKUP(AA5,'Salary Map'!A:E,5,FALSE),"Invoice Approval Not Mapped") | F13: BE | G13: "0" if Invoice Access = N. Otherwise the Salary Map Invoice Approval amount for the trimmed Salary Grade. | H13: Salary Map | I13: "Invoice Approval Not Mapped"
A14: legal_country | B14: Legal Country | C14: AI | D14: Country Map, looked up by the 3-character address country code, returns the 2-character Concur code. | E14: =IFERROR(VLOOKUP(Z5,'Country Map'!A:B,2,FALSE),"Legal Country Not Mapped") | F14: BF | G14: Country Map, looked up by Country Code, returns the 2-character code. | H14: Country Map | I14: ADP: "Legal Country Not Mapped"; UKG: "Country Not Mapped"
A15: locale_code | B15: Locale Code | C15: AJ | D15: Language Map, looked up by Language Description, returns a stem such as 'en_'. If that finds nothing, the Org Map default language for the Business Unit is used. Legal Country is then added to the end: 'en_' + 'US' = 'en_US'. | E15: =IFERROR(VLOOKUP(X5,'Language Map'!A:C,3,FALSE),IFERROR(VLOOKUP(T5,'Org Map'!A:F,6,FALSE),"ADP and BU Language Code Not Mapped"))&AH5 | F15: BG / 305 I | G15: Locale Map (Language Map columns M:O), looked up by the derived 2-character country. 'en_US' if the country is not in the map. | H15: Language Map, Org Map (ADP); Locale Map (UKG) | I15: ADP: "ADP and BU Language Code Not Mapped" + country; UKG: "en_US"
A16: reimbursement_currency | B16: Reimbursement Currency | C16: AK | D16: Org Map, looked up by Business Unit Description, returns Reimbursement Currency. | E16: =IFERROR(VLOOKUP(T5,'Org Map'!A:G,7),"BU Currency Not Mapped") | F16: BH | G16: Country Map, looked up by Country Code, returns Currency Code. | H16: Org Map (ADP); Country Map (UKG) | I16: ADP: "BU Currency Not Mapped"; UKG: "Country Not Mapped"
A17: preferred_name | B17: Preferred Name | C17: AL | D17: Preferred First Name + ' ' + Preferred Last Name. Blank if there is no preferred first name. | E17: =IF(ISBLANK(E5),"",TRIM(E5&" "&F5)) | F17: BI | G17: Always blank (the UKG sheet has no formula here). | H17: - | I17: -
A18: concur_status | B18: Status | C18: AM | D18: Status Map, looked up by Position Status, returns Y (active) or N (inactive). | E18: =IFERROR(VLOOKUP(O5,'Status Map'!A:B,2,FALSE),"Position Status Not Mapped") | F18: BJ | G18: Status Map, looked up by Employment Status (UKG 'A' maps to Y). | H18: Status Map | I18: "Position Status Not Mapped"
A19: term_date | B19: Term Date | C19: AN | D19: If Status = N: Termination Date formatted yyyymmdd. Otherwise blank. | E19: =IF(AL5="N",TEXT(M5,"yyyymmdd"),"") | F19: BK | G19: Always blank (the UKG sheet has no formula here). | H19: - | I19: Blank. A warning if the person is inactive with no date.
A20: invoice_access | B20: Invoice Access | C20: AO | D20: Invoice Exception Map (by File Number) returns Y or N and wins. Otherwise Y if the invoice limit is > 0, else N. | E20: =IFERROR(VLOOKUP(P5,'Invoice Exception Map'!A:C,3,FALSE),IF(AH5>0,"Y","N")) | F20: BL | G20: Invoice Exception Map (by Employee Number). Otherwise N. UKG never gets access from the pay grade. | H20: Invoice Exception Map, Salary Map | I20: N
A21: login_id | B21: Login ID | C21: - | D21: Config login_id rule: the first non-blank of ['work_email'], then prefix '', suffix '', replace_domain '', lowercase=False. With the current config this is the work email, unchanged. | E21: Not a workbook column (the workbook 305 builds it from the email) | F21: - | G21: Same rule as ADP. | H21: Config | I21: Blank, which is an error (no Login ID).

Sheet Record 100
A1: Record 100 - Import Settings
A2: The first line of every file. Built from config import_settings, not from the workbook. Current line: 100,0,SSO,UPDATE,EN,N,N
A4: Pos | B4: Col | C4: Field | D4: Current Value | E4: Allowed Values / Meaning
A5: 1 | B5: A | C5: Record Type | D5: 100 | E5: Constant
A6: 2 | B6: B | C6: Error Threshold | D6: 0 | E6: Errors allowed before the import stops. SAP says 0.
A7: 3 | B7: C | C7: Password Generation | D7: SSO | E7: EMPID | LOGINID | TEXT | SSO. SSO means the 305 password is ignored.
A8: 4 | B8: D | C8: Existing Record Handling | D8: UPDATE | E8: REPLACE | UPDATE | WARN | IGNORE. UPDATE writes only non-blank fields and never overwrites a password.
A9: 5 | B9: E | C9: Language Code | D9: EN | E9: Language of any localised text in the file.
A10: 6 | B10: F | C10: Validate Expense Group | D10: N | E10: Y | N (SAP default Y).
A11: 7 | B11: G | C11: Validate Payment Group | D11: N | E11: Y | N (SAP default Y).

Sheet Record 305
A1: Record 305 - Field Mapping
A2: Employee profile. Every employee, active and terminated. Password (G) is ignored because Password Generation = SSO. 137 positions, 29 filled. Every position is written, even when empty.
A4: Pos | B4: Col | C4: Concur Field | D4: ADP Value | E4: UKG Value | F4: Max Len | G4: Full Template Heading
A5: 1 | B5: A | C5: Trx Type | D5: Constant "305" | E5: Constant "305" | F5: 3 | G5: Trx Type (305)
A6: 2 | B6: B | C6: First Name | D6: ADP: Legal First Name (col B) [legal_first_name] | E6: UKG: Employee Name (Last Suffix, First MI) (col F), text after the comma [legal_first_name] | F6: 32
A7: 3 | B7: C | C7: Middle Name | D7: ADP: Middle Initial (col C) [middle_initial] | E7: (blank - no source) | F7: 32 | G7: Middle Name (required for travel ONLY if on traveler's ID)
A8: 4 | B8: D | C8: Last Name | D8: ADP: Legal Last Name (col D) [legal_last_name] | E8: UKG: Employee Name (Last Suffix, First MI) (col F), text before the comma [legal_last_name] | F8: 32
A9: 5 | B9: E | C9: Employee ID | D9: ADP: File Number (col P) [file_number] | E9: UKG: Employee Number (col D) [file_number] | F9: 48 | G9: Employee ID (Cannot be changed using this record - reference 320)
A10: 6 | B10: F | C10: Login ID | D10: Derived: Login ID [login_id] | E10: Derived: Login ID [login_id] | F10: 64 | G10: Login ID (Cannot be changed using this record - reference 320)
A11: 7 | B11: G | C11: Password | D11: Config "password" (currently "Welcome01"); a hand-keyed employee's own password wins | E11: Config "password" (currently "Welcome01"); a hand-keyed employee's own password wins | F11: 30 | G11: Password (only required if Password Gen in 100 = TEXT)
A12: 8 | B12: H | C12: Email Address | D12: ADP: Work Contact: Work Email (col I) [work_email] | E12: UKG: E-mail Address (col AQ) [work_email] | F12: 255 | G12: Email Address (required for Concur Travel & Expense)
A13: 9 | B13: I | C13: Locale Code | D13: Derived: Locale Code [locale_code] | E13: Derived: Locale Code [locale_code] | F13: 5
A14: 10 | B14: J | C14: Ctry Code | D14: Derived: Legal Country [legal_country] | E14: Derived: Legal Country [legal_country] | F14: 3
A15: 11 | B15: K | C15: Ctry Sub Code | F15: 6
A16: 12 | B16: L | C16: Ledger Code | D16: Derived: Org Unit 1 [org_unit_1] | E16: Derived: Ledger Code [concur_ledger_code] | F16: 20
A17: 13 | B17: M | C17: Reimbursement CRN Code | D17: Derived: Reimbursement Currency [reimbursement_currency] | E17: Derived: Reimbursement Currency [reimbursement_currency] | F17: 6
A18: 14 | B18: N | C18: Cash Advance Account Code | F18: 20
A19: 15 | B19: O | C19: Active | D19: Derived: Status [concur_status] | E19: Derived: Status [concur_status] | F19: 1 | G19: Active (Y/N)
A20: 16 | B20: P | C20: Org Unit 1 | D20: Derived: Org Unit 1 [org_unit_1] | E20: Derived: Org Unit 1 [org_unit_1] | F20: 48
A21: 17 | B21: Q | C21: Org Unit 2 | D21: Derived: Org Unit 2 [org_unit_2] | E21: Derived: Org Unit 2 [org_unit_2] | F21: 48
A22: 18 | B22: R | C22: Org Unit 3 | F22: 48
A23: 19 | B23: S | C23: Org Unit 4 | F23: 48
A24: 20 | B24: T | C24: Org Unit 5 | F24: 48
A25: 21 | B25: U | C25: Org Unit 6 | F25: 48
A26: 22 | B26: V | C26: Custom 1 | F26: 48
A27: 23 | B27: W | C27: Custom 2 | D27: ADP: Pay Grade Code (col AA) [pay_grade_code] | E27: UKG: Salary Grade (col Q) [pay_grade_code] | F27: 48
A28: 24 | B28: X | C28: Custom 3 | D28: Derived: Concur Profile [concur_profile] | E28: Derived: Concur Profile [concur_profile] | F28: 48
A29: 25 | B29: Y | C29: Custom 4 | F29: 48
A30: 26 | B30: Z | C30: Custom 5: UKG Site Location | D30: Derived: Org Unit 1 [org_unit_1] | E30: Derived: Custom 5 Code [concur_custom_5] | F30: 48
A31: 27 | B31: AA | C31: Custom 6 | F31: 48
A32: 28 | B32: AB | C32: Custom 7 | D32: Derived: Term Date [term_date] | E32: (blank - no source) | F32: 48
A33: 29 | B33: AC | C33: Custom 8 | D33: Derived: Preferred Name [preferred_name] | E33: (blank - no source) | F33: 48
A34: 30 | B34: AD | C34: Custom 9 | F34: 48
A35: 31 | B35: AE | C35: Custom 10 | D35: If column BU = Y then column AP, else blank | E35: If column BU = Y then constant "0088", else blank | F35: 48 | G35: Custom 10 - FMG Config uses this for Invoice Group
A36: 32 | B36: AF | C36: Custom 11 | F36: 48
A37: 33 | B37: AG | C37: Custom 12 | F37: 48
A38: 34 | B38: AH | C38: Custom 13 | F38: 48
A39: 35 | B39: AI | C39: Custom 14 | F39: 48
A40: 36 | B40: AJ | C40: Custom 15 | F40: 48
A41: 37 | B41: AK | C41: Custom 16 | F41: 48
...

Sheet Record 350
A1: Record 350 - Field Mapping
A2: Travel profile. ADP and hand-keyed employees only; UKG has no 350. Current scope: off. 67 positions, 5 filled. Every position is written, even when empty.
A4: Pos | B4: Col | C4: Concur Field | D4: ADP Value | E4: UKG Value | F4: Max Len | G4: Full Template Heading
A5: 1 | B5: A | C5: Trx Type | D5: Constant "350" | E5: n/a - UKG writes no 350 | F5: 3 | G5: Trx Type (350)
A6: 2 | B6: B | C6: Employee ID | D6: ADP: File Number (col P) [file_number] | E6: n/a - UKG writes no 350 | F6: 48
A7: 3 | B7: C | C7: Name Prefix | E7: n/a - UKG writes no 350 | F7: 60
A8: 4 | B8: D | C8: Name Suffix | E8: n/a - UKG writes no 350 | F8: 60
A9: 5 | B9: E | C9: Nick Name | E9: n/a - UKG writes no 350 | F9: 60
A10: 6 | B10: F | C10: Redress Number | E10: n/a - UKG writes no 350 | F10: 13
A11: 7 | B11: G | C11: Gender | E11: n/a - UKG writes no 350 | F11: 1
A12: 8 | B12: H | C12: Date of Birth | E12: n/a - UKG writes no 350 | F12: 10
A13: 9 | B13: I | C13: Employee ID of the Travel Approver | E13: n/a - UKG writes no 350 | F13: 128
A14: 10 | B14: J | C14: Job Title | E14: n/a - UKG writes no 350 | F14: 255
A15: 11 | B15: K | C15: Work Phone | E15: n/a - UKG writes no 350 | F15: 60
A16: 12 | B16: L | C16: Work Phone Extension | E16: n/a - UKG writes no 350 | F16: 60
A17: 13 | B17: M | C17: Work Fax | E17: n/a - UKG writes no 350 | F17: 60
A18: 14 | B18: N | C18: Home Phone | E18: n/a - UKG writes no 350 | F18: 60
... A21: 17 | B21: Q | C21: Travel Name Remark | E21: n/a - UKG writes no 350 | F21: 30
A22: 18 | B22: R | C22: Travel Class Name | D22: Derived: Travel Profile [travel_profile] | E22: n/a - UKG writes no 350 | F22: 60 | G22: Travel Class Name ***CA should convert to US*** •If employee salary level is H00 to Salary 19 then General xx (xx is 2 digit Country code). •If employee salary level is Salary 20 to Salary 23 then Senior Leadership xx (xx is 2 digit Country code). •If employee salary level is Salary 24 or greater than VIP xx (xx is 2 digit Country code).- exclude ELT ID's •If employee ID is listed below than ELT xx (xx is 2 digit Country code).
A23: 19 | B23: S | C23: GDS Profile Name | E23: n/a - UKG writes no 350 | F23: 60
A24: 20 | B24: T | C24: Org Unit/Division | D24: Derived: Org Unit 1 [org_unit_1] | E24: n/a - UKG writes no 350 | F24: 60 | G24: Org Unit/Division (Equals division code from 305 file, site location from UKG) except UK = Division Name
A25: 21 | B25: U | C25: Home Street Address | E25: n/a - UKG writes no 350 | F25: 255
A26: 22 | B26: V | C26: Home City | E26: n/a - UKG writes no 350 | F26: 30
A27: 23 | B27: W | C27: Home State | E27: n/a - UKG writes no 350 | F27: 30
A28: 24 | B28: X | C28: Home Postal Code | E28: n/a - UKG writes no 350 | F28: 20
A29: 25 | B29: Y | C29: Home Country | E29: n/a - UKG writes no 350 | F29: 2
A30: 26 | B30: Z | C30: Work Street Address | E30: n/a - UKG writes no 350 | F30: 255
A31: 27 | B31: AA | C31: Work City | E31: n/a - UKG writes no 350 | F31: 30
A32: 28 | B32: AB | C32: Work State | E32: n/a - UKG writes no 350 | F32: 30
A33: 29 | B33: AC | C33: Work Postal Code | E33: n/a - UKG writes no 350 | F33: 20
A34: 30 | B34: AD | C34: Work Country | E34: n/a - UKG writes no 350 | F34: 2
A35: 31 | B35: AE | C35: Email 2 | E35: n/a - UKG writes no 350 | F35: 255
A36: 32 | B36: AF | C36: Email 3 | E36: n/a - UKG writes no 350 | F36: 255
A37: 33 | B37: AG | C37: Custom 1 | D37: Derived: Org Unit 1 [org_unit_1] | E37: n/a - UKG writes no 350 | F37: 255 | G37: Custom 1 (Division) Format: BRNS_DIVISION=(code) Can come from Column 16 Org Unit 1 from the 305 file
A38: 34 | B38: AH | C38: Custom 2 | E38: n/a - UKG writes no 350 | F38: 255 | G38: Custom 2 (Department) Format: BRNS_DEPT=140400 Can come from Column 17, Org Unit 2 from 305 file
A39: 35 | B39: AI | C39: Custom 3 | E39: n/a - UKG writes no 350 | F39: 255 | G39: Custom 3 (Country of Employement) Format: COUNTRY_CODE=2 letter country code Can come from Column 10 Ctry Code from 305 file.
A40: 36 | B40: AJ | C40: Custom 4 | E40: n/a - UKG writes no 350 | F40: 255
A41: 37 | B41: AK | C41: Custom 5 | E41: n/a - UKG writes no 350 | F41: 255
A42: 38 | B42: AL | C42: Custom 6 | E42: n/a - UKG writes no 350 | F42: 255
A43: 39 | B43: AM | C43: Custom 7 | E43: n/a - UKG writes no 350 | F43: 255
...

Sheet Record 360
A1: Record 360 - Field Mapping
A2: Invoice / purchase request roles. Current scope: invoice. 35 positions, 11 filled. Every position is written, even when empty.
A4: Pos | B4: Col | C4: Concur Field | D4: ADP Value | E4: UKG Value | F4: Max Len | G4: Full Template Heading
A5: 1 | B5: A | C5: Trx Type | D5: Constant "360" | E5: Constant "360" | F5: 3 | G5: Trx Type (360)
A6: 2 | B6: B | C6: Employee ID | D6: ADP: File Number (col P) [file_number] | E6: UKG: Employee Number (col D) [file_number] | F6: 48
A7: 3 | B7: C | C7: Invoice User Role | D7: Derived: Invoice Access [invoice_access] | E7: Derived: Invoice Access [invoice_access] | F7: 1
A8: 4 | B8: D | C8: Invoice Approver Role | D8: Derived: Invoice Access [invoice_access] | E8: Derived: Invoice Access [invoice_access] | F8: 1
A9: 5 | B9: E | C9: Invoice Vendor Approver Role | F9: 1
A10: 6 | B10: F | C10: Invoice AP User Role | F10: 1
A11: 7 | B11: G | C11: Invoice Payment Manager Role | F11: 1
A12: 8 | B12: H | C12: Invoice Purchasing Role | D12: Derived: Invoice Access [invoice_access] | E12: Derived: Invoice Access [invoice_access] | F12: 1
A13: 9 | B13: I | C13: Purchase Request User | D13: Derived: Invoice Access [invoice_access] | E13: Derived: Invoice Access [invoice_access] | F13: 1
A14: 10 | B14: J | C14: Purchase Request Approver | D14: Derived: Invoice Access [invoice_access] | E14: Derived: Invoice Access [invoice_access] | F14: 1
A15: 11 | B15: K | C15: Future Use 3
A16: 12 | B16: L | C16: Future Use 4
A17: 13 | B17: M | C17: Future Use 5
A18: 14 | B18: N | C18: Future Use 6
A19: 15 | B19: O | C19: Future Use 7
A20: 16 | B20: P | C20: Send E-Mail When the Purchase Request Status Changes | F20: 1
A21: 17 | B21: Q | C21: Send E-Mail When the Purchase Request Is Awaiting Approval | F21: 1
A22: 18 | B22: R | C22: Default Purchase Request Approver Employee ID | D22: Derived: SupervisorID Formatted [supervisor_id] | E22: Derived: SupervisorID Formatted [supervisor_id] | F22: 48
A23: 19 | B23: S | C23: Payment Approver Employee ID | D23: Derived: SupervisorID Formatted [supervisor_id] | E23: Derived: SupervisorID Formatted [supervisor_id] | F23: 48
A24: 20 | B24: T | C24: Send E-Mail When the Payment Status Changes | F24: 1
A25: 21 | B25: U | C25: Send E-Mail When A Payment Is Awaiting Approval | F25: 1
A26: 22 | B26: V | C26: Prompt For Approver When Submitting a Payment | F26: 1
A27: 23 | B27: W | C27: Send E-Mail When The Payment Request Is Assigned To A User | F27: 1
A28: 24 | B28: X | C28: Send E-Mail When Request Is Assigned To Purchasing | F28: 1
A29: 25 | B29: Y | C29: Send E-Mail When A Request Is Sent Back From Purchasing | F29: 1
A30: 26 | B30: Z | C30: Send email when a fax image is available for a payment request | F30: 1
A31: 27 | B31: AA | C31: Prompt a user with a window to create new line items when creating a n | F31: 1 | G31: Prompt a user with a window to create new line items when creating a new payment request
A32: 28 | B32: AB | C32: Default Shipping Address | F32: 32
A33: 29 | B33: AC | C33: Display Image In-line | D33: Constant "Y" | E33: Derived: Invoice Access [invoice_access] | F33: 1
A34: 30 | B34: AD | C34: Auto Open Image | D34: Constant "Y" | E34: Constant "N" | F34: 1
A35: 31 | B35: AE | C35: Future Use 16
A36: 32 | B36: AF | C36: Future Use 17
A37: 33 | B37: AG | C37: Future Use 18
A38: 34 | B38: AH | C38: Future Use 19
A39: 35 | B39: AI | C39: Future Use 20

Sheet Record 700
A1: Record 700 - Field Mapping
A2: Payment approval authority. Written only for employees with Invoice Access = Y. Current scope: invoice. 16 positions, 5 filled. Every position is written, even when empty.
A4: Pos | B4: Col | C4: Concur Field | D4: ADP Value | E4: UKG Value | F4: Max Len | G4: Full Template Heading
A5: 1 | B5: A | C5: Trx Type | D5: Constant "700" | E5: Constant "700" | F5: 3 | G5: Trx Type (700)
A6: 2 | B6: B | C6: Approval Type | D6: Constant "PMT" | E6: Constant "PMT" | F6: 3
A7: 3 | B7: C | C7: Employee ID | D7: ADP: File Number (col P) [file_number] | E7: UKG: Employee Number (col D) [file_number] | F7: 48
A8: 4 | B8: D | C8: Segment 1 | F8: 32
A9: 5 | B9: E | C9: Segment 2 | F9: 32
A10: 6 | B10: F | C10: Segment 3 | F10: 32
A11: 7 | B11: G | C11: Segment 4 | F11: 32
A12: 8 | B12: H | C12: Segment 5 | F12: 32
A13: 9 | B13: I | C13: Segment 6 | F13: 32
A14: 10 | B14: J | C14: Segment 7 | F14: 32
A15: 11 | B15: K | C15: Segment 8 | F15: 32
A16: 12 | B16: L | C16: Segment 9 | F16: 32
A17: 13 | B17: M | C17: Segment 10 | F17: 32
A18: 14 | B18: N | C18: Exception Approval Authority | F18: 1
A19: 15 | B19: O | C19: Approval Limit | D19: Derived: Invoice Approval Limit [invoice_limit] | E19: Derived: Invoice Approval Limit [invoice_limit]
A20: 16 | B20: P | C20: Approval Limit Currency Code | D20: Derived: Reimbursement Currency [reimbursement_currency] | E20: Constant "USD" | F20: 3

Sheet Map Tables
A1: Map Tables
A2: Each lookup table: the workbook tab it is loaded from, the key it is looked up by, and what it returns. Rows are counted from the snapshot tabs.
A4: Guide Tab | B4: Database Table | C4: Workbook Tab | D4: Lookup Key | E4: Returns | F4: Used For | G4: Rows
A5: Map - Status | B5: ADP_Concur_StatusMap | C5: Status Map | D5: position_status | E5: concur_status | F5: Status (Y/N) | G5: =COUNTA('Map - Status'!A:A)-3
A6: Map - Country | B6: ADP_Concur_CountryMap | C6: Country Map (left block) | D6: adp_country (3-char) | E6: concur_country; currency_code | F6: Legal Country (both); Reimbursement Currency (UKG) | G6: =COUNTA('Map - Country'!A:A)-3
A7: Map - Org | B7: ADP_Concur_OrgMap | C7: Org Map | D7: business_unit_desc; home_department_code | E7: org_unit_1, default_language, currency (by BU); org_unit_2 (by dept code) | F7: ADP Org Unit 1, Org Unit 2, Locale fallback, Reimbursement Currency | G7: =COUNTA('Map - Org'!A:A)-3
A8: Map - Language | B8: ADP_Concur_LanguageMap | C8: Language Map (A:C) | D8: language_desc | E8: adp_language (stem 'xx_') | F8: ADP Locale Code | G8: =COUNTA('Map - Language'!A:A)-3
A9: Map - Locale | B9: ADP_Concur_LocaleMap | C9: Language Map (M:O) | D9: country_code (2-char) | E9: locale_code | F9: UKG Locale Code | G9: =COUNTA('Map - Locale'!A:A)-3
A10: Map - Salary | B10: ADP_Concur_SalaryMap | C10: Salary Map | D10: pay_grade_code (trimmed) | E10: expense_map, travel_map, invoice_map | F10: Concur Profile, Travel Profile, Invoice Limit, and ADP Invoice Access | G10: =COUNTA('Map - Salary'!A:A)-3
A11: Map - Supervisor | B11: ADP_Concur_SupervisorMap | C11: Supervisor Map | D11: file_number (the employee) | E11: supervisor_id | F11: Supervisor ID override (wins over the export) | G11: =COUNTA('Map - Supervisor'!A:A)-3
A12: Map - Invoice | B12: ADP_Concur_InvoiceMap | C12: Invoice Exception Map | D12: file_number (trimmed) | E12: access (Y/N) | F12: Invoice Access override | G12: =COUNTA('Map - Invoice'!A:A)-3
A13: Map - Company | B13: ADP_Concur_CompanyMap | C13: UKG Company Map | D13: site_location_code | E13: concur_company_code, expense_group_code, ledger_code, custom_5_code | F13: UKG Org Unit 1, Custom 21, Ledger Code, Custom 5 | G13: =COUNTA('Map - Company'!A:A)-3
A14: Map - CountryRef | B14: ADP_Concur_CountryRef | C14: Country Map (right block) | D14: country_code (2-char) | E14: currency_code | F14: Reference only | G14: =COUNTA('Map - CountryRef'!A:A)-3
A15: Map - Role | B15: ADP_Concur_RoleMap | C15: Role Map | D15: role | E15: automatic (Y/N) | F15: Reference only; the record builders do not read it | G15: =COUNTA('Map - Role'!A:A)-3

Sheet Config
A1: Config - ADP_Concur_Config.json
A2: Current values against the code defaults in ADP_Concur_Map.DEFAULT_CONFIG. Yellow = the file overrides the default.
A4: Setting | B4: Key | C4: Current Value | D4: Code Default | E4: What It Does
A5: login_id | B5: sources | C5: ["work_email"] | D5: ["work_email"] | E5: How the Login ID is built. See Derived Fields: login_id.
A6: login_id | B6: suffix | C6: "" | D6: .new.uat | E6: How the Login ID is built. See Derived Fields: login_id.
A7: login_id | B7: replace_domain | C7: "" | D7: "" | E7: How the Login ID is built. See Derived Fields: login_id.
A8: login_id | B8: prefix | C8: "" | D8: "" | E8: How the Login ID is built. See Derived Fields: login_id.
A9: login_id | B9: lowercase | C9: false | D9: false | E9: How the Login ID is built. See Derived Fields: login_id.
A10: login_id | B10: bare_domain | C10: "" | D10: "" | E10: How the Login ID is built. See Derived Fields: login_id.
A11: login_id_by_source | C11: {} | D11: {} | E11: Per-source overrides merged over login_id.
A12: password | C12: Welcome01 | D12: Welcome01 | E12: The 305 password (G). Ignored while Password Generation = SSO.
A13: import_settings | B13: error_threshold | C13: 0 | D13: 0 | E13: The 100 record. See Record 100.
A14: import_settings | B14: password_generation | C14: SSO | D14: SSO | E14: The 100 record. See Record 100.
A15: import_settings | B15: existing_record_handling | C15: UPDATE | D15: UPDATE | E15: The 100 record. See Record 100.
A16: import_settings | B16: language_code | C16: EN | D16: EN | E16: The 100 record. See Record 100.
A17: import_settings | B17: validate_expense_group | C17: N | D17: N | E17: The 100 record. See Record 100.
A18: import_settings | B18: validate_payment_group | C18: N | D18: N | E18: The 100 record. See Record 100.
A19: records_by_source | B19: adp | C19: ["305", "350", "360", "700"] | D19: ["305", "350", "360", "700"] | E19: Which record types each source can write.
A20: records_by_source | B20: ukg | C20: ["305", "360", "700"] | D20: ["305", "360", "700"] | E20: Which record types each source can write.
A21: records_by_source | B21: manual | C21: ["305", "350", "360", "700"] | D21: ["305", "350", "360", "700"] | E21: Which record types each source can write.
A22: scope | B22: 305 | C22: all | D22: all | E22: Who each record type covers: all | invoice (Invoice Access = Y) | off.
A23: scope | B23: 350 | C23: off | D23: all | E23: Who each record type covers: all | invoice (Invoice Access = Y) | off.
A24: scope | B24: 360 | C24: invoice | D24: all | E24: Who each record type covers: all | invoice (Invoice Access = Y) | off.
... A31: extract | B31: quote | C31: minimal | D31: minimal | E31: File shape: delimiter, quoting, line ending, order, file name, output folder.
A32: extract | B32: line_ending | E32: File shape: delimiter, quoting, line ending, order, file name, output folder.
A33: extract | B33: encoding | C33: utf-8 | D33: utf-8 | E33: File shape: delimiter, quoting, line ending, order, file name, output folder.
A34: extract | B34: order | C34: by_type | D34: by_type | E34: File shape: delimiter, quoting, line ending, order, file name, output folder.
A35: extract | B35: file_name | C35: FMG_Concur_Employee_{stamp}.txt | D35: FMG_Concur_Employee_{stamp}.txt | E35: File shape: delimiter, quoting, line ending, order, file name, output folder.
A36: extract | B36: selection_file_name | C36: FMG_Concur_Employee_Selection_{stamp}.txt | D36: FMG_Concur_Employee_Selection_{stamp}.txt | E36: File shape: delimiter, quoting, line ending, order, file name, output folder.
A37: extract | B37: outbound_dir | C37: "" | D37: "" | E37: File shape: delimiter, quoting, line ending, order, file name, output folder.
A38: block_on | B38: unmapped | C38: true | D38: true | E38: Which problems keep an employee out of the file (true) or only warn (false).
A39: block_on | B39: missing_login_id | C39: true | D39: true | E39: Which problems keep an employee out of the file (true) or only warn (false).
A40: block_on | B40: missing_employee_id | C40: true | D40: true | E40: Which problems keep an employee out of the file (true) or only warn (false).
A41: block_on | B41: broken_supervisor | C41: true | D41: true | E41: Which problems keep an employee out of the file (true) or only warn (false).
A42: block_on | B42: org_unit_2_code | C42: false | D42: false | E42: Which problems keep an employee out of the file (true) or only warn (false).

Sheet Validation
A1: Validation - Exceptions
A2: Rebuilt on every derive into ADP_Concur_Exceptions. Any Error keeps that employee out of every record type in the extract.
A4: Field | B4: Condition | C4: Current Severity | D4: Controlled By
A5: file_number | B5: No File Number | C5: Error (excluded) | D5: block_on.missing_employee_id
A6: login_id | B6: No Login ID (no source value for the rule) | C6: Error (excluded) | D6: block_on.missing_login_id
A7: work_email | B7: No work email in the export | C7: Warning | D7: -
A8: <any derived> | B8: A value contains a '... Not Mapped' / '... Not Matched' text. Terminated people are included too, because Concur checks the hierarchy node before status. | C8: Error (excluded) | D8: block_on.unmapped
A9: supervisor_id | B9: An active employee with no supervisor | C9: Warning | D9: -
A10: term_date | B10: Inactive (Status N) but no Termination Date | C10: Warning | D10: -
A11: duplicate_rows | B11: More than one export row for the File Number, or the person is in both ADP and UKG | C11: Warning | D11: -
A12: invoice_limit | B12: Invoice Access Y (from the exception map) but the grade's limit is 0 | C12: Warning | D12: -
A13: org_unit_2 | B13: Org Unit 2 is a name, not a numeric code. Concur's connected list rejects it. | C13: Warning | D13: block_on.org_unit_2_code
A14: supervisor_chain | B14: The supervisor is not in the load, the person reports to themselves, or the chain loops | C14: Error (excluded) | D14: block_on.broken_supervisor
A15: supervisor_chain | B15: The supervisor comes from the other system (ADP <-> UKG) | C15: Warning | D15: -
... A18: password | B18: Passwords run in an unbroken fill series (5 or more, e.g. Welcome01..Welcome82) | C18: Warning | D18: -

Sheet Map - Status
A1: Status Map -> ADP_Concur_StatusMap
A2: Snapshot of the live table taken 2026-09-29. Edit maps in the app, not here.
A4: position_status | B4: concur_status
A5: Active | B5: Y
A6: Terminated | B6: N
A7: Retired | B7: N
A8: Leave | B8: Y
A9: Leave of absence | B9: N

Sheet Map - Country
A1: Country Map (left block) -> ADP_Concur_CountryMap
A2: Snapshot of the live table taken 2026-09-29. Edit maps in the app, not here.
A4: adp_country | B4: concur_country | C4: country_name | D4: currency_code | E4: currency_name
A5: USA | B5: US | C5: United States | D5: USD | E5: US Dollar
A6: CHN | B6: CN | C6: China | D6: CNY | E6: Chinese Yuan (Renminbi)
A7: DEU | B7: DE | C7: Germany | D7: EUR | E7: Euro
A8: ESP | B8: ES | C8: Spail | D8: EUR | E8: Euro
A9: FRA | B9: FR | C9: France | D9: EUR | E9: Euro
A10: GBR | B10: GB | C10: United Kingdom | D10: GBP | E10: Pound Sterling
A11: IND | B11: IN | C11: India | D11: INR | E11: Indian Rupee
A12: KOR | B12: KR | C12: South Korea | D12: KRW | E12: South Korean Won
A13: MEX | B13: MX | C13: Mexico | D13: MXN | E13: Mexican Peso
A14: SWE | B14: SE | C14: Sweden | D14: SEK | E14: Swedish Krona
A15: SGP | B15: SG | C15: Singapore | D15: SGD | E15: Singapore Dollar
A16: JPN | B16: JP | C16: Japan | D16: JPY | E16: Japanese Yen

Sheet Map - Org
A1: Org Map -> ADP_Concur_OrgMap
A2: Snapshot of the live table taken 2026-09-29. Edit maps in the app, not here.
A4: business_unit_desc | B4: home_department_desc | C4: home_department_code | D4: org_unit_1 | E4: org_unit_2 | F4: default_language | G4: currency
A5: 025-NGP Hyson Products | B5: CNC Lathe Hyson | C5: 000100 | D5: 0096 | E5: 100 | F5: en_ | G5: USD
A6: 025-NGP Hyson Products | B6: Assembly Hyson | C6: 000200 | D6: 0096 | E6: 200 | F6: en_ | G6: USD
A7: 025-NGP Hyson Products | B7: Edgework- Hyson | C7: 000350 | D7: 0096 | E7: 350 | F7: en_ | G7: USD
A8: 025-NGP Hyson Products | B8: Indirect General -Hyson | C8: 000400 | D8: 0096 | E8: 400 | F8: en_ | G8: USD
A9: 025-NGP Hyson Products | B9: Maintenance-Hyson | C9: 000450 | D9: 0096 | E9: 450 | F9: en_ | G9: USD
A10: 025-NGP Hyson Products | B10: Quality | C10: 000500 | D10: 0096 | E10: 500 | F10: en_ | G10: USD
A11: 025-NGP Hyson Products | B11: Factory Super-Hyson | C11: 000515 | D11: 0096 | E11: 515 | F11: en_ | G11: USD
A12: 025-NGP Hyson Products | B12: Warehouse | C12: 000555 | D12: 0096 | E12: 555 | F12: en_ | G12: USD
A13: 025-NGP Hyson Products | B13: R&D | C13: 000713 | D13: 0096 | E13: 713 | F13: en_ | G13: USD
A14: 025-NGP Hyson Products | B14: Engineering | C14: 000718 | D14: 0096 | E14: 718 | F14: en_ | G14: USD
A15: 025-NGP Hyson Products | B15: Project Management | C15: 000801 | D15: 0096 | E15: 801 | F15: en_ | G15: USD
... A38: 088-AS Raymond | B38: Admin-Quality | C38: 009500 | D38: 0088 | E38: 9500 | F38: en_ | G38: USD
A39: 0088 | B39: (0088) AS Raymond
A40: 0096 | B40: (0096) NGP Hyson Products

Sheet Map - Language
A1: Language Map (A:C) -> ADP_Concur_LanguageMap
A2: Snapshot of the live table taken 2026-09-29. Edit maps in the app, not here.
A4: language_desc | B4: language_code | C4: adp_language
A5: English | B5: 4 | C5: en_
A6: Tamil | B6: 24 | C6: en_
A7: Bulgarian | C7: bg_
A8: Chinese | C8: zh_
A9: Croatian | C9: hr_
A10: Czech | C10: cs_
A11: Danish | C11: da_
A12: Dutch | C12: nl_
A13: Finnish | C13: fi_
A14: French | C14: fr_
A15: German | C15: de_
A16: Greek | C16: el_
A17: Hungarian | C17: hu_
A18: Indonesian | C18: id_
... A35: Vietnamese | C35: vi_

Sheet Map - Locale
A1: Language Map (M:O) -> ADP_Concur_LocaleMap
A2: Snapshot of the live table taken 2026-09-29. Edit maps in the app, not here.
A4: country_code | B4: locale_name | C4: locale_code
A5: AU | B5: English (Australia) | C5: en_AU
A6: CA | B6: English (Canada) | C6: en_CA
A7: IE | B7: English (Ireland) | C7: en_IE
A8: IN | B8: English (India) | C8: en_IN
A9: NZ | B9: English (New Zealand) | C9: en_NZ
A10: US | B10: English (United States) | C10: en_US
A11: ZA | B11: English (South Africa) | C11: en_ZA
A12: BG | B12: Bulgarian (Bulgaria) | C12: bg_BG
A13: CN | B13: Chinese (China) | C13: zh_CN
A14: HK | B14: Chinese (Hong Kong, China) | C14: zh_HK
A15: TW | B15: Chinese (Taiwan, China) | C15: zh_TW
... A66: VN | B66: Vietnamese (Vietnam) | C66: vi_VN

Sheet Map - Salary
A1: Salary Map -> ADP_Concur_SalaryMap
A2: Snapshot of the live table taken 2026-09-29. Edit maps in the app, not here.
A4: pay_grade_code | B4: pay_grade_desc | C4: expense_map | D4: travel_map | E4: invoice_map
A5: S24 | B5: FMG-S24 | C5: Officers | D5: VIP
A6: S23 | B6: FMG-S23 | C6: Grade 20 | D6: Senior Leadership US
A7: S22 | B7: FMG-S22 | C7: Grade 20 | D7: Senior Leadership US | E7: 999999999.99
A8: S21 | B8: FMG-S21 | C8: Grade 20 | D8: Senior Leadership US | E8: 1000000
A9: S20 | B9: FMG-S20 | C9: Grade 20 | D9: Senior Leadership US | E9: 100000
A10: S19 | B10: FMG-S19 | C10: Default | D10: General US | E10: 100000
A11: S18 | B11: FMG-S18 | C11: Default | D11: General US | E11: 25000
A12: S17 | B12: FMG-S17 | C12: Default | D12: General US | E12: 25000
A13: S16 | B13: FMG-S16 | C13: Default | D13: General US | E13: 25000
A14: S15 | B14: FMG-S15 | C14: Default | D14: General US | E14: 0
A15: S14 | B15: FMG-S14 | C15: Default | D15: General US | E15: 0
A16: S13 | B16: FMG-S13 | C16: Default | D16: General US | E16: 0
A17: S12 | B17: FMG-S12 | C17: Default | D17: General US | E17: 0
A18: S11 | B18: FMG-S11 | C18: Default | D18: General US | E18: 0
... A40: H0000 | B40: FMG-H0000 | C40: Default | D40: General US | E40: 0

Sheet Map - Supervisor
A1: Supervisor Map -> ADP_Concur_SupervisorMap
A2: Snapshot of the live table taken 2026-09-29. Edit maps in the app, not here.
A4: file_number | B4: employee_name | C4: supervisor_name | D4: supervisor_id | E4: note
A5: 902688 | B5: Bailey, Jason | C5: Kemenah, Greg | D5: 211766
A6: 209579 | B6: Barry, Kirsten | C6: Rodriguez, Siobhan | D6: 207588
A7: 900848 | B7: Finch, Jeffrey | C7: Erdogan, Mehmet | D7: 207199
A8: 902627 | B8: Garber, Anne | C8: Bate, Natalie | D8: 213037
A9: 212052 | B9: Moavero, Anthony | C9: Brower, James | D9: 006769
A10: 209181 | B10: Oleksa, Laura | C10: Adewalure, Babatunde | D10: 203011
A11: 207709 | B11: Bair, Teresa | E11: Top of food chain - blank supervisor

Sheet Map - Invoice
A1: Invoice Exception Map -> ADP_Concur_InvoiceMap
A2: Snapshot of the live table taken 2026-09-29. Edit maps in the app, not here.
A4: file_number | B4: employee_name | C4: access
A5: 007861 | B5: Amy McGuire | C5: Y
A6: 203011 | B6: Babatunde Adewalure | C6: Y
A7: 902437 | B7: Bradley Masters | C7: N
A8: 007630 | B8: Candi Morals | C8: Y
A9: 212478 | B9: Carol Phillips | C9: N
A10: 213331 | B10: Gregory Adams | C10: N
A11: 203036 | B11: Jean-Philippe Duvillard | C11: Y
A12: 210018 | B12: Jeff Raese | C12: N
A13: 212146 | B13: Joyce Spilza | C13: Y
A14: 209579 | B14: Kirsten Barry | C14: N
A15: 902013 | B15: Kugagini Thineshkumar | C15: Y
... A27: 212705 | B27: Bonnetta Warren | C27: Y

Sheet Map - Company
A1: UKG Company Map -> ADP_Concur_CompanyMap
A2: Snapshot of the live table taken 2026-09-29. Edit maps in the app, not here.
A4: site_location | B4: site_location_code | C4: concur_company_code | D4: concur_company_desc | E4: expense_group_code | F4: ledger_code | G4: custom_5_code
A5: ASI Raymond China | B5: 0083 | C5: 0083 | D5: Raymond China | E5: 0083 | F5: 0083 | G5: 0083
A6: NGP China | B6: 0079 | C6: 0079 | D6: NP China | E6: 0079 | F6: 0079 | G6: 0079
A7: Barnes Acquisition Group | B7: 0400 | C7: 0400 | E7: 0400 | F7: 0400 | G7: 0400
A8: ASI Raymond France | B8: 127 | C8: 0055 | D8: Raymond France | E8: 0055 | F8: 0055 | G8: 0055
A9: ASI Raymond UK | B9: 0035 | C9: 0035 | D9: Raymond - UK | E9: 0035 | F9: 0035 | G9: 0035
A10: NGP IGS UK | B10: 0218 | C10: 0218 | D10: Industrial Gas Springs Ltd (UK) | E10: 0218 | F10: 0218 | G10: 0218
A11: NGP United Kingdom | B11: 0219 | C11: 0114 | D11: Industrial Gas Springs Ltd (UK) | E11: 0114 | F11: 0114 | G11: 0114
A12: NGP India | B12: 176 | C12: 26 | D12: NP India | E12: 26 | F12: 26 | G12: 0026
A13: MAI Maenner Japan | B13: 406 | C13: 0406 | D13: Männer Japan | E13: 0406 | F13: 0406 | G13: 0406
A14: SMS Japan | B14: 0463 | C14: 0463 | D14: SMS Japan | E14: 0463 | F14: 0463 | G14: 0463
A15: NGP Korea | B15: 179 | C15: 34 | D15: NP Korea | E15: 34 | F15: 34 | G15: 0034
A16: Raymond Distribution – MX | B16: 0084 | C16: 0084 | D16: Raymond Mexico | E16: 0084 | F16: 0084 | G16: 0084
A17: MX Nitrogen Division | B17: 0075 | C17: 0075 | D17: NGP Mexico | E17: 0075 | F17: 0075 | G17: 0075
A18: NGP Sweden | B18: 0077 | C18: 0077 | D18: Stromsholmen | E18: 0077 | F18: 0077 | G18: 0077
A19: NGP Sweden | B19: 177 | C19: 0077 | D19: Stromsholmen | E19: 0077 | F19: 0077 | G19: 0077
A20: ASI Raymond Singapore | B20: 0057 | C20: 0057 | D20: Raymond Singapore | E20: 0057 | F20: 0057 | G20: 0057

Sheet Map - CountryRef
A1: Country Map (right block) -> ADP_Concur_CountryRef
A2: Snapshot of the live table taken 2026-09-29. Edit maps in the app, not here.
A4: country_code | B4: country_name | C4: currency_code | D4: currency_name
A5: US | B5: United States | C5: USD | D5: US Dollar
A6: CN | B6: China | C6: CNY | D6: Chinese Yuan (Renminbi)
A7: DE | B7: Germany | C7: EUR | D7: Euro
A8: ES | B8: Spail | C8: EUR | D8: Euro
A9: FR | B9: France | C9: EUR | D9: Euro
A10: GB | B10: United Kingdom | C10: GBP | D10: Pound Sterling
A11: IN | B11: India | C11: INR | D11: Indian Rupee
A12: KR | B12: South Korea | C12: KRW | D12: South Korean Won
A13: MX | B13: Mexico | C13: MXN | D13: Mexican Peso
A14: SE | B14: Sweden | C14: SEK | D14: Swedish Krona
A15: SG | B15: Singapore | C15: SGD | D15: Singapore Dollar
A16: JP | B16: Japan | C16: JPY | D16: Japanese Yen

Sheet Map - Role
A1: Role Map -> ADP_Concur_RoleMap
A2: Snapshot of the live table taken 2026-09-29. Edit maps in the app, not here.
A4: role | B4: category | C4: automatic
A5: Card Program Administrator | B5: Admin | C5: N
A6: Cognos Business Author | B6: Admin | C6: N
A7: Employee Administrator | B7: Admin | C7: N
A8: Invoice Configuration Administrator (Restricted) | B8: Admin | C8: N
A9: Invoice Proxy Logon | B9: Admin | C9: N
A10: Reimbursement Manager | B10: Admin | C10: N
A11: Role Administrator | B11: Admin | C11: N
A12: Expense User | B12: Expense | C12: Y
A13: Expense Processor | B13: Expense | C13: Y
A14: Expense Processor (Audit) | B14: Expense | C14: Y
A15: Expense Proxy Logon | B15: Expense | C15: Y
... A25: Purchase Request Processor (Audit) | B25: Payables | C25: N
