Workbook

Sheet Multiple Payrolls
A1: Details for Count of Payroll Company Code
A3: Payroll Company Code | B3: Legal First Name | C3: Middle Initial | D3: Legal Last Name | E3: Preferred or Chosen First Name | F3: Preferred or Chosen Last Name | G3: Reports To Legal Name | H3: Supervisor ID | I3: Work Contact: Work Email | J3: Personal Contact: Personal Email | K3: Job Title Description | L3: Hire Date | M3: Termination Date | N3: Rehire Date | O3: Position Status | P3: File Number | Q3: Pay Frequency | R3: Employee Type | S3: Business Unit Code | T3: Business Unit Description | U3: Home Department Description | V3: Home Department Code | W3: Location Description | X3: Language Description | Y3: Language Code | Z3: Legal / Preferred Address: Country Code | AA3: Pay Grade Code | AB3: Pay Grade Description | AC3: SupervisorID Formatted | AD3: Org Unit 1 | AE3: Org Unit 2 | AF3: Concur Profile | AG3: Travel Profile | AH3: Legal Country | AI3: Local Code | AJ3: Reumbursement Currency | AK3: Perferred Name | AL3: Status | AM3: Term Date | AN3: 7/20/26 | AO3: Name | AP3: SupervisorLastName | AQ3: Lookup Supervisor ID | AR3: SupervisorName=Supervisor ID
A4: KSX | B4: Abdellatef | C4: M | D4: Mahmoud | G4: Burchell, Mathew | H4: KSY211756 | J4: oomer77@yahoo.com | K4: Assistant, Warehouse II | L4: 45208 | O4: Active | P4: 210316 | Q4: Biweekly | R4: Full Time | S4: 088 | T4: 088-AS Raymond | U4: Assembly | V4: 005100 | W4: AS Raymond | Z4: USA | AA4: S05 | AB4: FMG-S05 | AC4: 211756 | AD4: 0088 | AE4: 5100 | AF4: Default | AG4: General | AH4: US | AI4: en_US | AJ4: USD | AL4: Y | AO4: AbdellatefMMahmoud | AP4: Burchell | AQ4: 211756 | AR4: TRUE
A5: KSY | B5: Alex | D5: Palicki | G5: Creager, Andrew | H5: KSY212699 | I5: apalicki@onebarnes.com | J5: alexpalicki4@gmail.com | K5: Buyer III | L5: 45831 | O5: Active | P5: 212119 | Q5: Monthly | R5: Full Time | S5: 088 | T5: 088-AS Raymond | U5: Admin-Material Management | V5: 009400 | W5: AS Raymond | Z5: USA | AA5: S13 | AB5: FMG-S13 | AC5: 212699 | AD5: 0088 | AE5: 9400 | AF5: Default | AG5: General | AH5: US | AI5: en_US | AJ5: USD | AL5: Y | AO5: AlexPalicki | AP5: Creager | AQ5: 212699 | AR5: TRUE
A6: KSX | B6: Amir | D6: Dillard | G6: Burchell, Mathew | H6: KSY211756 | I6: adillard1@onebarnes.com | J6: amirdillard4@gmail.com | K6: Assistant, Warehouse II | L6: 45754 | O6: Active | P6: 211895 | Q6: Biweekly | R6: Full Time | S6: 088 | T6: 088-AS Raymond | U6: Assembly | V6: 005100 | W6: AS Raymond | Z6: USA | AA6: S05 | AB6: FMG-S05 | AC6: 211756 | AD6: 0088 | AE6: 5100 | AF6: Default | AG6: General | AH6: US | AI6: en_US | AJ6: USD | AL6: Y | AO6: AmirDillard | AP6: Burchell | AQ6: 211756 | AR6: TRUE
A7: V0U | B7: Amy | C7: C | D7: McGuire | G7: Warner, Dwight | H7: V0U008750 | I7: AMcGuire@onebarnes.com | J7: RedAmyMcG@gmail.com | K7: Accountant III | L7: 35338 | O7: Active | P7: 007861 | Q7: Monthly | R7: Full Time | S7: 025 | T7: 025-NGP Hyson Products | U7: Finance | V7: 000910 | W7: Hyson Products | Z7: USA | AA7: S13 | AB7: FMG-S13 | AC7: 008750 | AD7: 0096 | AE7: 910 | AF7: Default | AG7: General | AH7: US | AI7: en_US | AJ7: USD | AL7: Y | AO7: AmyCMcGuire | AP7: Warner | AQ7: 008750 | AR7: TRUE
A8: KSY | B8: Andrew | C8: J | D8: Creager | G8: Bailey, Jason | H8: KSY211766 | I8: acreager@onebarnes.com | K8: Mgr, Supply Chain III | L8: 45957 | O8: Active | P8: 212699 | Q8: Monthly | R8: Full Time | S8: 088 | T8: 088-AS Raymond | U8: Admin-Material Management | V8: 009400 | W8: AS Raymond | Z8: USA | AA8: S17 | AB8: FMG-S17 | AC8: 211766 | AD8: 0088 | AE8: 9400 | AF8: Default | AG8: General | AH8: US | AI8: en_US | AJ8: USD | AL8: Y | AO8: AndrewJCreager | AP8: Bailey | AQ8: 902688 | AR8: FALSE
A9: KSX | B9: Angela | D9: Myers | G9: Burchell, Mathew | H9: KSY211756 | J9: amm823@bex.net | K9: Assistant, Warehouse II | L9: 45881 | O9: Active | P9: 212349 | Q9: Biweekly | R9: Full Time | S9: 088 | T9: 088-AS Raymond | U9: Assembly | V9: 005100 | W9: AS Raymond | Z9: USA | AA9: S05 | AB9: FMG-S05 | AC9: 211756 | AD9: 0088 | AE9: 5100 | AF9: Default | AG9: General | AH9: US | AI9: en_US | AJ9: USD | AL9: Y | AO9: AngelaMyers | AP9: Burchell | AQ9: 211756 | AR9: TRUE
A10: V0U | B10: Anne | C10: M | D10: Garber | G10: Bate, Natalie | I10: agarber@onebarnes.com | J10: anne.michael00@gmail.com | K10: Mgr, Program | L10: 46265 | O10: Active | P10: 902627 | Q10: Monthly | R10: Full Time | S10: 025 | T10: 025-NGP Hyson Products | U10: Administration | V10: 000917 | W10: Hyson Products | Z10: USA | AA10: S17 | AB10: FMG-S17 | AD10: 0096 | AE10: 0007 | AF10: Default | AG10: General | AH10: US | AI10: en_US | AJ10: USD | AL10: Y | AO10: AnneMGarber | AP10: Bate | AQ10: 213037 | AR10: FALSE
A11: KSW | B11: Anthony | D11: Desillas | J11: desillasa@yahoo.com | K11: Lathe Operator | L11: 45859 | M11: 46046 | O11: Terminated | P11: 212244 | Q11: Biweekly | R11: Full Time | S11: 025 | T11: 025-NGP Hyson Products | U11: CNC Lathe Hyson | V11: 000100 | W11: Hyson Products | Z11: USA | AA11: H07 | AB11: FMG-H07 | AD11: 0096 | AE11: 100 | AF11: Default | AG11: General | AH11: US | AI11: en_US | AJ11: USD | AL11: N | AM11: 20260124 | AN11: Exclude record termination over 45 days ago | AO11: AnthonyDesillas | AP11: #VALUE! | AQ11: No Reports to Name | AR11: FALSE
A12: KSW | B12: Anthony | C12: J | D12: Frimel | G12: Steen, Michael | H12: V0U211062 | I12: afrimel@onebarnes.com | J12: tfrimel@att.net | K12: Tech, Manufacturing A | L12: 37410 | O12: Active | P12: 004352 | Q12: Biweekly | R12: Full Time | S12: 025 | T12: 025-NGP Hyson Products | U12: CNC Lathe Hyson | V12: 000100 | W12: Hyson Products | Z12: USA | AA12: H08 | AB12: FMG-H08 | AC12: 211062 | AD12: 0096 | AE12: 100 | AF12: Default | AG12: General | AH12: US | AI12: en_US | AJ12: USD | AL12: Y | AO12: AnthonyJFrimel | AP12: Steen | AQ12: 211062 | AR12: TRUE
A13: V0U | B13: Anthony | C13: J | D13: Moavero | G13: Brower, James | I13: amoavero1@onebarnes.com | K13: Intern, Engineering Indir | L13: 45810 | M13: 46176 | O13: Terminated | P13: 212052 | Q13: Monthly | R13: Intern | S13: 025 | T13: 025-NGP Hyson Products | U13: Sustaining Engineering | V13: 000900 | W13: Hyson Products | Z13: USA | AA13: H05 | AB13: FMG-H05 | AD13: 0096 | AE13: 900 | AF13: Default | AG13: General | AH13: US | AI13: en_US | AJ13: USD | AL13: N | AM13: 20260603 | AN13: Fix and Include Record | AO13: AnthonyJMoavero | AP13: Brower | AQ13: 006769 | AR13: FALSE
A14: KSX | B14: Anthony | C14: J | D14: Moavero | I14: amoavero1@onebarnes.com | L14: 45810 | M14: 45878 | O14: Terminated | P14: 212052 | Q14: Biweekly | R14: Full Time | W14: AS Raymond | Z14: USA | AD14: BU Description Not Mapped | AE14: Home Department Code Not Mapped | AF14: Salary Code Not Mapped | AG14: Salary Code Not Mapped | AH14: US | AI14: ADP and BU Language Code Not MappedUS | AJ14: BU Currency Not Mapped | AL14: N | AM14: 20250809 | AN14: Exclude record termination over 45 days ago | AO14: AnthonyJMoavero | AP14: #VALUE! | AQ14: No Reports to Name | AR14: FALSE
A15: KSW | B15: Anthony | C15: J | D15: Moavero | G15: Brower, James | H15: V0U006769 | I15: amoavero1@onebarnes.com | K15: Intern, Engineering Indir | L15: 45810 | M15: 46248 | O15: Terminated | P15: 212052 | Q15: Biweekly | R15: Intern | S15: 025 | T15: 025-NGP Hyson Products | U15: Sustaining Engineering | V15: 000900 | W15: Hyson Products | Z15: USA | AA15: H05 | AB15: FMG-H05 | AC15: 006769 | AD15: 0096 | AE15: 900 | AF15: Default | AG15: General | AH15: US | AI15: en_US | AJ15: USD | AL15: N | AM15: 20260814 | AN15: Exclude record termination over 45 days ago | AO15: AnthonyJMoavero | AP15: Brower | AQ15: 006769 | AR15: TRUE
A16: V0U | B16: Anthony | C16: J | D16: Moavero | G16: Brower, James | I16: amoavero1@onebarnes.com | K16: Intern, Engineering Indir | L16: 45810 | M16: 46176 | O16: Terminated | P16: 212052 | Q16: Biweekly | R16: Intern | S16: 025 | T16: 025-NGP Hyson Products | U16: Sustaining Engineering | V16: 000900 | W16: Hyson Products | Z16: USA | AA16: H05 | AB16: FMG-H05 | AD16: 0096 | AE16: 900 | AF16: Default | AG16: General | AH16: US | AI16: en_US | AJ16: USD | AL16: N | AM16: 20260603 | AN16: Fix and Include Record | AO16: AnthonyJMoavero | AP16: Brower | AQ16: 006769 | AR16: FALSE
A17: KSX | B17: Asia | D17: Sexton | G17: Burchell, Mathew | H17: KSY211756 | J17: asexton@yahoo.com | K17: Assistant, Warehouse II | L17: 46190 | M17: 46251 | O17: Terminated | Q17: Biweekly | R17: Temporary | S17: 088 | T17: 088-AS Raymond | U17: Assembly | V17: 005100 | W17: AS Raymond | Z17: USA | AA17: S05 | AB17: FMG-S05 | AC17: 211756 | AD17: 0088 | AE17: 5100 | AF17: Default | AG17: General | AH17: US | AI17: en_US | AJ17: USD | AL17: N | AM17: 20260817 | AN17: Fix and Include Record | AO17: AsiaSexton | AP17: Burchell | AQ17: 211756 | AR17: TRUE
A18: KSX | B18: Aydrian | C18: M | D18: Ahrens | G18: Burchell, Mathew | H18: KSY211756 | J18: aydrian0323@yahoo.com | K18: Assistant, Warehouse II | L18: 45754 | O18: Active | P18: 211901 | Q18: Biweekly | R18: Full Time | S18: 088 | T18: 088-AS Raymond | U18: Assembly | V18: 005100 | W18: AS Raymond | Z18: USA | AA18: S05 | AB18: FMG-S05 | AC18: 211756 | AD18: 0088 | AE18: 5100 | AF18: Default | AG18: General | AH18: US | AI18: en_US | AJ18: USD | AL18: Y | AO18: AydrianMAhrens | AP18: Burchell | AQ18: 211756 | AR18: TRUE
A19: KSX | B19: Barbara | C19: C | D19: Wilkinson | G19: Burchell, Mathew | H19: KSY211756 | J19: wilkinsonb518@gmail.com | K19: Assistant, Warehouse II | L19: 44942 | O19: Active | P19: 209539 | Q19: Biweekly | R19: Full Time | S19: 088 | T19: 088-AS Raymond | U19: Assembly | V19: 005100 | W19: AS Raymond | Z19: USA | AA19: S05 | AB19: FMG-S05 | AC19: 211756 | AD19: 0088 | AE19: 5100 | AF19: Default | AG19: General | AH19: US | AI19: en_US | AJ19: USD | AL19: Y | AO19: BarbaraCWilkinson | AP19: Burchell | AQ19: 211756 | AR19: TRUE
A20: KSX | B20: Benjamin | C20: D | D20: Uncapher | G20: Rafferty, Jonathan | H20: KSY211131 | I20: buncapher@onebarnes.com | K20: Rep, Customer Service III | L20: 45867 | O20: Active | P20: 212254 | Q20: Biweekly | R20: Full Time | S20: 088 | T20: 088-AS Raymond | U20: Inside Sales | V20: 008100 | W20: AS Raymond | Z20: USA | AA20: S11 | AB20: FMG-S11 | AC20: 211131 | AD20: 0088 | AE20: 8100 | AF20: Default | AG20: General | AH20: US | AI20: en_US | AJ20: USD | AL20: Y | AO20: BenjaminDUncapher | AP20: Rafferty | AQ20: 211131 | AR20: TRUE
A21: KSY | B21: Benjamin | C21: D | D21: Uncapher | I21: buncapher@onebarnes.com | K21: Rep, Customer Service III | L21: 45867 | M21: 46175 | O21: Terminated | P21: 212254 | Q21: Monthly | R21: Full Time | S21: 088 | T21: 088-AS Raymond | U21: Inside Sales | V21: 008100 | W21: AS Raymond | Z21: USA | AA21: S11 | AB21: FMG-S11 | AD21: 0088 | AE21: 8100 | AF21: Default | AG21: General | AH21: US | AI21: en_US | AJ21: USD | AL21: N | AM21: 20260602 | AN21: Fix and Include Record | AO21: BenjaminDUncapher | AP21: #VALUE! | AQ21: No Reports to Name | AR21: FALSE
A22: KSY | B22: Benjamin | D22: Sullivan | G22: Creager, Andrew | H22: KSY212699 | I22: bsullivan@onebarnes.com | K22: Planner, Production II | L22: 45131 | O22: Active | P22: 210103 | Q22: Monthly | R22: Full Time | S22: 088 | T22: 088-AS Raymond | U22: Admin-Material Management | V22: 009400 | W22: AS Raymond | Z22: USA | AA22: S12 | AB22: FMG-S12 | AC22: 212699 | AD22: 0088 | AE22: 9400 | AF22: Default | AG22: General | AH22: US | AI22: en_US | AJ22: USD | AL22: Y | AO22: BenjaminSullivan | AP22: Creager | AQ22: 212699 | AR22: TRUE
A23: KSW | B23: Bobby | D23: Hicks | G23: Wallace, Derron | H23: V0U211998 | I23: bhicks@onebarnes.com | J23: bhicks1@me.com | K23: Lead, Unit Team | L23: 45481 | O23: Active | P23: 211145 | Q23: Biweekly | R23: Full Time | S23: 025 | T23: 025-NGP Hyson Products | U23: Assembly Hyson | V23: 000200 | W23: Hyson Products | Z23: USA | AA23: H08 | AB23: FMG-H08 | AC23: 211998 | AD23: 0096 | AE23: 200 | AF23: Default | AG23: General | AH23: US | AI23: en_US | AJ23: USD | AL23: Y | AO23: BobbyHicks | AP23: Wallace | AQ23: 211998 | AR23: TRUE
A24: KSY | B24: Bonnetta | C24: D | D24: Warren | G24: Oleksa, Laura | H24: V0U209181 | I24: bwarren@onebarnes.com | K24: Mgr, HR I | L24: 45958 | O24: Active | P24: 212705 | Q24: Monthly | R24: Full Time | S24: 088 | T24: 088-AS Raymond | U24: HR CU | V24: 009210 | W24: Works from home - Ohio | Z24: USA | AA24: S15 | AB24: FMG-S15 | AC24: 209181 | AD24: 0088 | AE24: 9210 | AF24: Default | AG24: General | AH24: US | AI24: en_US | AJ24: USD | AL24: Y | AO24: BonnettaDWarren | AP24: Oleksa | AQ24: 209181 | AR24: TRUE
A25: KSY | B25: Bradley | D25: Masters | E25: Brad | F25: Masters | G25: Rodriguez, Siobhan | H25: V0U207588 | I25: bmasters@onebarnes.com | J25: brad.a.masters@gmail.com | K25: Mgr, Sales | L25: 46223 | O25: Active | P25: 902437 | Q25: Monthly | R25: Full Time | S25: 088 | T25: 088-AS Raymond | U25: Outside Sales | V25: 008200 | W25: Works from home - Ohio | Z25: USA | AA25: S16 | AB25: FMG-S16 | AC25: 207588 | AD25: 0088 | AE25: 8200 | AF25: Default | AG25: General | AH25: US | AI25: en_US | AJ25: USD | AK25: Brad Masters | AL25: Y | AO25: BradleyMasters | AP25: Rodriguez | AQ25: 212338 | AR25: FALSE
A26: KSX | B26: Brandon | D26: Hibbitts | H26: KSY900848 | I26: bhibbitts@onebarnes.com | J26: hibbitts.brandon@gmail.com | K26: Intern, IT Indirect | L26: 45502 | M26: 46203 | O26: Terminated | P26: 211181 | Q26: Biweekly | R26: Part Time | S26: 088 | T26: 088-AS Raymond | U26: Business Applications | V26: 009150 | W26: AS Raymond | Z26: USA | AA26: H05 | AB26: FMG-H05 | AC26: 900848 | AD26: 0088 | AE26: 9150 | AF26: Default | AG26: General | AH26: US | AI26: en_US | AJ26: USD | AL26: N | AM26: 20260630 | AN26: Fix and Include Record | AO26: BrandonHibbitts | AP26: #VALUE! | AQ26: No Reports to Name | AR26: FALSE
A27: KSY | B27: Brandon | D27: Hibbitts | G27: Erdogan, Mehmet | H27: 000207199N | I27: bhibbitts@onebarnes.com | J27: hibbitts.brandon@gmail.com | K27: Analyst, Help Desk II | L27: 45502 | O27: Active | P27: 211181 | Q27: Monthly | R27: Full Time | S27: 088 | T27: 088-AS Raymond | U27: Business Applications | V27: 009150 | W27: AS Raymond | Z27: USA | AA27: S12 | AB27: FMG-S12 | AC27: 207199 | AD27: 0088 | AE27: 9150 | AF27: Default | AG27: General | AH27: US | AI27: en_US | AJ27: USD | AL27: Y | AO27: BrandonHibbitts | AP27: Erdogan | AQ27: No Reports to Name | AR27: FALSE
A28: KSX | B28: Brandon | D28: Kelly | G28: Alexander, Thomas | H28: KSY210892 | J28: bkelly8@rockets.utoledo.edu | K28: Intern, Operations Direct | L28: 46155 | M28: 46248 | O28: Terminated | P28: 213235 | Q28: Biweekly | R28: Intern | S28: 088 | T28: 088-AS Raymond | U28: Admin-Quality | V28: 009500 | W28: AS Raymond | Z28: USA | AA28: H05 | AB28: FMG-H05 | AC28: 210892 | AD28: 0088 | AE28: 9500 | AF28: Default | AG28: General | AH28: US | AI28: en_US | AJ28: USD | AL28: N | AM28: 20260814 | AN28: Exclude record termination over 45 days ago | AO28: BrandonKelly | AP28: Alexander | AQ28: 210892 | AR28: TRUE
A29: KSX | B29: Brenda | D29: Bixler | G29: LaPlante, Derek | H29: KSY211736 | I29: bbixler@onebarnes.com | J29: beebix911@gmail.com | K29: Expeditor, Warehouse | L29: 45502 | O29: Active | P29: 211174 | Q29: Biweekly | R29: Full Time | S29: 088 | T29: 088-AS Raymond | U29: FG Warehouse | V29: 005200 | W29: AS Raymond | Z29: USA | AA29: S06 | AB29: FMG-S06 | AC29: 211736 | AD29: 0088 | AE29: 5200 | AF29: Default | AG29: General | AH29: US | AI29: en_US | AJ29: USD | AL29: Y | AO29: BrendaBixler | AP29: LaPlante | AQ29: 211736 | AR29: TRUE
A30: KSX | B30: Brenda | C30: J | D30: Daniel | H30: KSY202533 | J30: brendajdaniel@gmail.com | K30: Rep, Customer Service I | L30: 46160 | M30: 46181 | O30: Terminated | P30: 213236 | Q30: Biweekly | R30: Full Time | S30: 088 | T30: 088-AS Raymond | U30: Inside Sales | V30: 008100 | W30: AS Raymond | Z30: USA | AA30: S08 | AB30: FMG-S08 | AC30: 202533 | AD30: 0088 | AE30: 8100 | AF30: Default | AG30: General | AH30: US | AI30: en_US | AJ30: USD | AL30: N | AM30: 20260608 | AN30: Fix and Include Record | AO30: BrendaJDaniel | AP30: #VALUE! | AQ30: No Reports to Name | AR30: FALSE
A31: KSW | B31: Brennen | C31: G | D31: Valley | G31: Steen, Michael | H31: V0U211062 | I31: bvalley@onebarnes.com | K31: Machinist, CNC | L31: 44361 | O31: Active | P31: 206287 | Q31: Biweekly | R31: Part Time | S31: 025 | T31: 025-NGP Hyson Products | U31: CNC Lathe Hyson | V31: 000100 | W31: Hyson Products | Z31: USA | AA31: H04 | AB31: FMG-H04 | AC31: 211062 | AD31: 0096 | AE31: 100 | AF31: Default | AG31: General | AH31: US | AI31: en_US | AJ31: USD | AL31: Y | AO31: BrennenGValley | AP31: Steen | AQ31: 211062 | AR31: TRUE
A32: KSY | B32: Brittany | C32: M | D32: Velner | I32: bvelner@onebarnes.com | K32: Lead, Cust Serv | L32: 45951 | M32: 46136 | O32: Terminated | P32: 212687 | Q32: Monthly | R32: Full Time | S32: 088 | T32: 088-AS Raymond | U32: Inside Sales | V32: 008100 | W32: AS Raymond | Z32: USA | AA32: S12 | AB32: FMG-S12 | AD32: 0088 | AE32: 8100 | AF32: Default | AG32: General | AH32: US | AI32: en_US | AJ32: USD | AL32: N | AM32: 20260424 | AN32: Fix and Include Record | AO32: BrittanyMVelner | AP32: #VALUE! | AQ32: No Reports to Name | AR32: FALSE
A33: KSX | B33: Candi | C33: M | D33: Morales | G33: Alexander, Thomas | H33: KSY210892 | I33: cburris@onebarnes.com | J33: cmorales6132015@gmail.com | K33: Admin, Document Control | L33: 35947 | O33: Active | P33: 007630 | Q33: Biweekly | R33: Full Time | S33: 088 | T33: 088-AS Raymond | U33: Admin-Quality | V33: 009500 | W33: AS Raymond | Z33: USA | AA33: S10 | AB33: FMG-S10 | AC33: 210892 | AD33: 0088 | AE33: 9500 | AF33: Default | AG33: General | AH33: US | AI33: en_US | AJ33: USD | AL33: Y | AO33: CandiMMorales | AP33: Alexander | AQ33: 210892 | AR33: TRUE
A34: KSY | B34: Carla | C34: J | D34: Cunningham | I34: ccunningham@onebarnes.com | J34: springgirl3@sbcglobal.net | L34: 46022 | M34: 46022 | O34: Terminated | P34: 007633 | Q34: Monthly | R34: Full Time | W34: AS Raymond | Z34: USA | AD34: BU Description Not Mapped | AE34: Home Department Code Not Mapped | AF34: Salary Code Not Mapped | AG34: Salary Code Not Mapped | AH34: US | AI34: ADP and BU Language Code Not MappedUS | AJ34: BU Currency Not Mapped | AL34: N | AM34: 20251231 | AN34: Fix and Include Record | AO34: CarlaJCunningham | AP34: #VALUE! | AQ34: No Reports to Name | AR34: FALSE
B35: Carla | C35: J | D35: Cunningham | I35: ccunningham@onebarnes.com | J35: springgirl3@sbcglobal.net | L35: 46022 | M35: 46023 | O35: Terminated | Q35: Weekly | Z35: USA | AD35: BU Description Not Mapped | AE35: Home Department Code Not Mapped | AF35: Salary Code Not Mapped | AG35: Salary Code Not Mapped | AH35: US | AI35: ADP and BU Language Code Not MappedUS | AJ35: BU Currency Not Mapped | AL35: N | AM35: 20260101 | AN35: Exclude record termination over 45 days ago | AO35: CarlaJCunningham | AP35: #VALUE! | AQ35: No Reports to Name | AR35: FALSE
A36: KSY | B36: Carol | D36: Phillips | G36: Rodriguez, Siobhan | H36: V0U207588 | I36: cphillips1@onebarnes.com | J36: cphillips1226@icloud.com | K36: Mgr, Sales | L36: 45909 | O36: Active | P36: 212478 | Q36: Monthly | R36: Full Time | S36: 088 | T36: 088-AS Raymond | U36: Outside Sales | V36: 008200 | W36: Works from home - Ohio | Z36: USA | AA36: S16 | AB36: FMG-S16 | AC36: 207588 | AD36: 0088 | AE36: 8200 | AF36: Default | AG36: General | AH36: US | AI36: en_US | AJ36: USD | AL36: Y | AO36: CarolPhillips | AP36: Rodriguez | AQ36: 212338 | AR36: FALSE
A37: KSY | B37: Carrie | C37: M | D37: Hoffman | G37: Oleksa, Laura | H37: V0U209181 | I37: choffman@onebarnes.com | J37: Carriehoffman89@gmail.com | K37: HR Coordinator | L37: 43101 | O37: Active | P37: 902349 | Q37: Monthly | R37: Full Time | S37: 088 | T37: 088-AS Raymond | U37: HR General | V37: 009200 | W37: AS Raymond | Z37: USA | AA37: S11 | AB37: FMG-S11 | AC37: 209181 | AD37: 0088 | AE37: 9200 | AF37: Default | AG37: General | AH37: US | AI37: en_US | AJ37: USD | AL37: Y | AO37: CarrieMHoffman | AP37: Oleksa | AQ37: 209181 | AR37: TRUE
A38: KSX | B38: Cassandra | C38: G | D38: Richards | G38: LaPlante, Derek | H38: KSY211736 | I38: crichards@onebarnes.com | J38: cassandrarichards13@gmail.com | K38: Assistant, Warehouse II | L38: 45334 | M38: 46262 | O38: Terminated | P38: 210727 | Q38: Biweekly | R38: Full Time | S38: 088 | T38: 088-AS Raymond | U38: FG Warehouse | V38: 005200 | W38: AS Raymond | Z38: USA | AA38: S05 | AB38: FMG-S05 | AC38: 211736 | AD38: 0088 | AE38: 5200 | AF38: Default | AG38: General | AH38: US | AI38: en_US | AJ38: USD | AL38: N | AM38: 20260828 | AN38: Fix and Include Record | AO38: CassandraGRichards | AP38: LaPlante | AQ38: 211736 | AR38: TRUE
A39: V0U | B39: Chad | D39: Phillips | G39: Wilkins, William | H39: V0U901934 | I39: cphillips@onebarnes.com | J39: phillipsx2@verizon.net | K39: Mgr, Sales | L39: 45243 | M39: 46248 | O39: Terminated | P39: 210402 | Q39: Monthly | R39: Full Time | S39: 025 | T39: 025-NGP Hyson Products | U39: Outside Sales | V39: 000820 | W39: Hyson Products | Z39: USA | AA39: S15 | AB39: FMG-S15 | AC39: 901934 | AD39: 0096 | AE39: 820 | AF39: Default | AG39: General | AH39: US | AI39: en_US | AJ39: USD | AL39: N | AM39: 20260814 | AN39: Fix and Include Record | AO39: ChadPhillips | AP39: Wilkins | AQ39: 901934 | AR39: TRUE
A40: KSW | B40: Charles | D40: McDavid | H40: V0U211062 | J40: chuckmcdavid1999@icloud.com | K40: Lathe Operator | L40: 46202 | O40: Active | P40: 213332 | Q40: Biweekly | R40: Full Time | S40: 025 | T40: 025-NGP Hyson Products | U40: CNC Lathe Hyson | V40: 000100 | W40: Hyson Products | Z40: USA | AA40: H07 | AB40: FMG-H07 | AC40: 211062 | AD40: 0096 | AE40: 100 | AF40: Default | AG40: General | AH40: US | AI40: en_US | AJ40: USD | AL40: Y | AO40: CharlesMcDavid | AP40: #VALUE! | AQ40: No Reports to Name | AR40: FALSE
A41: KSW | B41: Cherie | D41: Hassey | G41: Wallace, Derron | H41: V0U211998 | I41: chassey@onebarnes.com | J41: c.hassey@att.net | K41: Rep, Customer Service II | L41: 46125 | O41: Active | P41: 213144 | Q41: Biweekly | R41: Full Time | S41: 025 | T41: 025-NGP Hyson Products | U41: Inside Sales | V41: 000850 | W41: Hyson Products | Z41: USA | AA41: S10 | AB41: FMG-S10 | AC41: 211998 | AD41: 0096 | AE41: 850 | AF41: Default | AG41: General | AH41: US | AI41: en_US | AJ41: USD | AL41: Y | AO41: CherieHassey | AP41: Wallace | AQ41: 211998 | AR41: TRUE
...

Sheet Sheet2
A3: Row Labels | B3: Count of Payroll Company Code
A4: AnthonyJMoavero | B4: 4
A5: IsaakRTaiclet | B5: 3
A6: MichaelMolnar | B6: 3
A7: JosephMLorenz | B7: 3
A8: DanielWhite | B8: 3
A9: TerryWagner | B9: 3
A10: DemetriusADaniels | B10: 3
A11: TimothyEClifton | B11: 3
A12: CherieHassey | B12: 2
A13: CarlaJCunningham | B13: 2
A14: BrandonHibbitts | B14: 2
A15: JamesStefancin | B15: 2
... A20: Grand Total | B20: 41

Sheet 1
A1: Employment Profile - Effective Date | B1: Effective as of 08/31/2026 | H1: Non US Temp Employee | I1: Missing work email address | R1: Do we want to filter here | T1: Map and Filter | V1: Map based on ERP length | X1: Will be filled in | Y1: Will be filled in | AC1: Fix Supervisor ID | AD1: Assign an Org correctly | AE1: Fix to valid GL Company codes | AF1: Assign Salary Code | AG1: Assign Salary Code | AR1: Where false validate the actual supervisor id is correct
A2: Employment Profile - Time & Attendance - Effective Date | B2: All records independent of date | H2: Missing Supervisor
A3: Employment Profile - Pay Rates - Effective Date | B3: All records independent of date | H3: Top of food chain
A4: Payroll Company Code | B4: Legal First Name | C4: Middle Initial | D4: Legal Last Name | E4: Preferred or Chosen First Name | F4: Preferred or Chosen Last Name | G4: Reports To Legal Name | H4: Supervisor ID | I4: Work Contact: Work Email | J4: Personal Contact: Personal Email | K4: Job Title Description | L4: Hire Date | M4: Termination Date | N4: Rehire Date | O4: Position Status | P4: File Number | Q4: Pay Frequency | R4: Employee Type | S4: Business Unit Code | T4: Business Unit Description | U4: Home Department Description | V4: Home Department Code | W4: Location Description | X4: Language Description | Y4: Language Code | Z4: Legal / Preferred Address: Country Code | AA4: Pay Grade Code | AB4: Pay Grade Description | AC4: SupervisorID Formatted | AD4: Org Unit 1 | AE4: Org Unit 2 | AF4: Concur Profile | AG4: Travel Profile | AH4: Legal Country | AI4: Local Code | AJ4: Reumbursement Currency | AK4: Perferred Name | AL4: Status | AM4: Term Date | AN4: =TODAY()-45 -> 46223 | AO4: Name | AP4: SupervisorLastName | AQ4: Lookup Supervisor ID | AR4: SupervisorName=Supervisor ID
A5: KSX | B5: Tammie | D5: Abitua | G5: Burchell, Mathew | H5: KSY211756 | I5: tabitua1@onebarnes.com | J5: abituatammie@gmail.com | K5: Assistant, Warehouse II | L5: 45733 | O5: Active | P5: 211837 | Q5: Biweekly | R5: Full Time | S5: 088 | T5: 088-AS Raymond | U5: Assembly | V5: 005100 | W5: AS Raymond | Z5: USA | AA5: S05 | AB5: FMG-S05 | AC5: =IF(ISBLANK(H5),VLOOKUP(P5,'US Supervisor Map'!A:D,4,FALSE),MID(H5,4,6)) -> 211756 | AD5: =IFERROR(VLOOKUP(T5,'Org Map'!A:E,4),"BU Description Not Mapped") -> 0088 | AE5: =IFERROR(VLOOKUP(V5,'Org Map'!C:E,3),"Home Department Code Not Mapped") -> 5100 | AF5: =IFERROR(VLOOKUP(AA5,'Salary Map'!A:D,3,FALSE),"Salary Code Not Mapped") -> Default | AG5: =IFERROR(VLOOKUP(AA5,'Salary Map'!A:D,4,FALSE),"Salary Code Not Mapped") -> General | AH5: =IFERROR(VLOOKUP(Z5,'Country Map'!A:B,2,FALSE),"Legal Country Not Mapped") -> US | AI5: =IFERROR(VLOOKUP(X5,'Language Map'!A:C,3,FALSE),IFERROR(VLOOKUP(T5,'Org Map'!A:F,6,FALSE),"ADP and BU Language Code Not Mapped"))&AH5 -> en_US | AJ5: =IFERROR(VLOOKUP(T5,'Org Map'!A:G,7),"BU Currency Not Mapped") -> USD | AK5: =IF(ISBLANK(E5),"",TRIM(E5&" "&F5)) | AL5: =IFERROR(VLOOKUP(O5,'Status Map'!A:B,2,FALSE),"Position Status Not Mapped") -> Y | AM5: =IF(AL5="N",TEXT(M5,"yyyymmdd"),"") | AO5: =B5&C5&D5 -> TammieAbitua | AP5: =LEFT(G5,FIND(",",G5)-1) -> Burchell | AQ5: =IFERROR(VLOOKUP(AP5,D:P,13,FALSE),"No Reports to Name") -> 211756 | AR5: =AQ5=MID(H5,4,6) -> TRUE
A6: KSY | B6: Gregory | C6: S | D6: Adams | G6: Rodriguez, Siobhan | H6: V0U207588 | I6: gadams@onebarnes.com | J6: gdsad.adams@cox.net | K6: Mgr, Sales | L6: 46188 | O6: Active | P6: 213331 | Q6: Monthly | R6: Full Time | S6: 088 | T6: 088-AS Raymond | U6: Outside Sales | V6: 008200 | W6: Work from home - Connecticut | Z6: USA | AA6: S16 | AB6: FMG-S16 | AC6: =IF(ISBLANK(H6),VLOOKUP(P6,'US Supervisor Map'!A:D,4,FALSE),MID(H6,4,6)) -> 207588 | AD6: =IFERROR(VLOOKUP(T6,'Org Map'!A:E,4),"BU Description Not Mapped") -> 0088 | AE6: =IFERROR(VLOOKUP(V6,'Org Map'!C:E,3),"Home Department Code Not Mapped") -> 8200 | AF6: =IFERROR(VLOOKUP(AA6,'Salary Map'!A:D,3,FALSE),"Salary Code Not Mapped") -> Default | AG6: =IFERROR(VLOOKUP(AA6,'Salary Map'!A:D,4,FALSE),"Salary Code Not Mapped") -> General | AH6: =IFERROR(VLOOKUP(Z6,'Country Map'!A:B,2,FALSE),"Legal Country Not Mapped") -> US | AI6: =IFERROR(VLOOKUP(X6,'Language Map'!A:C,3,FALSE),IFERROR(VLOOKUP(T6,'Org Map'!A:F,6,FALSE),"ADP and BU Language Code Not Mapped"))&AH6 -> en_US | AJ6: =IFERROR(VLOOKUP(T6,'Org Map'!A:G,7),"BU Currency Not Mapped") -> USD | AK6: =IF(ISBLANK(E6),"",TRIM(E6&" "&F6)) | AL6: =IFERROR(VLOOKUP(O6,'Status Map'!A:B,2,FALSE),"Position Status Not Mapped") -> Y | AM6: =IF(AL6="N",TEXT(M6,"yyyymmdd"),"") | AO6: =B6&C6&D6 -> GregorySAdams | AP6: =LEFT(G6,FIND(",",G6)-1) -> Rodriguez | AQ6: =IFERROR(VLOOKUP(AP6,D:P,13,FALSE),"No Reports to Name") -> 212338 | AR6: =AQ6=MID(H6,4,6) -> FALSE
A7: KSY | B7: Krystle | D7: Agler | G7: Kemenah, Greg | H7: KSY211766 | J7: krystle.agler@gmail.com | K7: Mgr, Marketing II | L7: 46160 | O7: Active | P7: 213226 | Q7: Monthly | R7: Full Time | S7: 088 | T7: 088-AS Raymond | U7: Marketing | V7: 008300 | W7: AS Raymond | Z7: USA | AA7: S16 | AB7: FMG-S16 | AC7: =IF(ISBLANK(H7),VLOOKUP(P7,'US Supervisor Map'!A:D,4,FALSE),MID(H7,4,6)) -> 211766 | AD7: =IFERROR(VLOOKUP(T7,'Org Map'!A:E,4),"BU Description Not Mapped") -> 0088 | AE7: =IFERROR(VLOOKUP(V7,'Org Map'!C:E,3),"Home Department Code Not Mapped") -> 8300 | AF7: =IFERROR(VLOOKUP(AA7,'Salary Map'!A:D,3,FALSE),"Salary Code Not Mapped") -> Default | AG7: =IFERROR(VLOOKUP(AA7,'Salary Map'!A:D,4,FALSE),"Salary Code Not Mapped") -> General | AH7: =IFERROR(VLOOKUP(Z7,'Country Map'!A:B,2,FALSE),"Legal Country Not Mapped") -> US | AI7: =IFERROR(VLOOKUP(X7,'Language Map'!A:C,3,FALSE),IFERROR(VLOOKUP(T7,'Org Map'!A:F,6,FALSE),"ADP and BU Language Code Not Mapped"))&AH7 -> en_US | AJ7: =IFERROR(VLOOKUP(T7,'Org Map'!A:G,7),"BU Currency Not Mapped") -> USD | AK7: =IF(ISBLANK(E7),"",TRIM(E7&" "&F7)) | AL7: =IFERROR(VLOOKUP(O7,'Status Map'!A:B,2,FALSE),"Position Status Not Mapped") -> Y | AM7: =IF(AL7="N",TEXT(M7,"yyyymmdd"),"") | AO7: =B7&C7&D7 -> KrystleAgler | AP7: =LEFT(G7,FIND(",",G7)-1) -> Kemenah | AQ7: =IFERROR(VLOOKUP(AP7,D:P,13,FALSE),"No Reports to Name") -> 211766 | AR7: =AQ7=MID(H7,4,6) -> TRUE
A8: KSX | B8: Aydrian | C8: M | D8: Ahrens | G8: Burchell, Mathew | H8: KSY211756 | J8: aydrian0323@yahoo.com | K8: Assistant, Warehouse II | L8: 45754 | O8: Active | P8: 211901 | Q8: Biweekly | R8: Full Time | S8: 088 | T8: 088-AS Raymond | U8: Assembly | V8: 005100 | W8: AS Raymond | Z8: USA | AA8: S05 | AB8: FMG-S05 | AC8: =IF(ISBLANK(H8),VLOOKUP(P8,'US Supervisor Map'!A:D,4,FALSE),MID(H8,4,6)) -> 211756 | AD8: =IFERROR(VLOOKUP(T8,'Org Map'!A:E,4),"BU Description Not Mapped") -> 0088 | AE8: =IFERROR(VLOOKUP(V8,'Org Map'!C:E,3),"Home Department Code Not Mapped") -> 5100 | AF8: =IFERROR(VLOOKUP(AA8,'Salary Map'!A:D,3,FALSE),"Salary Code Not Mapped") -> Default | AG8: =IFERROR(VLOOKUP(AA8,'Salary Map'!A:D,4,FALSE),"Salary Code Not Mapped") -> General | AH8: =IFERROR(VLOOKUP(Z8,'Country Map'!A:B,2,FALSE),"Legal Country Not Mapped") -> US | AI8: =IFERROR(VLOOKUP(X8,'Language Map'!A:C,3,FALSE),IFERROR(VLOOKUP(T8,'Org Map'!A:F,6,FALSE),"ADP and BU Language Code Not Mapped"))&AH8 -> en_US | AJ8: =IFERROR(VLOOKUP(T8,'Org Map'!A:G,7),"BU Currency Not Mapped") -> USD | AK8: =IF(ISBLANK(E8),"",TRIM(E8&" "&F8)) | AL8: =IFERROR(VLOOKUP(O8,'Status Map'!A:B,2,FALSE),"Position Status Not Mapped") -> Y | AM8: =IF(AL8="N",TEXT(M8,"yyyymmdd"),"") | AO8: =B8&C8&D8 -> AydrianMAhrens | AP8: =LEFT(G8,FIND(",",G8)-1) -> Burchell | AQ8: =IFERROR(VLOOKUP(AP8,D:P,13,FALSE),"No Reports to Name") -> 211756 | AR8: =AQ8=MID(H8,4,6) -> TRUE
A9: KSX | B9: Matthew | D9: Ahrens | G9: Burchell, Mathew | H9: KSY211756 | J9: mattcjahrens89@yahoo.com | K9: Assistant, Warehouse II | L9: 46176 | M9: 46182 | O9: Terminated | P9: 213306 | Q9: Biweekly | R9: Full Time | S9: 088 | T9: 088-AS Raymond | U9: WH Material Management | V9: 005300 | W9: AS Raymond | Z9: USA | AA9: S05 | AB9: FMG-S05 | AC9: =IF(ISBLANK(H9),VLOOKUP(P9,'US Supervisor Map'!A:D,4,FALSE),MID(H9,4,6)) -> 211756 | AD9: =IFERROR(VLOOKUP(T9,'Org Map'!A:E,4),"BU Description Not Mapped") -> 0088 | AE9: =IFERROR(VLOOKUP(V9,'Org Map'!C:E,3),"Home Department Code Not Mapped") -> 5300 | AF9: =IFERROR(VLOOKUP(AA9,'Salary Map'!A:D,3,FALSE),"Salary Code Not Mapped") -> Default | AG9: =IFERROR(VLOOKUP(AA9,'Salary Map'!A:D,4,FALSE),"Salary Code Not Mapped") -> General | AH9: =IFERROR(VLOOKUP(Z9,'Country Map'!A:B,2,FALSE),"Legal Country Not Mapped") -> US | AI9: =IFERROR(VLOOKUP(X9,'Language Map'!A:C,3,FALSE),IFERROR(VLOOKUP(T9,'Org Map'!A:F,6,FALSE),"ADP and BU Language Code Not Mapped"))&AH9 -> en_US | AJ9: =IFERROR(VLOOKUP(T9,'Org Map'!A:G,7),"BU Currency Not Mapped") -> USD | AK9: =IF(ISBLANK(E9),"",TRIM(E9&" "&F9)) | AL9: =IFERROR(VLOOKUP(O9,'Status Map'!A:B,2,FALSE),"Position Status Not Mapped") -> N | AM9: =IF(AL9="N",TEXT(M9,"yyyymmdd"),"") -> 20260609 | AN9: =IF(M9>AN4,"Fix and Include Record","Exclude record termination over 45 days ago") -> Exclude record termination over 45 days ago | AO9: =B9&C9&D9 -> MatthewAhrens | AP9: =LEFT(G9,FIND(",",G9)-1) -> Burchell | AQ9: =IFERROR(VLOOKUP(AP9,D:P,13,FALSE),"No Reports to Name") -> 211756 | AR9: =AQ9=MID(H9,4,6) -> TRUE
A10: KSY | B10: Thomas | C10: E | D10: Alexander | G10: Kemenah, Greg | H10: KSY211766 | I10: talexander@onebarnes.com | J10: tom5683alexander@gmail.com | K10: Mgr, Quality II | L10: 45392 | O10: Active | P10: 210892 | Q10: Monthly | R10: Full Time | S10: 088 | T10: 088-AS Raymond | U10: Admin-Quality | V10: 009500 | W10: AS Raymond | Z10: USA | AA10: S16 | AB10: FMG-S16 | AC10: =IF(ISBLANK(H10),VLOOKUP(P10,'US Supervisor Map'!A:D,4,FALSE),MID(H10,4,6)) -> 211766 | AD10: =IFERROR(VLOOKUP(T10,'Org Map'!A:E,4),"BU Description Not Mapped") -> 0088 | AE10: =IFERROR(VLOOKUP(V10,'Org Map'!C:E,3),"Home Department Code Not Mapped") -> 9500 | AF10: =IFERROR(VLOOKUP(AA10,'Salary Map'!A:D,3,FALSE),"Salary Code Not Mapped") -> Default | AG10: =IFERROR(VLOOKUP(AA10,'Salary Map'!A:D,4,FALSE),"Salary Code Not Mapped") -> General | AH10: =IFERROR(VLOOKUP(Z10,'Country Map'!A:B,2,FALSE),"Legal Country Not Mapped") -> US | AI10: =IFERROR(VLOOKUP(X10,'Language Map'!A:C,3,FALSE),IFERROR(VLOOKUP(T10,'Org Map'!A:F,6,FALSE),"ADP and BU Language Code Not Mapped"))&AH10 -> en_US | AJ10: =IFERROR(VLOOKUP(T10,'Org Map'!A:G,7),"BU Currency Not Mapped") -> USD | AK10: =IF(ISBLANK(E10),"",TRIM(E10&" "&F10)) | AL10: =IFERROR(VLOOKUP(O10,'Status Map'!A:B,2,FALSE),"Position Status Not Mapped") -> Y | AM10: =IF(AL10="N",TEXT(M10,"yyyymmdd"),"") | AO10: =B10&C10&D10 -> ThomasEAlexander | AP10: =LEFT(G10,FIND(",",G10)-1) -> Kemenah | AQ10: =IFERROR(VLOOKUP(AP10,D:P,13,FALSE),"No Reports to Name") -> 211766 | AR10: =AQ10=MID(H10,4,6) -> TRUE
A11: KSX | B11: Tina | C11: M | D11: Allen | G11: LaPlante, Derek | H11: KSY211736 | I11: TAllen2@onebarnes.com | J11: tinaallen908@gmail.com | K11: Assistant, Warehouse II | L11: 44550 | O11: Active | P11: 206848 | Q11: Biweekly | R11: Full Time | S11: 088 | T11: 088-AS Raymond | U11: FG Warehouse | V11: 005200 | W11: AS Raymond | Z11: USA | AA11: S05 | AB11: FMG-S05 | AC11: =IF(ISBLANK(H11),VLOOKUP(P11,'US Supervisor Map'!A:D,4,FALSE),MID(H11,4,6)) -> 211736 | AD11: =IFERROR(VLOOKUP(T11,'Org Map'!A:E,4),"BU Description Not Mapped") -> 0088 | AE11: =IFERROR(VLOOKUP(V11,'Org Map'!C:E,3),"Home Department Code Not Mapped") -> 5200 | AF11: =IFERROR(VLOOKUP(AA11,'Salary Map'!A:D,3,FALSE),"Salary Code Not Mapped") -> Default | AG11: =IFERROR(VLOOKUP(AA11,'Salary Map'!A:D,4,FALSE),"Salary Code Not Mapped") -> General | AH11: =IFERROR(VLOOKUP(Z11,'Country Map'!A:B,2,FALSE),"Legal Country Not Mapped") -> US | AI11: =IFERROR(VLOOKUP(X11,'Language Map'!A:C,3,FALSE),IFERROR(VLOOKUP(T11,'Org Map'!A:F,6,FALSE),"ADP and BU Language Code Not Mapped"))&AH11 -> en_US | AJ11: =IFERROR(VLOOKUP(T11,'Org Map'!A:G,7),"BU Currency Not Mapped") -> USD | AK11: =IF(ISBLANK(E11),"",TRIM(E11&" "&F11)) | AL11: =IFERROR(VLOOKUP(O11,'Status Map'!A:B,2,FALSE),"Position Status Not Mapped") -> Y | AM11: =IF(AL11="N",TEXT(M11,"yyyymmdd"),"") | AO11: =B11&C11&D11 -> TinaMAllen | AP11: =LEFT(G11,FIND(",",G11)-1) -> LaPlante | AQ11: =IFERROR(VLOOKUP(AP11,D:P,13,FALSE),"No Reports to Name") -> 211736 | AR11: =AQ11=MID(H11,4,6) -> TRUE
A12: KSY | B12: Kimberly | D12: Ashley | G12: Warner, Dwight | H12: V0U008750 | I12: KAshley@onebarnes.com | K12: Accountant III | L12: 43710 | O12: Active | P12: 201688 | Q12: Monthly | R12: Full Time | S12: 088 | T12: 088-AS Raymond | U12: Finance General | V12: 009100 | W12: Work from home - Connecticut | Z12: USA | AA12: S13 | AB12: FMG-S13 | AC12: =IF(ISBLANK(H12),VLOOKUP(P12,'US Supervisor Map'!A:D,4,FALSE),MID(H12,4,6)) -> 008750 | AD12: =IFERROR(VLOOKUP(T12,'Org Map'!A:E,4),"BU Description Not Mapped") -> 0088 | AE12: =IFERROR(VLOOKUP(V12,'Org Map'!C:E,3),"Home Department Code Not Mapped") -> 9100 | AF12: =IFERROR(VLOOKUP(AA12,'Salary Map'!A:D,3,FALSE),"Salary Code Not Mapped") -> Default | AG12: =IFERROR(VLOOKUP(AA12,'Salary Map'!A:D,4,FALSE),"Salary Code Not Mapped") -> General | AH12: =IFERROR(VLOOKUP(Z12,'Country Map'!A:B,2,FALSE),"Legal Country Not Mapped") -> US | AI12: =IFERROR(VLOOKUP(X12,'Language Map'!A:C,3,FALSE),IFERROR(VLOOKUP(T12,'Org Map'!A:F,6,FALSE),"ADP and BU Language Code Not Mapped"))&AH12 -> en_US | AJ12: =IFERROR(VLOOKUP(T12,'Org Map'!A:G,7),"BU Currency Not Mapped") -> USD | AK12: =IF(ISBLANK(E12),"",TRIM(E12&" "&F12)) | AL12: =IFERROR(VLOOKUP(O12,'Status Map'!A:B,2,FALSE),"Position Status Not Mapped") -> Y | AM12: =IF(AL12="N",TEXT(M12,"yyyymmdd"),"") | AO12: =B12&C12&D12 -> KimberlyAshley | AP12: =LEFT(G12,FIND(",",G12)-1) -> Warner | AQ12: =IFERROR(VLOOKUP(AP12,D:P,13,FALSE),"No Reports to Name") -> 008750 | AR12: =AQ12=MID(H12,4,6) -> TRUE
A13: KSY | B13: Jason | C13: J | D13: Bailey | G13: Kemenah, Greg | I13: jbailey@onebarnes.com | J13: jjbailey08@gmail.com | K13: Senior Mgr, Operations | L13: 46258 | O13: Active | P13: 902688 | Q13: Monthly | R13: Full Time | S13: 088 | T13: 088-AS Raymond | U13: Operations 5200 5200 | V13: 000007 | W13: AS Raymond | Z13: USA | AA13: S18 | AB13: FMG-S18 | AC13: =IF(ISBLANK(H13),VLOOKUP(P13,'US Supervisor Map'!A:D,4,FALSE),MID(H13,4,6)) | AD13: =IFERROR(VLOOKUP(T13,'Org Map'!A:E,4),"BU Description Not Mapped") -> 0088 | AE13: =IFERROR(VLOOKUP(V13,'Org Map'!C:E,3),"Home Department Code Not Mapped") -> Home Department Code Not Mapped | AF13: =IFERROR(VLOOKUP(AA13,'Salary Map'!A:D,3,FALSE),"Salary Code Not Mapped") -> Default | AG13: =IFERROR(VLOOKUP(AA13,'Salary Map'!A:D,4,FALSE),"Salary Code Not Mapped") -> General | AH13: =IFERROR(VLOOKUP(Z13,'Country Map'!A:B,2,FALSE),"Legal Country Not Mapped") -> US | AI13: =IFERROR(VLOOKUP(X13,'Language Map'!A:C,3,FALSE),IFERROR(VLOOKUP(T13,'Org Map'!A:F,6,FALSE),"ADP and BU Language Code Not Mapped"))&AH13 -> en_US | AJ13: =IFERROR(VLOOKUP(T13,'Org Map'!A:G,7),"BU Currency Not Mapped") -> USD | AK13: =IF(ISBLANK(E13),"",TRIM(E13&" "&F13)) | AL13: =IFERROR(VLOOKUP(O13,'Status Map'!A:B,2,FALSE),"Position Status Not Mapped") -> Y | AM13: =IF(AL13="N",TEXT(M13,"yyyymmdd"),"") | AO13: =B13&C13&D13 -> JasonJBailey | AP13: =LEFT(G13,FIND(",",G13)-1) -> Kemenah | AQ13: =IFERROR(VLOOKUP(AP13,D:P,13,FALSE),"No Reports to Name") -> 211766 | AR13: =AQ13=MID(H13,4,6) -> FALSE
A14: KSY | B14: Teresa | D14: Bair | I14: TBair@onebarnes.com | K14: President, SBU II | L14: 44732 | O14: Active | P14: 207709 | Q14: Monthly | R14: Full Time | S14: 088 | T14: 088-AS Raymond | U14: Bus Execs CU | V14: 009310 | W14: AS Raymond | Z14: USA | AA14: S22 | AB14: FMG-S22 | AC14: =IF(ISBLANK(H14),VLOOKUP(P14,'US Supervisor Map'!A:D,4,FALSE),MID(H14,4,6)) | AD14: =IFERROR(VLOOKUP(T14,'Org Map'!A:E,4),"BU Description Not Mapped") -> 0088 | AE14: =IFERROR(VLOOKUP(V14,'Org Map'!C:E,3),"Home Department Code Not Mapped") -> 9310 | AF14: =IFERROR(VLOOKUP(AA14,'Salary Map'!A:D,3,FALSE),"Salary Code Not Mapped") -> Grade 20 | AG14: =IFERROR(VLOOKUP(AA14,'Salary Map'!A:D,4,FALSE),"Salary Code Not Mapped") -> Senior Leadership | AH14: =IFERROR(VLOOKUP(Z14,'Country Map'!A:B,2,FALSE),"Legal Country Not Mapped") -> US | AI14: =IFERROR(VLOOKUP(X14,'Language Map'!A:C,3,FALSE),IFERROR(VLOOKUP(T14,'Org Map'!A:F,6,FALSE),"ADP and BU Language Code Not Mapped"))&AH14 -> en_US | AJ14: =IFERROR(VLOOKUP(T14,'Org Map'!A:G,7),"BU Currency Not Mapped") -> USD | AK14: =IF(ISBLANK(E14),"",TRIM(E14&" "&F14)) | AL14: =IFERROR(VLOOKUP(O14,'Status Map'!A:B,2,FALSE),"Position Status Not Mapped") -> Y | AM14: =IF(AL14="N",TEXT(M14,"yyyymmdd"),"") | AO14: =B14&C14&D14 -> TeresaBair | AP14: =LEFT(G14,FIND(",",G14)-1) -> #VALUE! | AQ14: =IFERROR(VLOOKUP(AP14,D:P,13,FALSE),"No Reports to Name") -> No Reports to Name | AR14: =AQ14=MID(H14,4,6) -> FALSE
A15: V0U | B15: Kirsten | C15: V | D15: Barry | G15: Rodriguez, Siobhan | I15: kbarry@onebarnes.com | K15: Mgr, Project I | L15: 44949 | O15: Active | P15: 209579 | Q15: Monthly | R15: Full Time | S15: 025 | T15: 025-NGP Hyson Products | U15: Outside Sales | V15: 000820 | W15: Hyson Products | Z15: USA | AA15: S15 | AB15: FMG-S15 | AC15: =IF(ISBLANK(H15),VLOOKUP(P15,'US Supervisor Map'!A:D,4,FALSE),MID(H15,4,6)) | AD15: =IFERROR(VLOOKUP(T15,'Org Map'!A:E,4),"BU Description Not Mapped") -> 0096 | AE15: =IFERROR(VLOOKUP(V15,'Org Map'!C:E,3),"Home Department Code Not Mapped") -> 820 | AF15: =IFERROR(VLOOKUP(AA15,'Salary Map'!A:D,3,FALSE),"Salary Code Not Mapped") -> Default | AG15: =IFERROR(VLOOKUP(AA15,'Salary Map'!A:D,4,FALSE),"Salary Code Not Mapped") -> General | AH15: =IFERROR(VLOOKUP(Z15,'Country Map'!A:B,2,FALSE),"Legal Country Not Mapped") -> US | AI15: =IFERROR(VLOOKUP(X15,'Language Map'!A:C,3,FALSE),IFERROR(VLOOKUP(T15,'Org Map'!A:F,6,FALSE),"ADP and BU Language Code Not Mapped"))&AH15 -> en_US | AJ15: =IFERROR(VLOOKUP(T15,'Org Map'!A:G,7),"BU Currency Not Mapped") -> USD | AK15: =IF(ISBLANK(E15),"",TRIM(E15&" "&F15)) | AL15: =IFERROR(VLOOKUP(O15,'Status Map'!A:B,2,FALSE),"Position Status Not Mapped") -> Y | AM15: =IF(AL15="N",TEXT(M15,"yyyymmdd"),"") | AO15: =B15&C15&D15 -> KirstenVBarry | AP15: =LEFT(G15,FIND(",",G15)-1) -> Rodriguez | AQ15: =IFERROR(VLOOKUP(AP15,D:P,13,FALSE),"No Reports to Name") -> 212338 | AR15: =AQ15=MID(H15,4,6) -> FALSE
A16: V0U | B16: Natalie | D16: Bate | G16: Bair, Teresa | H16: KSY207709 | I16: nbate@onebarnes.com | J16: natalie.m.bate@gmail.com | K16: Mgr, Division II | L16: 46083 | O16: Active | P16: 213037 | Q16: Monthly | R16: Full Time | S16: 025 | T16: 025-NGP Hyson Products | U16: Administration | V16: 000917 | W16: Hyson Products | Z16: USA | AA16: S19 | AB16: FMG-S19 | AC16: =IF(ISBLANK(H16),VLOOKUP(P16,'US Supervisor Map'!A:D,4,FALSE),MID(H16,4,6)) -> 207709 | AD16: =IFERROR(VLOOKUP(T16,'Org Map'!A:E,4),"BU Description Not Mapped") -> 0096 | AE16: =IFERROR(VLOOKUP(V16,'Org Map'!C:E,3),"Home Department Code Not Mapped") -> 0007 | AF16: =IFERROR(VLOOKUP(AA16,'Salary Map'!A:D,3,FALSE),"Salary Code Not Mapped") -> Default | AG16: =IFERROR(VLOOKUP(AA16,'Salary Map'!A:D,4,FALSE),"Salary Code Not Mapped") -> General | AH16: =IFERROR(VLOOKUP(Z16,'Country Map'!A:B,2,FALSE),"Legal Country Not Mapped") -> US | AI16: =IFERROR(VLOOKUP(X16,'Language Map'!A:C,3,FALSE),IFERROR(VLOOKUP(T16,'Org Map'!A:F,6,FALSE),"ADP and BU Language Code Not Mapped"))&AH16 -> en_US | AJ16: =IFERROR(VLOOKUP(T16,'Org Map'!A:G,7),"BU Currency Not Mapped") -> USD | AK16: =IF(ISBLANK(E16),"",TRIM(E16&" "&F16)) | AL16: =IFERROR(VLOOKUP(O16,'Status Map'!A:B,2,FALSE),"Position Status Not Mapped") -> Y | AM16: =IF(AL16="N",TEXT(M16,"yyyymmdd"),"") | AO16: =B16&C16&D16 -> NatalieBate | AP16: =LEFT(G16,FIND(",",G16)-1) -> Bair | AQ16: =IFERROR(VLOOKUP(AP16,D:P,13,FALSE),"No Reports to Name") -> 207709 | AR16: =AQ16=MID(H16,4,6) -> TRUE
A17: KSY | B17: Michael | C17: J | D17: Beasley | G17: Rodriguez, Siobhan | H17: V0U207588 | I17: mbeasley@onebarnes.com | J17: gqnbeasley@comcast.net | K17: Mgr, Sales | L17: 46202 | O17: Active | P17: 213333 | Q17: Monthly | R17: Full Time | S17: 088 | T17: 088-AS Raymond | U17: Outside Sales | V17: 008200 | W17: Work from home - Washington | Z17: USA | AA17: S16 | AB17: FMG-S16 | AC17: =IF(ISBLANK(H17),VLOOKUP(P17,'US Supervisor Map'!A:D,4,FALSE),MID(H17,4,6)) -> 207588 | AD17: =IFERROR(VLOOKUP(T17,'Org Map'!A:E,4),"BU Description Not Mapped") -> 0088 | AE17: =IFERROR(VLOOKUP(V17,'Org Map'!C:E,3),"Home Department Code Not Mapped") -> 8200 | AF17: =IFERROR(VLOOKUP(AA17,'Salary Map'!A:D,3,FALSE),"Salary Code Not Mapped") -> Default | AG17: =IFERROR(VLOOKUP(AA17,'Salary Map'!A:D,4,FALSE),"Salary Code Not Mapped") -> General | AH17: =IFERROR(VLOOKUP(Z17,'Country Map'!A:B,2,FALSE),"Legal Country Not Mapped") -> US | AI17: =IFERROR(VLOOKUP(X17,'Language Map'!A:C,3,FALSE),IFERROR(VLOOKUP(T17,'Org Map'!A:F,6,FALSE),"ADP and BU Language Code Not Mapped"))&AH17 -> en_US | AJ17: =IFERROR(VLOOKUP(T17,'Org Map'!A:G,7),"BU Currency Not Mapped") -> USD | AK17: =IF(ISBLANK(E17),"",TRIM(E17&" "&F17)) | AL17: =IFERROR(VLOOKUP(O17,'Status Map'!A:B,2,FALSE),"Position Status Not Mapped") -> Y | AM17: =IF(AL17="N",TEXT(M17,"yyyymmdd"),"") | AO17: =B17&C17&D17 -> MichaelJBeasley | AP17: =LEFT(G17,FIND(",",G17)-1) -> Rodriguez | AQ17: =IFERROR(VLOOKUP(AP17,D:P,13,FALSE),"No Reports to Name") -> 212338 | AR17: =AQ17=MID(H17,4,6) -> FALSE
A18: KSX | B18: Ella Renae | C18: E | D18: Beatrice | G18: LaPlante, Derek | H18: KSY211736 | I18: ebeatrice@onebarnes.com | J18: thatellachick@gmail.com | K18: Assistant, Warehouse II | L18: 45929 | O18: Active | P18: 212626 | Q18: Biweekly | R18: Full Time | S18: 088 | T18: 088-AS Raymond | U18: FG Warehouse | V18: 005200 | W18: AS Raymond | Z18: USA | AA18: S05 | AB18: FMG-S05 | AC18: =IF(ISBLANK(H18),VLOOKUP(P18,'US Supervisor Map'!A:D,4,FALSE),MID(H18,4,6)) -> 211736 | AD18: =IFERROR(VLOOKUP(T18,'Org Map'!A:E,4),"BU Description Not Mapped") -> 0088 | AE18: =IFERROR(VLOOKUP(V18,'Org Map'!C:E,3),"Home Department Code Not Mapped") -> 5200 | AF18: =IFERROR(VLOOKUP(AA18,'Salary Map'!A:D,3,FALSE),"Salary Code Not Mapped") -> Default | AG18: =IFERROR(VLOOKUP(AA18,'Salary Map'!A:D,4,FALSE),"Salary Code Not Mapped") -> General | AH18: =IFERROR(VLOOKUP(Z18,'Country Map'!A:B,2,FALSE),"Legal Country Not Mapped") -> US | AI18: =IFERROR(VLOOKUP(X18,'Language Map'!A:C,3,FALSE),IFERROR(VLOOKUP(T18,'Org Map'!A:F,6,FALSE),"ADP and BU Language Code Not Mapped"))&AH18 -> en_US | AJ18: =IFERROR(VLOOKUP(T18,'Org Map'!A:G,7),"BU Currency Not Mapped") -> USD | AK18: =IF(ISBLANK(E18),"",TRIM(E18&" "&F18)) | AL18: =IFERROR(VLOOKUP(O18,'Status Map'!A:B,2,FALSE),"Position Status Not Mapped") -> Y | AM18: =IF(AL18="N",TEXT(M18,"yyyymmdd"),"") | AO18: =B18&C18&D18 -> Ella RenaeEBeatrice | AP18: =LEFT(G18,FIND(",",G18)-1) -> LaPlante | AQ18: =IFERROR(VLOOKUP(AP18,D:P,13,FALSE),"No Reports to Name") -> 211736 | AR18: =AQ18=MID(H18,4,6) -> TRUE
A19: KSX | B19: John | D19: Bentz | G19: LaPlante, Derek | H19: KSY211736 | I19: jbentz@onebarnes.com | J19: xjbm13@yahoo.com | K19: Assistant, Warehouse II | L19: 45937 | O19: Active | P19: 212639 | Q19: Biweekly | R19: Full Time | S19: 088 | T19: 088-AS Raymond | U19: FG Warehouse | V19: 005200 | W19: AS Raymond | Z19: USA | AA19: S05 | AB19: FMG-S05 | AC19: =IF(ISBLANK(H19),VLOOKUP(P19,'US Supervisor Map'!A:D,4,FALSE),MID(H19,4,6)) -> 211736 | AD19: =IFERROR(VLOOKUP(T19,'Org Map'!A:E,4),"BU Description Not Mapped") -> 0088 | AE19: =IFERROR(VLOOKUP(V19,'Org Map'!C:E,3),"Home Department Code Not Mapped") -> 5200 | AF19: =IFERROR(VLOOKUP(AA19,'Salary Map'!A:D,3,FALSE),"Salary Code Not Mapped") -> Default | AG19: =IFERROR(VLOOKUP(AA19,'Salary Map'!A:D,4,FALSE),"Salary Code Not Mapped") -> General | AH19: =IFERROR(VLOOKUP(Z19,'Country Map'!A:B,2,FALSE),"Legal Country Not Mapped") -> US | AI19: =IFERROR(VLOOKUP(X19,'Language Map'!A:C,3,FALSE),IFERROR(VLOOKUP(T19,'Org Map'!A:F,6,FALSE),"ADP and BU Language Code Not Mapped"))&AH19 -> en_US | AJ19: =IFERROR(VLOOKUP(T19,'Org Map'!A:G,7),"BU Currency Not Mapped") -> USD | AK19: =IF(ISBLANK(E19),"",TRIM(E19&" "&F19)) | AL19: =IFERROR(VLOOKUP(O19,'Status Map'!A:B,2,FALSE),"Position Status Not Mapped") -> Y | AM19: =IF(AL19="N",TEXT(M19,"yyyymmdd"),"") | AO19: =B19&C19&D19 -> JohnBentz | AP19: =LEFT(G19,FIND(",",G19)-1) -> LaPlante | AQ19: =IFERROR(VLOOKUP(AP19,D:P,13,FALSE),"No Reports to Name") -> 211736 | AR19: =AQ19=MID(H19,4,6) -> TRUE
A20: KSY | B20: Michael | D20: Biniecki | G20: Bailey, Jason | H20: KSY211766 | I20: mbiniecki@onebarnes.com | J20: mbineck@frontier.com | K20: Supv, CI | L20: 45565 | O20: Active | P20: 211464 | Q20: Monthly | R20: Full Time | S20: 088 | T20: 088-AS Raymond | U20: FG Warehouse | V20: 005200 | W20: AS Raymond | Z20: USA | AA20: S16 | AB20: FMG-S16 | AC20: =IF(ISBLANK(H20),VLOOKUP(P20,'US Supervisor Map'!A:D,4,FALSE),MID(H20,4,6)) -> 211766 | AD20: =IFERROR(VLOOKUP(T20,'Org Map'!A:E,4),"BU Description Not Mapped") -> 0088 | AE20: =IFERROR(VLOOKUP(V20,'Org Map'!C:E,3),"Home Department Code Not Mapped") -> 5200 | AF20: =IFERROR(VLOOKUP(AA20,'Salary Map'!A:D,3,FALSE),"Salary Code Not Mapped") -> Default | AG20: =IFERROR(VLOOKUP(AA20,'Salary Map'!A:D,4,FALSE),"Salary Code Not Mapped") -> General | AH20: =IFERROR(VLOOKUP(Z20,'Country Map'!A:B,2,FALSE),"Legal Country Not Mapped") -> US | AI20: =IFERROR(VLOOKUP(X20,'Language Map'!A:C,3,FALSE),IFERROR(VLOOKUP(T20,'Org Map'!A:F,6,FALSE),"ADP and BU Language Code Not Mapped"))&AH20 -> en_US | AJ20: =IFERROR(VLOOKUP(T20,'Org Map'!A:G,7),"BU Currency Not Mapped") -> USD | AK20: =IF(ISBLANK(E20),"",TRIM(E20&" "&F20)) | AL20: =IFERROR(VLOOKUP(O20,'Status Map'!A:B,2,FALSE),"Position Status Not Mapped") -> Y | AM20: =IF(AL20="N",TEXT(M20,"yyyymmdd"),"") | AO20: =B20&C20&D20 -> MichaelBiniecki | AP20: =LEFT(G20,FIND(",",G20)-1) -> Bailey | AQ20: =IFERROR(VLOOKUP(AP20,D:P,13,FALSE),"No Reports to Name") -> 902688 | AR20: =AQ20=MID(H20,4,6) -> FALSE
A21: V0U | B21: Nathan | D21: Bird | G21: Wilkins, William | H21: V0U901934 | I21: nbird@onebarnes.com | J21: bird.nathan@icloud.com | K21: Mgr, Sales | L21: 45131 | O21: Active | P21: 210102 | Q21: Monthly | R21: Full Time | S21: 025 | T21: 025-NGP Hyson Products | U21: Outside Sales | V21: 000820 | W21: Work from home - Arizona | Z21: USA | AA21: S15 | AB21: FMG-S15 | AC21: =IF(ISBLANK(H21),VLOOKUP(P21,'US Supervisor Map'!A:D,4,FALSE),MID(H21,4,6)) -> 901934 | AD21: =IFERROR(VLOOKUP(T21,'Org Map'!A:E,4),"BU Description Not Mapped") -> 0096 | AE21: =IFERROR(VLOOKUP(V21,'Org Map'!C:E,3),"Home Department Code Not Mapped") -> 820 | AF21: =IFERROR(VLOOKUP(AA21,'Salary Map'!A:D,3,FALSE),"Salary Code Not Mapped") -> Default | AG21: =IFERROR(VLOOKUP(AA21,'Salary Map'!A:D,4,FALSE),"Salary Code Not Mapped") -> General | AH21: =IFERROR(VLOOKUP(Z21,'Country Map'!A:B,2,FALSE),"Legal Country Not Mapped") -> US | AI21: =IFERROR(VLOOKUP(X21,'Language Map'!A:C,3,FALSE),IFERROR(VLOOKUP(T21,'Org Map'!A:F,6,FALSE),"ADP and BU Language Code Not Mapped"))&AH21 -> en_US | AJ21: =IFERROR(VLOOKUP(T21,'Org Map'!A:G,7),"BU Currency Not Mapped") -> USD | AK21: =IF(ISBLANK(E21),"",TRIM(E21&" "&F21)) | AL21: =IFERROR(VLOOKUP(O21,'Status Map'!A:B,2,FALSE),"Position Status Not Mapped") -> Y | AM21: =IF(AL21="N",TEXT(M21,"yyyymmdd"),"") | AO21: =B21&C21&D21 -> NathanBird | AP21: =LEFT(G21,FIND(",",G21)-1) -> Wilkins | AQ21: =IFERROR(VLOOKUP(AP21,D:P,13,FALSE),"No Reports to Name") -> 901934 | AR21: =AQ21=MID(H21,4,6) -> TRUE
A22: KSW | B22: James | D22: Biss | G22: Steen, Michael | H22: V0U211062 | J22: jlbjr7784@gmail.com | K22: Assembler B | L22: 45232 | O22: Active | P22: 210375 | Q22: Biweekly | R22: Full Time | S22: 025 | T22: 025-NGP Hyson Products | U22: Assembly Hyson | V22: 000200 | W22: Hyson Products | Z22: USA | AA22: H05 | AB22: FMG-H05 | AC22: =IF(ISBLANK(H22),VLOOKUP(P22,'US Supervisor Map'!A:D,4,FALSE),MID(H22,4,6)) -> 211062 | AD22: =IFERROR(VLOOKUP(T22,'Org Map'!A:E,4),"BU Description Not Mapped") -> 0096 | AE22: =IFERROR(VLOOKUP(V22,'Org Map'!C:E,3),"Home Department Code Not Mapped") -> 200 | AF22: =IFERROR(VLOOKUP(AA22,'Salary Map'!A:D,3,FALSE),"Salary Code Not Mapped") -> Default | AG22: =IFERROR(VLOOKUP(AA22,'Salary Map'!A:D,4,FALSE),"Salary Code Not Mapped") -> General | AH22: =IFERROR(VLOOKUP(Z22,'Country Map'!A:B,2,FALSE),"Legal Country Not Mapped") -> US | AI22: =IFERROR(VLOOKUP(X22,'Language Map'!A:C,3,FALSE),IFERROR(VLOOKUP(T22,'Org Map'!A:F,6,FALSE),"ADP and BU Language Code Not Mapped"))&AH22 -> en_US | AJ22: =IFERROR(VLOOKUP(T22,'Org Map'!A:G,7),"BU Currency Not Mapped") -> USD | AK22: =IF(ISBLANK(E22),"",TRIM(E22&" "&F22)) | AL22: =IFERROR(VLOOKUP(O22,'Status Map'!A:B,2,FALSE),"Position Status Not Mapped") -> Y | AM22: =IF(AL22="N",TEXT(M22,"yyyymmdd"),"") | AO22: =B22&C22&D22 -> JamesBiss | AP22: =LEFT(G22,FIND(",",G22)-1) -> Steen | AQ22: =IFERROR(VLOOKUP(AP22,D:P,13,FALSE),"No Reports to Name") -> 211062 | AR22: =AQ22=MID(H22,4,6) -> TRUE
A23: KSX | B23: Brenda | D23: Bixler | G23: LaPlante, Derek | H23: KSY211736 | I23: bbixler@onebarnes.com | J23: beebix911@gmail.com | K23: Expeditor, Warehouse | L23: 45502 | O23: Active | P23: 211174 | Q23: Biweekly | R23: Full Time | S23: 088 | T23: 088-AS Raymond | U23: FG Warehouse | V23: 005200 | W23: AS Raymond | Z23: USA | AA23: S06 | AB23: FMG-S06 | AC23: =IF(ISBLANK(H23),VLOOKUP(P23,'US Supervisor Map'!A:D,4,FALSE),MID(H23,4,6)) -> 211736 | AD23: =IFERROR(VLOOKUP(T23,'Org Map'!A:E,4),"BU Description Not Mapped") -> 0088 | AE23: =IFERROR(VLOOKUP(V23,'Org Map'!C:E,3),"Home Department Code Not Mapped") -> 5200 | AF23: =IFERROR(VLOOKUP(AA23,'Salary Map'!A:D,3,FALSE),"Salary Code Not Mapped") -> Default | AG23: =IFERROR(VLOOKUP(AA23,'Salary Map'!A:D,4,FALSE),"Salary Code Not Mapped") -> General | AH23: =IFERROR(VLOOKUP(Z23,'Country Map'!A:B,2,FALSE),"Legal Country Not Mapped") -> US | AI23: =IFERROR(VLOOKUP(X23,'Language Map'!A:C,3,FALSE),IFERROR(VLOOKUP(T23,'Org Map'!A:F,6,FALSE),"ADP and BU Language Code Not Mapped"))&AH23 -> en_US | AJ23: =IFERROR(VLOOKUP(T23,'Org Map'!A:G,7),"BU Currency Not Mapped") -> USD | AK23: =IF(ISBLANK(E23),"",TRIM(E23&" "&F23)) | AL23: =IFERROR(VLOOKUP(O23,'Status Map'!A:B,2,FALSE),"Position Status Not Mapped") -> Y | AM23: =IF(AL23="N",TEXT(M23,"yyyymmdd"),"") | AO23: =B23&C23&D23 -> BrendaBixler | AP23: =LEFT(G23,FIND(",",G23)-1) -> LaPlante | AQ23: =IFERROR(VLOOKUP(AP23,D:P,13,FALSE),"No Reports to Name") -> 211736 | AR23: =AQ23=MID(H23,4,6) -> TRUE
A24: KSX | B24: Robert | D24: Bordner | G24: Burchell, Mathew | H24: KSY211756 | J24: robertbordner@gmail.com | K24: Assistant, Warehouse II | L24: 46190 | O24: Active | Q24: Biweekly | R24: Temporary | S24: 088 | T24: 088-AS Raymond | U24: Assembly | V24: 005100 | W24: AS Raymond | Z24: USA | AA24: S05 | AB24: FMG-S05 | AC24: =IF(ISBLANK(H24),VLOOKUP(P24,'US Supervisor Map'!A:D,4,FALSE),MID(H24,4,6)) -> 211756 | AD24: =IFERROR(VLOOKUP(T24,'Org Map'!A:E,4),"BU Description Not Mapped") -> 0088 | AE24: =IFERROR(VLOOKUP(V24,'Org Map'!C:E,3),"Home Department Code Not Mapped") -> 5100 | AF24: =IFERROR(VLOOKUP(AA24,'Salary Map'!A:D,3,FALSE),"Salary Code Not Mapped") -> Default | AG24: =IFERROR(VLOOKUP(AA24,'Salary Map'!A:D,4,FALSE),"Salary Code Not Mapped") -> General | AH24: =IFERROR(VLOOKUP(Z24,'Country Map'!A:B,2,FALSE),"Legal Country Not Mapped") -> US | AI24: =IFERROR(VLOOKUP(X24,'Language Map'!A:C,3,FALSE),IFERROR(VLOOKUP(T24,'Org Map'!A:F,6,FALSE),"ADP and BU Language Code Not Mapped"))&AH24 -> en_US | AJ24: =IFERROR(VLOOKUP(T24,'Org Map'!A:G,7),"BU Currency Not Mapped") -> USD | AK24: =IF(ISBLANK(E24),"",TRIM(E24&" "&F24)) | AL24: =IFERROR(VLOOKUP(O24,'Status Map'!A:B,2,FALSE),"Position Status Not Mapped") -> Y | AM24: =IF(AL24="N",TEXT(M24,"yyyymmdd"),"") | AO24: =B24&C24&D24 -> RobertBordner | AP24: =LEFT(G24,FIND(",",G24)-1) -> Burchell | AQ24: =IFERROR(VLOOKUP(AP24,D:P,13,FALSE),"No Reports to Name") -> 211756 | AR24: =AQ24=MID(H24,4,6) -> TRUE
A25: KSX | B25: Jack | C25: O | D25: Bradford | G25: Halpin, Emma | H25: KSY211489 | J25: jb7222222@gmail.com | K25: Intern, Project Mgr Indir | L25: 46153 | M25: 46241 | O25: Terminated | P25: 213234 | Q25: Biweekly | R25: Intern | S25: 088 | T25: 088-AS Raymond | U25: Marketing | V25: 008300 | W25: AS Raymond | Z25: USA | AA25: H05 | AB25: FMG-H05 | AC25: =IF(ISBLANK(H25),VLOOKUP(P25,'US Supervisor Map'!A:D,4,FALSE),MID(H25,4,6)) -> 211489 | AD25: =IFERROR(VLOOKUP(T25,'Org Map'!A:E,4),"BU Description Not Mapped") -> 0088 | AE25: =IFERROR(VLOOKUP(V25,'Org Map'!C:E,3),"Home Department Code Not Mapped") -> 8300 | AF25: =IFERROR(VLOOKUP(AA25,'Salary Map'!A:D,3,FALSE),"Salary Code Not Mapped") -> Default | AG25: =IFERROR(VLOOKUP(AA25,'Salary Map'!A:D,4,FALSE),"Salary Code Not Mapped") -> General | AH25: =IFERROR(VLOOKUP(Z25,'Country Map'!A:B,2,FALSE),"Legal Country Not Mapped") -> US | AI25: =IFERROR(VLOOKUP(X25,'Language Map'!A:C,3,FALSE),IFERROR(VLOOKUP(T25,'Org Map'!A:F,6,FALSE),"ADP and BU Language Code Not Mapped"))&AH25 -> en_US | AJ25: =IFERROR(VLOOKUP(T25,'Org Map'!A:G,7),"BU Currency Not Mapped") -> USD | AK25: =IF(ISBLANK(E25),"",TRIM(E25&" "&F25)) | AL25: =IFERROR(VLOOKUP(O25,'Status Map'!A:B,2,FALSE),"Position Status Not Mapped") -> N | AM25: =IF(AL25="N",TEXT(M25,"yyyymmdd"),"") -> 20260807 | AN25: =IF(M25>AN20,"Fix and Include Record","Exclude record termination over 45 days ago") -> Fix and Include Record | AO25: =B25&C25&D25 -> JackOBradford | AP25: =LEFT(G25,FIND(",",G25)-1) -> Halpin | AQ25: =IFERROR(VLOOKUP(AP25,D:P,13,FALSE),"No Reports to Name") -> 211489 | AR25: =AQ25=MID(H25,4,6) -> TRUE
A26: KSW | B26: John | D26: Brewer | G26: Steen, Michael | H26: V0U211062 | J26: maddenbeast09@gmail.com | K26: Boring Mill Operator | L26: 46230 | O26: Active | Q26: Biweekly | R26: Temporary | AA26: H07 | AB26: FMG-H07 | AC26: =IF(ISBLANK(H26),VLOOKUP(P26,'US Supervisor Map'!A:D,4,FALSE),MID(H26,4,6)) -> 211062 | AD26: =IFERROR(VLOOKUP(T26,'Org Map'!A:E,4),"BU Description Not Mapped") -> BU Description Not Mapped | AE26: =IFERROR(VLOOKUP(V26,'Org Map'!C:E,3),"Home Department Code Not Mapped") -> Home Department Code Not Mapped | AF26: =IFERROR(VLOOKUP(AA26,'Salary Map'!A:D,3,FALSE),"Salary Code Not Mapped") -> Default | AG26: =IFERROR(VLOOKUP(AA26,'Salary Map'!A:D,4,FALSE),"Salary Code Not Mapped") -> General | AH26: =IFERROR(VLOOKUP(Z26,'Country Map'!A:B,2,FALSE),"Legal Country Not Mapped") -> Legal Country Not Mapped | AI26: =IFERROR(VLOOKUP(X26,'Language Map'!A:C,3,FALSE),IFERROR(VLOOKUP(T26,'Org Map'!A:F,6,FALSE),"ADP and BU Language Code Not Mapped"))&AH26 -> ADP and BU Language Code Not MappedLegal Country Not Mapped | AJ26: =IFERROR(VLOOKUP(T26,'Org Map'!A:G,7),"BU Currency Not Mapped") -> BU Currency Not Mapped | AK26: =IF(ISBLANK(E26),"",TRIM(E26&" "&F26)) | AL26: =IFERROR(VLOOKUP(O26,'Status Map'!A:B,2,FALSE),"Position Status Not Mapped") -> Y | AM26: =IF(AL26="N",TEXT(M26,"yyyymmdd"),"") | AO26: =B26&C26&D26 -> JohnBrewer | AP26: =LEFT(G26,FIND(",",G26)-1) -> Steen | AQ26: =IFERROR(VLOOKUP(AP26,D:P,13,FALSE),"No Reports to Name") -> 211062 | AR26: =AQ26=MID(H26,4,6) -> TRUE
A27: V0U | B27: James | D27: Brower | G27: Bate, Natalie | H27: V0U213037 | I27: JBrower@onebarnes.com | J27: browerj@cox.net | K27: Engineer, Application III | L27: 34736 | O27: Active | P27: 006769 | Q27: Monthly | R27: Full Time | S27: 025 | T27: 025-NGP Hyson Products | U27: Engineering | V27: 000718 | W27: Hyson Products | Z27: USA | AA27: S15 | AB27: FMG-S15 | AC27: =IF(ISBLANK(H27),VLOOKUP(P27,'US Supervisor Map'!A:D,4,FALSE),MID(H27,4,6)) -> 213037 | AD27: =IFERROR(VLOOKUP(T27,'Org Map'!A:E,4),"BU Description Not Mapped") -> 0096 | AE27: =IFERROR(VLOOKUP(V27,'Org Map'!C:E,3),"Home Department Code Not Mapped") -> 718 | AF27: =IFERROR(VLOOKUP(AA27,'Salary Map'!A:D,3,FALSE),"Salary Code Not Mapped") -> Default | AG27: =IFERROR(VLOOKUP(AA27,'Salary Map'!A:D,4,FALSE),"Salary Code Not Mapped") -> General | AH27: =IFERROR(VLOOKUP(Z27,'Country Map'!A:B,2,FALSE),"Legal Country Not Mapped") -> US | AI27: =IFERROR(VLOOKUP(X27,'Language Map'!A:C,3,FALSE),IFERROR(VLOOKUP(T27,'Org Map'!A:F,6,FALSE),"ADP and BU Language Code Not Mapped"))&AH27 -> en_US | AJ27: =IFERROR(VLOOKUP(T27,'Org Map'!A:G,7),"BU Currency Not Mapped") -> USD | AK27: =IF(ISBLANK(E27),"",TRIM(E27&" "&F27)) | AL27: =IFERROR(VLOOKUP(O27,'Status Map'!A:B,2,FALSE),"Position Status Not Mapped") -> Y | AM27: =IF(AL27="N",TEXT(M27,"yyyymmdd"),"") | AO27: =B27&C27&D27 -> JamesBrower | AP27: =LEFT(G27,FIND(",",G27)-1) -> Bate | AQ27: =IFERROR(VLOOKUP(AP27,D:P,13,FALSE),"No Reports to Name") -> 213037 | AR27: =AQ27=MID(H27,4,6) -> TRUE
