Workbook

Sheet 320 One Time
A1: All fields must be represented. Fields with dark red text are system-required. Other fields may be required by your company's configuration.
A2: 1 | B2: 2 | C2: 3 | D2: 4 | E2: 5 | F2: 6 | G2: 7 | H2: 8 | I2: 9
A3: Trx Type (320) | B3: Current Employee ID | C3: New Employee ID | D3: New Login ID | E3: Future Use 1 | F3: Future Use 2 | G3: Future Use 3 | H3: Future Use 4 | I3: Future Use 5
A4: 3 | B4: 48 | C4: 48 | D4: 64 | E4: Future Use | F4: Future Use | G4: Future Use | H4: Future Use | I4: Future Use
A5: 320 | B5: =ADP!P5 -> 211837 | D5: ='305 ADP Employee (All)'!F5 -> tabitua1@onebarnes.com.new.uat
A6: 320 | B6: =ADP!P6 -> 213331 | D6: ='305 ADP Employee (All)'!F6 -> gadams@onebarnes.com.new.uat
A7: 320 | B7: =ADP!P7 -> 213226 | D7: ='305 ADP Employee (All)'!F7 -> kagler@onebarnes.com.new.uat
A8: 320 | B8: =ADP!P8 -> 210892 | D8: ='305 ADP Employee (All)'!F8 -> talexander@onebarnes.com.new.uat
A9: 320 | B9: =ADP!P9 -> 206848 | D9: ='305 ADP Employee (All)'!F9 -> TAllen2@onebarnes.com.new.uat
A10: 320 | B10: =ADP!P10 -> 201688 | D10: ='305 ADP Employee (All)'!F10 -> KAshley@onebarnes.com.new.uat
A11: 320 | B11: =ADP!P11 -> 902688 | D11: ='305 ADP Employee (All)'!F11 -> jbailey@onebarnes.com.new.uat
A12: 320 | B12: =ADP!P12 -> 207709 | D12: ='305 ADP Employee (All)'!F12 -> TBair@onebarnes.com.new.uat
A13: 320 | B13: =ADP!P13 -> 209579 | D13: ='305 ADP Employee (All)'!F13 -> kbarry@onebarnes.com.new.uat
A14: 320 | B14: =ADP!P14 -> 213037 | D14: ='305 ADP Employee (All)'!F14 -> nbate@onebarnes.com.new.uat
A15: 320 | B15: =ADP!P15 -> 213333 | D15: ='305 ADP Employee (All)'!F15 -> mbeasley@onebarnes.com.new.uat
A16: 320 | B16: =ADP!P16 -> 212626 | D16: ='305 ADP Employee (All)'!F16 -> ebeatrice@onebarnes.com.new.uat
... A169: 320 | B169: =ADP!P169 -> 0 | D169: ='305 ADP Employee (All)'!F169 -> .new.uat
A170: 320 | B170: =ADP!#REF! -> #REF! | D170: ='305 ADP Employee (All)'!F170 -> #REF!
A171: 320 | B171: =ADP!#REF! -> #REF! | D171: ='305 ADP Employee (All)'!F171 -> #REF!
A172: 320 | B172: =ADP!#REF! -> #REF! | D172: ='305 ADP Employee (All)'!F172 -> #REF!
A173: 320 | B173: =ADP!#REF! -> #REF! | D173: ='305 ADP Employee (All)'!F173 -> #REF!
A174: 320 | B174: =ADP!#REF! -> #REF! | D174: ='305 ADP Employee (All)'!F174 -> #REF!
A175: 320 | B175: =ADP!#REF! -> #REF! | D175: ='305 ADP Employee (All)'!F175 -> #REF!
A176: 320 | B176: =ADP!#REF! -> #REF! | D176: ='305 ADP Employee (All)'!F176 -> #REF!
A177: 320 | B177: =ADP!#REF! -> #REF! | D177: ='305 ADP Employee (All)'!F177 -> #REF!
A178: 320 | B178: =ADP!#REF! -> #REF! | D178: ='305 ADP Employee (All)'!F178 -> #REF!
A179: 320 | B179: =ADP!#REF! -> #REF! | D179: ='305 ADP Employee (All)'!F179 -> #REF!
A180: 320 | B180: =ADP!#REF! -> #REF! | D180: ='305 ADP Employee (All)'!F180 -> #REF!
A181: 320 | B181: =ADP!#REF! -> #REF! | D181: ='305 ADP Employee (All)'!F181 -> #REF!
... A203: 320 | B203: =ADP!#REF! -> #REF! | D203: ='305 ADP Employee (All)'!F203 -> #REF!

Sheet Multiple Payrolls
A1: Details for Count of Payroll Company Code
A3: Payroll Company Code | B3: Legal First Name | C3: Middle Initial | D3: Legal Last Name | E3: Preferred or Chosen First Name | F3: Preferred or Chosen Last Name | G3: Reports To Legal Name | H3: Supervisor ID | I3: Work Contact: Work Email | J3: Personal Contact: Personal Email | K3: Job Title Description | L3: Hire Date | M3: Termination Date | N3: Rehire Date | O3: Position Status | P3: File Number | Q3: Pay Frequency | R3: Employee Type | S3: Business Unit Code | T3: Business Unit Description | U3: Home Department Description | V3: Home Department Code | W3: Location Description | X3: Language Description | Y3: Language Code | Z3: Legal / Preferred Address: Country Code | AA3: Pay Grade Code | AB3: Pay Grade Description | AC3: SupervisorID Formatted | AD3: Org Unit 1 | AE3: Org Unit 2 | AF3: Concur Profile | AG3: Travel Profile | AH3: Legal Country | AI3: Local Code | AJ3: Reumbursement Currency | AK3: Perferred Name | AL3: Status | AM3: Term Date | AN3: 7/20/26 | AO3: Name | AP3: SupervisorLastName | AQ3: Lookup Supervisor ID | AR3: SupervisorName=Supervisor ID
A4: KSX | B4: Abdellatef | C4: M | D4: Mahmoud | G4: Burchell, Mathew | H4: KSY211756 | J4: oomer77@yahoo.com | K4: Assistant, Warehouse II | L4: 45208 | O4: Active | P4: 210316 | Q4: Biweekly | R4: Full Time | S4: 088 | T4: 088-AS Raymond | U4: Assembly | V4: 005100 | W4: AS Raymond | Z4: USA | AA4: S05 | AB4: FMG-S05 | AC4: 211756 | AD4: 0088 | AE4: 5100 | AF4: Default | AG4: General | AH4: US | AI4: en_US | AJ4: USD | AL4: Y | AO4: AbdellatefMMahmoud | AP4: Burchell | AQ4: 211756 | AR4: TRUE
A5: KSY | B5: Alex | D5: Palicki | G5: Creager, Andrew | H5: KSY212699 | I5: apalicki@onebarnes.com | J5: alexpalicki4@gmail.com | K5: Buyer III | L5: 45831 | O5: Active | P5: 212119 | Q5: Monthly | R5: Full Time | S5: 088 | T5: 088-AS Raymond | U5: Admin-Material Management | V5: 009400 | W5: AS Raymond | Z5: USA | AA5: S13 | AB5: FMG-S13 | AC5: 212699 | AD5: 0088 | AE5: 9400 | AF5: Default | AG5: General | AH5: US | AI5: en_US | AJ5: USD | AL5: Y | AO5: AlexPalicki | AP5: Creager | AQ5: 212699 | AR5: TRUE
A6: KSX | B6: Amir | D6: Dillard | G6: Burchell, Mathew | H6: KSY211756 | I6: adillard1@onebarnes.com | J6: amirdillard4@gmail.com | K6: Assistant, Warehouse II | L6: 45754 | O6: Active | P6: 211895 | Q6: Biweekly | R6: Full Time | S6: 088 | T6: 088-AS Raymond | U6: Assembly | V6: 005100 | W6: AS Raymond | Z6: USA | AA6: S05 | AB6: FMG-S05 | AC6: 211756 | AD6: 0088 | AE6: 5100 | AF6: Default | AG6: General | AH6: US | AI6: en_US | AJ6: USD | AL6: Y | AO6: AmirDillard | AP6: Burchell | AQ6: 211756 | AR6: TRUE
A7: V0U | B7: Amy | C7: C | D7: McGuire | G7: Warner, Dwight | H7: V0U008750 | I7: AMcGuire@onebarnes.com | J7: RedAmyMcG@gmail.com | K7: Accountant III | L7: 35338 | O7: Active | P7: 007861 | Q7: Monthly | R7: Full Time | S7: 025 | T7: 025-NGP Hyson Products | U7: Finance | V7: 000910 | W7: Hyson Products | Z7: USA | AA7: S13 | AB7: FMG-S13 | AC7: 008750 | AD7: 0096 | AE7: 910 | AF7: Default | AG7: General | AH7: US | AI7: en_US | AJ7: USD | AL7: Y | AO7: AmyCMcGuire | AP7: Warner | AQ7: 008750 | AR7: TRUE
A8: KSY | B8: Andrew | C8: J | D8: Creager | G8: Bailey, Jason | H8: KSY211766 | I8: acreager@onebarnes.com | K8: Mgr, Supply Chain III | L8: 45957 | O8: Active | P8: 212699 | Q8: Monthly | R8: Full Time | S8: 088 | T8: 088-AS Raymond | U8: Admin-Material Management | V8: 009400 | W8: AS Raymond | Z8: USA | AA8: S17 | AB8: FMG-S17 | AC8: 211766 | AD8: 0088 | AE8: 9400 | AF8: Default | AG8: General | AH8: US | AI8: en_US | AJ8: USD | AL8: Y | AO8: AndrewJCreager | AP8: Bailey | AQ8: 902688 | AR8: FALSE
A9: KSX | B9: Angela | D9: Myers | G9: Burchell, Mathew | H9: KSY211756 | J9: amm823@bex.net | K9: Assistant, Warehouse II | L9: 45881 | O9: Active | P9: 212349 | Q9: Biweekly | R9: Full Time | S9: 088 | T9: 088-AS Raymond | U9: Assembly | V9: 005100 | W9: AS Raymond | Z9: USA | AA9: S05 | AB9: FMG-S05 | AC9: 211756 | AD9: 0088 | AE9: 5100 | AF9: Default | AG9: General | AH9: US | AI9: en_US | AJ9: USD | AL9: Y | AO9: AngelaMyers | AP9: Burchell | AQ9: 211756 | AR9: TRUE
A10: V0U | B10: Anne | C10: M | D10: Garber | G10: Bate, Natalie | I10: agarber@onebarnes.com | J10: anne.michael00@gmail.com | K10: Mgr, Program | L10: 46265 | O10: Active | P10: 902627 | Q10: Monthly | R10: Full Time | S10: 025 | T10: 025-NGP Hyson Products | U10: Administration | V10: 000917 | W10: Hyson Products | Z10: USA | AA10: S17 | AB10: FMG-S17 | AD10: 0096 | AE10: 0007 | AF10: Default | AG10: General | AH10: US | AI10: en_US | AJ10: USD | AL10: Y | AO10: AnneMGarber | AP10: Bate | AQ10: 213037 | AR10: FALSE
A11: KSW | B11: Anthony | D11: Desillas | J11: desillasa@yahoo.com | K11: Lathe Operator | L11: 45859 | M11: 46046 | O11: Terminated | P11: 212244 | Q11: Biweekly | R11: Full Time | S11: 025 | T11: 025-NGP Hyson Products | U11: CNC Lathe Hyson | V11: 000100 | W11: Hyson Products | Z11: USA | AA11: H07 | AB11: FMG-H07 | AD11: 0096 | AE11: 100 | AF11: Default | AG11: General | AH11: US | AI11: en_US | AJ11: USD | AL11: N | AM11: 20260124 | AN11: Exclude record termination over 45 days ago | AO11: AnthonyDesillas | AP11: #VALUE! | AQ11: No Reports to Name | AR11: FALSE
A12: KSW | B12: Anthony | C12: J | D12: Frimel | G12: Steen, Michael | H12: V0U211062 | I12: afrimel@onebarnes.com | J12: tfrimel@att.net | K12: Tech, Manufacturing A | L12: 37410 | O12: Active | P12: 004352 | Q12: Biweekly | R12: Full Time | S12: 025 | T12: 025-NGP Hyson Products | U12: CNC Lathe Hyson | V12: 000100 | W12: Hyson Products | Z12: USA | AA12: H08 | AB12: FMG-H08 | AC12: 211062 | AD12: 0096 | AE12: 100 | AF12: Default | AG12: General | AH12: US | AI12: en_US | AJ12: USD | AL12: Y | AO12: AnthonyJFrimel | AP12: Steen | AQ12: 211062 | AR12: TRUE
A13: V0U | B13: Anthony | C13: J | D13: Moavero | G13: Brower, James | I13: amoavero1@onebarnes.com | K13: Intern, Engineering Indir | L13: 45810 | M13: 46176 | O13: Terminated | P13: 212052 | Q13: Monthly | R13: Intern | S13: 025 | T13: 025-NGP Hyson Products | U13: Sustaining Engineering | V13: 000900 | W13: Hyson Products | Z13: USA | AA13: H05 | AB13: FMG-H05 | AD13: 0096 | AE13: 900 | AF13: Default | AG13: General | AH13: US | AI13: en_US | AJ13: USD | AL13: N | AM13: 20260603 | AN13: Fix and Include Record | AO13: AnthonyJMoavero | AP13: Brower | AQ13: 006769 | AR13: FALSE
A14: KSX | B14: Anthony | C14: J | D14: Moavero | I14: amoavero1@onebarnes.com | L14: 45810 | M14: 45878 | O14: Terminated | P14: 212052 | Q14: Biweekly | R14: Full Time | W14: AS Raymond | Z14: USA | AD14: BU Description Not Mapped | AE14: Home Department Code Not Mapped | AF14: Salary Code Not Mapped | AG14: Salary Code Not Mapped | AH14: US | AI14: ADP and BU Language Code Not MappedUS | AJ14: BU Currency Not Mapped | AL14: N | AM14: 20250809 | AN14: Exclude record termination over 45 days ago | AO14: AnthonyJMoavero | AP14: #VALUE! | AQ14: No Reports to Name | AR14: FALSE
A15: KSW | B15: Anthony | C15: J | D15: Moavero | G15: Brower, James | H15: V0U006769 | I15: amoavero1@onebarnes.com | K15: Intern, Engineering Indir | L15: 45810 | M15: 46248 | O15: Terminated | P15: 212052 | Q15: Biweekly | R15: Intern | S15: 025 | T15: 025-NGP Hyson Products | U15: Sustaining Engineering | V15: 000900 | W15: Hyson Products | Z15: USA | AA15: H05 | AB15: FMG-H05 | AC15: 006769 | AD15: 0096 | AE15: 900 | AF15: Default | AG15: General | AH15: US | AI15: en_US | AJ15: USD | AL15: N | AM15: 20260814 | AN15: Exclude record termination over 45 days ago | AO15: AnthonyJMoavero | AP15: Brower | AQ15: 006769 | AR15: TRUE
A16: V0U | B16: Anthony | C16: J | D16: Moavero | G16: Brower, James | I16: amoavero1@onebarnes.com | K16: Intern, Engineering Indir | L16: 45810 | M16: 46176 | O16: Terminated | P16: 212052 | Q16: Biweekly | R16: Intern | S16: 025 | T16: 025-NGP Hyson Products | U16: Sustaining Engineering | V16: 000900 | W16: Hyson Products | Z16: USA | AA16: H05 | AB16: FMG-H05 | AD16: 0096 | AE16: 900 | AF16: Default | AG16: General | AH16: US | AI16: en_US | AJ16: USD | AL16: N | AM16: 20260603 | AN16: Fix and Include Record | AO16: AnthonyJMoavero | AP16: Brower | AQ16: 006769 | AR16: FALSE
A17: KSX | B17: Asia | D17: Sexton | G17: Burchell, Mathew | H17: KSY211756 | J17: asexton@yahoo.com | K17: Assistant, Warehouse II | L17: 46190 | M17: 46251 | O17: Terminated | Q17: Biweekly | R17: Temporary | S17: 088 | T17: 088-AS Raymond | U17: Assembly | V17: 005100 | W17: AS Raymond | Z17: USA | AA17: S05 | AB17: FMG-S05 | AC17: 211756 | AD17: 0088 | AE17: 5100 | AF17: Default | AG17: General | AH17: US | AI17: en_US | AJ17: USD | AL17: N | AM17: 20260817 | AN17: Fix and Include Record | AO17: AsiaSexton | AP17: Burchell | AQ17: 211756 | AR17: TRUE
A18: KSX | B18: Aydrian | C18: M | D18: Ahrens | G18: Burchell, Mathew | H18: KSY211756 | J18: aydrian0323@yahoo.com | K18: Assistant, Warehouse II | L18: 45754 | O18: Active | P18: 211901 | Q18: Biweekly | R18: Full Time | S18: 088 | T18: 088-AS Raymond | U18: Assembly | V18: 005100 | W18: AS Raymond | Z18: USA | AA18: S05 | AB18: FMG-S05 | AC18: 211756 | AD18: 0088 | AE18: 5100 | AF18: Default | AG18: General | AH18: US | AI18: en_US | AJ18: USD | AL18: Y | AO18: AydrianMAhrens | AP18: Burchell | AQ18: 211756 | AR18: TRUE
A19: KSX | B19: Barbara | C19: C | D19: Wilkinson | G19: Burchell, Mathew | H19: KSY211756 | J19: wilkinsonb518@gmail.com | K19: Assistant, Warehouse II | L19: 44942 | O19: Active | P19: 209539 | Q19: Biweekly | R19: Full Time | S19: 088 | T19: 088-AS Raymond | U19: Assembly | V19: 005100 | W19: AS Raymond | Z19: USA | AA19: S05 | AB19: FMG-S05 | AC19: 211756 | AD19: 0088 | AE19: 5100 | AF19: Default | AG19: General | AH19: US | AI19: en_US | AJ19: USD | AL19: Y | AO19: BarbaraCWilkinson | AP19: Burchell | AQ19: 211756 | AR19: TRUE
A20: KSX | B20: Benjamin | C20: D | D20: Uncapher | G20: Rafferty, Jonathan | H20: KSY211131 | I20: buncapher@onebarnes.com | K20: Rep, Customer Service III | L20: 45867 | O20: Active | P20: 212254 | Q20: Biweekly | R20: Full Time | S20: 088 | T20: 088-AS Raymond | U20: Inside Sales | V20: 008100 | W20: AS Raymond | Z20: USA | AA20: S11 | AB20: FMG-S11 | AC20: 211131 | AD20: 0088 | AE20: 8100 | AF20: Default | AG20: General | AH20: US | AI20: en_US | AJ20: USD | AL20: Y | AO20: BenjaminDUncapher | AP20: Rafferty | AQ20: 211131 | AR20: TRUE
A21: KSY | B21: Benjamin | C21: D | D21: Uncapher | I21: buncapher@onebarnes.com | K21: Rep, Customer Service III | L21: 45867 | M21: 46175 | O21: Terminated | P21: 212254 | Q21: Monthly | R21: Full Time | S21: 088 | T21: 088-AS Raymond | U21: Inside Sales | V21: 008100 | W21: AS Raymond | Z21: USA | AA21: S11 | AB21: FMG-S11 | AD21: 0088 | AE21: 8100 | AF21: Default | AG21: General | AH21: US | AI21: en_US | AJ21: USD | AL21: N | AM21: 20260602 | AN21: Fix and Include Record | AO21: BenjaminDUncapher | AP21: #VALUE! | AQ21: No Reports to Name | AR21: FALSE
A22: KSY | B22: Benjamin | D22: Sullivan | G22: Creager, Andrew | H22: KSY212699 | I22: bsullivan@onebarnes.com | K22: Planner, Production II | L22: 45131 | O22: Active | P22: 210103 | Q22: Monthly | R22: Full Time | S22: 088 | T22: 088-AS Raymond | U22: Admin-Material Management | V22: 009400 | W22: AS Raymond | Z22: USA | AA22: S12 | AB22: FMG-S12 | AC22: 212699 | AD22: 0088 | AE22: 9400 | AF22: Default | AG22: General | AH22: US | AI22: en_US | AJ22: USD | AL22: Y | AO22: BenjaminSullivan | AP22: Creager | AQ22: 212699 | AR22: TRUE
A23: KSW | B23: Bobby | D23: Hicks | G23: Wallace, Derron | H23: V0U211998 | I23: bhicks@onebarnes.com | J23: bhicks1@me.com | K23: Lead, Unit Team | L23: 45481 | O23: Active | P23: 211145 | Q23: Biweekly | R23: Full Time | S23: 025 | T23: 025-NGP Hyson Products | U23: Assembly Hyson | V23: 000200 | W23: Hyson Products | Z23: USA | AA23: H08 | AB23: FMG-H08 | AC23: 211998 | AD23: 0096 | AE23: 200 | AF23: Default | AG23: General | AH23: US | AI23: en_US | AJ23: USD | AL23: Y | AO23: BobbyHicks | AP23: Wallace | AQ23: 211998 | AR23: TRUE
A24: KSY | B24: Bonnetta | C24: D | D24: Warren | G24: Oleksa, Laura | H24: V0U209181 | I24: bwarren@onebarnes.com | K24: Mgr, HR I | L24: 45958 | O24: Active | P24: 212705 | Q24: Monthly | R24: Full Time | S24: 088 | T24: 088-AS Raymond | U24: HR CU | V24: 009210 | W24: Works from home - Ohio | Z24: USA | AA24: S15 | AB24: FMG-S15 | AC24: 209181 | AD24: 0088 | AE24: 9210 | AF24: Default | AG24: General | AH24: US | AI24: en_US | AJ24: USD | AL24: Y | AO24: BonnettaDWarren | AP24: Oleksa | AQ24: 209181 | AR24: TRUE
A25: KSY | B25: Bradley | D25: Masters | E25: Brad | F25: Masters | G25: Rodriguez, Siobhan | H25: V0U207588 | I25: bmasters@onebarnes.com | J25: brad.a.masters@gmail.com | K25: Mgr, Sales | L25: 46223 | O25: Active | P25: 902437 | Q25: Monthly | R25: Full Time | S25: 088 | T25: 088-AS Raymond | U25: Outside Sales | V25: 008200 | W25: Works from home - Ohio | Z25: USA | AA25: S16 | AB25: FMG-S16 | AC25: 207588 | AD25: 0088 | AE25: 8200 | AF25: Default | AG25: General | AH25: US | AI25: en_US | AJ25: USD | AK25: Brad Masters | AL25: Y | AO25: BradleyMasters | AP25: Rodriguez | AQ25: 212338 | AR25: FALSE
A26: KSX | B26: Brandon | D26: Hibbitts | H26: KSY900848 | I26: bhibbitts@onebarnes.com | J26: hibbitts.brandon@gmail.com | K26: Intern, IT Indirect | L26: 45502 | M26: 46203 | O26: Terminated | P26: 211181 | Q26: Biweekly | R26: Part Time | S26: 088 | T26: 088-AS Raymond | U26: Business Applications | V26: 009150 | W26: AS Raymond | Z26: USA | AA26: H05 | AB26: FMG-H05 | AC26: 900848 | AD26: 0088 | AE26: 9150 | AF26: Default | AG26: General | AH26: US | AI26: en_US | AJ26: USD | AL26: N | AM26: 20260630 | AN26: Fix and Include Record | AO26: BrandonHibbitts | AP26: #VALUE! | AQ26: No Reports to Name | AR26: FALSE
A27: KSY | B27: Brandon | D27: Hibbitts | G27: Erdogan, Mehmet | H27: 000207199N | I27: bhibbitts@onebarnes.com | J27: hibbitts.brandon@gmail.com | K27: Analyst, Help Desk II | L27: 45502 | O27: Active | P27: 211181 | Q27: Monthly | R27: Full Time | S27: 088 | T27: 088-AS Raymond | U27: Business Applications | V27: 009150 | W27: AS Raymond | Z27: USA | AA27: S12 | AB27: FMG-S12 | AC27: 207199 | AD27: 0088 | AE27: 9150 | AF27: Default | AG27: General | AH27: US | AI27: en_US | AJ27: USD | AL27: Y | AO27: BrandonHibbitts | AP27: Erdogan | AQ27: No Reports to Name | AR27: FALSE
A28: KSX | B28: Brandon | D28: Kelly | G28: Alexander, Thomas | H28: KSY210892 | J28: bkelly8@rockets.utoledo.edu | K28: Intern, Operations Direct | L28: 46155 | M28: 46248 | O28: Terminated | P28: 213235 | Q28: Biweekly | R28: Intern | S28: 088 | T28: 088-AS Raymond | U28: Admin-Quality | V28: 009500 | W28: AS Raymond | Z28: USA | AA28: H05 | AB28: FMG-H05 | AC28: 210892 | AD28: 0088 | AE28: 9500 | AF28: Default | AG28: General | AH28: US | AI28: en_US | AJ28: USD | AL28: N | AM28: 20260814 | AN28: Exclude record termination over 45 days ago | AO28: BrandonKelly | AP28: Alexander | AQ28: 210892 | AR28: TRUE
A29: KSX | B29: Brenda | D29: Bixler | G29: LaPlante, Derek | H29: KSY211736 | I29: bbixler@onebarnes.com | J29: beebix911@gmail.com | K29: Expeditor, Warehouse | L29: 45502 | O29: Active | P29: 211174 | Q29: Biweekly | R29: Full Time | S29: 088 | T29: 088-AS Raymond | U29: FG Warehouse | V29: 005200 | W29: AS Raymond | Z29: USA | AA29: S06 | AB29: FMG-S06 | AC29: 211736 | AD29: 0088 | AE29: 5200 | AF29: Default | AG29: General | AH29: US | AI29: en_US | AJ29: USD | AL29: Y | AO29: BrendaBixler | AP29: LaPlante | AQ29: 211736 | AR29: TRUE
A30: KSX | B30: Brenda | C30: J | D30: Daniel | H30: KSY202533 | J30: brendajdaniel@gmail.com | K30: Rep, Customer Service I | L30: 46160 | M30: 46181 | O30: Terminated | P30: 213236 | Q30: Biweekly | R30: Full Time | S30: 088 | T30: 088-AS Raymond | U30: Inside Sales | V30: 008100 | W30: AS Raymond | Z30: USA | AA30: S08 | AB30: FMG-S08 | AC30: 202533 | AD30: 0088 | AE30: 8100 | AF30: Default | AG30: General | AH30: US | AI30: en_US | AJ30: USD | AL30: N | AM30: 20260608 | AN30: Fix and Include Record | AO30: BrendaJDaniel | AP30: #VALUE! | AQ30: No Reports to Name | AR30: FALSE
A31: KSW | B31: Brennen | C31: G | D31: Valley | G31: Steen, Michael | H31: V0U211062 | I31: bvalley@onebarnes.com | K31: Machinist, CNC | L31: 44361 | O31: Active | P31: 206287 | Q31: Biweekly | R31: Part Time | S31: 025 | T31: 025-NGP Hyson Products | U31: CNC Lathe Hyson | V31: 000100 | W31: Hyson Products | Z31: USA | AA31: H04 | AB31: FMG-H04 | AC31: 211062 | AD31: 0096 | AE31: 100 | AF31: Default | AG31: General | AH31: US | AI31: en_US | AJ31: USD | AL31: Y | AO31: BrennenGValley | AP31: Steen | AQ31: 211062 | AR31: TRUE
A32: KSY | B32: Brittany | C32: M | D32: Velner | I32: bvelner@onebarnes.com | K32: Lead, Cust Serv | L32: 45951 | M32: 46136 | O32: Terminated | P32: 212687 | Q32: Monthly | R32: Full Time | S32: 088 | T32: 088-AS Raymond | U32: Inside Sales | V32: 008100 | W32: AS Raymond | Z32: USA | AA32: S12 | AB32: FMG-S12 | AD32: 0088 | AE32: 8100 | AF32: Default | AG32: General | AH32: US | AI32: en_US | AJ32: USD | AL32: N | AM32: 20260424 | AN32: Fix and Include Record | AO32: BrittanyMVelner | AP32: #VALUE! | AQ32: No Reports to Name | AR32: FALSE
A33: KSX | B33: Candi | C33: M | D33: Morales | G33: Alexander, Thomas | H33: KSY210892 | I33: cburris@onebarnes.com | J33: cmorales6132015@gmail.com | K33: Admin, Document Control | L33: 35947 | O33: Active | P33: 007630 | Q33: Biweekly | R33: Full Time | S33: 088 | T33: 088-AS Raymond | U33: Admin-Quality | V33: 009500 | W33: AS Raymond | Z33: USA | AA33: S10 | AB33: FMG-S10 | AC33: 210892 | AD33: 0088 | AE33: 9500 | AF33: Default | AG33: General | AH33: US | AI33: en_US | AJ33: USD | AL33: Y | AO33: CandiMMorales | AP33: Alexander | AQ33: 210892 | AR33: TRUE
A34: KSY | B34: Carla | C34: J | D34: Cunningham | I34: ccunningham@onebarnes.com | J34: springgirl3@sbcglobal.net | L34: 46022 | M34: 46022 | O34: Terminated | P34: 007633 | Q34: Monthly | R34: Full Time | W34: AS Raymond | Z34: USA | AD34: BU Description Not Mapped | AE34: Home Department Code Not Mapped | AF34: Salary Code Not Mapped | AG34: Salary Code Not Mapped | AH34: US | AI34: ADP and BU Language Code Not MappedUS | AJ34: BU Currency Not Mapped | AL34: N | AM34: 20251231 | AN34: Fix and Include Record | AO34: CarlaJCunningham | AP34: #VALUE! | AQ34: No Reports to Name | AR34: FALSE
B35: Carla | C35: J | D35: Cunningham | I35: ccunningham@onebarnes.com | J35: springgirl3@sbcglobal.net | L35: 46022 | M35: 46023 | O35: Terminated | Q35: Weekly | Z35: USA | AD35: BU Description Not Mapped | AE35: Home Department Code Not Mapped | AF35: Salary Code Not Mapped | AG35: Salary Code Not Mapped | AH35: US | AI35: ADP and BU Language Code Not MappedUS | AJ35: BU Currency Not Mapped | AL35: N | AM35: 20260101 | AN35: Exclude record termination over 45 days ago | AO35: CarlaJCunningham | AP35: #VALUE! | AQ35: No Reports to Name | AR35: FALSE
A36: KSY | B36: Carol | D36: Phillips | G36: Rodriguez, Siobhan | H36: V0U207588 | I36: cphillips1@onebarnes.com | J36: cphillips1226@icloud.com | K36: Mgr, Sales | L36: 45909 | O36: Active | P36: 212478 | Q36: Monthly | R36: Full Time | S36: 088 | T36: 088-AS Raymond | U36: Outside Sales | V36: 008200 | W36: Works from home - Ohio | Z36: USA | AA36: S16 | AB36: FMG-S16 | AC36: 207588 | AD36: 0088 | AE36: 8200 | AF36: Default | AG36: General | AH36: US | AI36: en_US | AJ36: USD | AL36: Y | AO36: CarolPhillips | AP36: Rodriguez | AQ36: 212338 | AR36: FALSE
A37: KSY | B37: Carrie | C37: M | D37: Hoffman | G37: Oleksa, Laura | H37: V0U209181 | I37: choffman@onebarnes.com | J37: Carriehoffman89@gmail.com | K37: HR Coordinator | L37: 43101 | O37: Active | P37: 902349 | Q37: Monthly | R37: Full Time | S37: 088 | T37: 088-AS Raymond | U37: HR General | V37: 009200 | W37: AS Raymond | Z37: USA | AA37: S11 | AB37: FMG-S11 | AC37: 209181 | AD37: 0088 | AE37: 9200 | AF37: Default | AG37: General | AH37: US | AI37: en_US | AJ37: USD | AL37: Y | AO37: CarrieMHoffman | AP37: Oleksa | AQ37: 209181 | AR37: TRUE
A38: KSX | B38: Cassandra | C38: G | D38: Richards | G38: LaPlante, Derek | H38: KSY211736 | I38: crichards@onebarnes.com | J38: cassandrarichards13@gmail.com | K38: Assistant, Warehouse II | L38: 45334 | M38: 46262 | O38: Terminated | P38: 210727 | Q38: Biweekly | R38: Full Time | S38: 088 | T38: 088-AS Raymond | U38: FG Warehouse | V38: 005200 | W38: AS Raymond | Z38: USA | AA38: S05 | AB38: FMG-S05 | AC38: 211736 | AD38: 0088 | AE38: 5200 | AF38: Default | AG38: General | AH38: US | AI38: en_US | AJ38: USD | AL38: N | AM38: 20260828 | AN38: Fix and Include Record | AO38: CassandraGRichards | AP38: LaPlante | AQ38: 211736 | AR38: TRUE
A39: V0U | B39: Chad | D39: Phillips | G39: Wilkins, William | H39: V0U901934 | I39: cphillips@onebarnes.com | J39: phillipsx2@verizon.net | K39: Mgr, Sales | L39: 45243 | M39: 46248 | O39: Terminated | P39: 210402 | Q39: Monthly | R39: Full Time | S39: 025 | T39: 025-NGP Hyson Products | U39: Outside Sales | V39: 000820 | W39: Hyson Products | Z39: USA | AA39: S15 | AB39: FMG-S15 | AC39: 901934 | AD39: 0096 | AE39: 820 | AF39: Default | AG39: General | AH39: US | AI39: en_US | AJ39: USD | AL39: N | AM39: 20260814 | AN39: Fix and Include Record | AO39: ChadPhillips | AP39: Wilkins | AQ39: 901934 | AR39: TRUE
A40: KSW | B40: Charles | D40: McDavid | H40: V0U211062 | J40: chuckmcdavid1999@icloud.com | K40: Lathe Operator | L40: 46202 | O40: Active | P40: 213332 | Q40: Biweekly | R40: Full Time | S40: 025 | T40: 025-NGP Hyson Products | U40: CNC Lathe Hyson | V40: 000100 | W40: Hyson Products | Z40: USA | AA40: H07 | AB40: FMG-H07 | AC40: 211062 | AD40: 0096 | AE40: 100 | AF40: Default | AG40: General | AH40: US | AI40: en_US | AJ40: USD | AL40: Y | AO40: CharlesMcDavid | AP40: #VALUE! | AQ40: No Reports to Name | AR40: FALSE
A41: KSW | B41: Cherie | D41: Hassey | G41: Wallace, Derron | H41: V0U211998 | I41: chassey@onebarnes.com | J41: c.hassey@att.net | K41: Rep, Customer Service II | L41: 46125 | O41: Active | P41: 213144 | Q41: Biweekly | R41: Full Time | S41: 025 | T41: 025-NGP Hyson Products | U41: Inside Sales | V41: 000850 | W41: Hyson Products | Z41: USA | AA41: S10 | AB41: FMG-S10 | AC41: 211998 | AD41: 0096 | AE41: 850 | AF41: Default | AG41: General | AH41: US | AI41: en_US | AJ41: USD | AL41: Y | AO41: CherieHassey | AP41: Wallace | AQ41: 211998 | AR41: TRUE
...

Sheet Status Map
A1: Position Status | B1: Concur Status
A2: Active | B2: Y
A3: Terminated | B3: N
A4: Retired | B4: N
A5: Leave | B5: Y
A6: Leave of absence | B6: N

Sheet Country Map
A1: Legal / Preferred Address: Country Code | B1: ADP Country | C1: Country | D1: Currency Code | E1: Currency
A2: USA | B2: US | C2: United States | D2: USD | E2: US Dollar
A3: CHN | B3: CN | C3: China | D3: CNY | E3: Chinese Yuan (Renminbi)
A4: DEU | B4: DE | C4: Germany | D4: EUR | E4: Euro
A5: ESP | B5: ES | C5: Spail | D5: EUR | E5: Euro
A6: FRA | B6: FR | C6: France | D6: EUR | E6: Euro
A7: GBR | B7: GB | C7: United Kingdom | D7: GBP | E7: Pound Sterling
A8: IND | B8: IN | C8: India | D8: INR | E8: Indian Rupee
A9: KOR | B9: KR | C9: South Korea | D9: KRW | E9: South Korean Won
A10: MEX | B10: MX | C10: Mexico | D10: MXN | E10: Mexican Peso
A11: SWE | B11: SE | C11: Sweden | D11: SEK | E11: Swedish Krona
A12: SGP | B12: SG | C12: Singapore | D12: SGD | E12: Singapore Dollar
A13: JPN | B13: JP | C13: Japan | D13: JPY | E13: Japanese Yen

Sheet Org Map
A1: Business Unit Description | B1: Home Department Description | C1: Home Department Code | D1: Concur Org 1 (and others) | E1: Concur / ERP Code Org 2 | F1: Default Org Language | G1: Reimbursement Currency
A2: 025-NGP Hyson Products | B2: CNC Lathe Hyson | C2: 000100 | D2: 0096 | E2: 100 | F2: en_ | G2: USD
A3: 025-NGP Hyson Products | B3: Assembly Hyson | C3: 000200 | D3: 0096 | E3: 200 | F3: en_ | G3: USD
A4: 025-NGP Hyson Products | B4: Edgework- Hyson | C4: 000350 | D4: 0096 | E4: 350 | F4: en_ | G4: USD
A5: 025-NGP Hyson Products | B5: Indirect General -Hyson | C5: 000400 | D5: 0096 | E5: 400 | F5: en_ | G5: USD
A6: 025-NGP Hyson Products | B6: Maintenance-Hyson | C6: 000450 | D6: 0096 | E6: 450 | F6: en_ | G6: USD
A7: 025-NGP Hyson Products | B7: Quality | C7: 000500 | D7: 0096 | E7: 500 | F7: en_ | G7: USD
A8: 025-NGP Hyson Products | B8: Factory Super-Hyson | C8: 000515 | D8: 0096 | E8: 515 | F8: en_ | G8: USD
A9: 025-NGP Hyson Products | B9: Warehouse | C9: 000555 | D9: 0096 | E9: 555 | F9: en_ | G9: USD
A10: 025-NGP Hyson Products | B10: R&D | C10: 000713 | D10: 0096 | E10: 713 | F10: en_ | G10: USD
A11: 025-NGP Hyson Products | B11: Engineering | C11: 000718 | D11: 0096 | E11: 718 | F11: en_ | G11: USD
A12: 025-NGP Hyson Products | B12: Project Management | C12: 000801 | D12: 0096 | E12: 801 | F12: en_ | G12: USD
A13: 025-NGP Hyson Products | B13: Outside Sales | C13: 000820 | D13: 0096 | E13: 820 | F13: en_ | G13: USD
... A19: 088-AS Raymond | B19: Admin-Quality | C19: 009500 | D19: 0088 | E19: 9500 | F19: en_ | G19: USD
A20: 088-AS Raymond | B20: Customer Service | C20: 000002 | D20: 0088 | E20: 0002 | F20: en_ | G20: USD | H20: Move to inside sales
A21: 088-AS Raymond | B21: Supply Chain | C21: 000004 | D21: 0088 | E21: 0004 | F21: en_ | G21: USD | H21: Move to material management
A22: 088-AS Raymond | B22: Operations 5200 5200 | C22: 000007 | D22: 0088 | E22: 0007 | F22: en_ | G22: USD | H22: Move to FG Warehouse
A23: 088-AS Raymond | B23: Assembly | C23: 005100 | D23: 0088 | E23: 5100 | F23: en_ | G23: USD
A24: 088-AS Raymond | B24: FG Warehouse | C24: 005200 | D24: 0088 | E24: 5200 | F24: en_ | G24: USD
A25: 088-AS Raymond | B25: WH Material Management | C25: 005300 | D25: 0088 | E25: 5300 | F25: en_ | G25: USD
A26: 088-AS Raymond | B26: Inside Sales | C26: 008100 | D26: 0088 | E26: 8100 | F26: en_ | G26: USD
A27: 088-AS Raymond | B27: Outside Sales | C27: 008200 | D27: 0088 | E27: 8200 | F27: en_ | G27: USD
A28: 088-AS Raymond | B28: Marketing | C28: 008300 | D28: 0088 | E28: 8300 | F28: en_ | G28: USD
A29: 088-AS Raymond | B29: Finance General | C29: 009100 | D29: 0088 | E29: 9100 | F29: en_ | G29: USD
A30: 088-AS Raymond | B30: Business Applications | C30: 009150 | D30: 0088 | E30: 9150 | F30: en_ | G30: USD
A31: 088-AS Raymond | B31: HR General | C31: 009200 | D31: 0088 | E31: 9200 | F31: en_ | G31: USD
A32: 088-AS Raymond | B32: HR CU | C32: 009210 | D32: 0088 | E32: 9210 | F32: en_ | G32: USD
A33: 088-AS Raymond | B33: Bus Execs CU | C33: 009310 | D33: 0088 | E33: 9310 | F33: en_ | G33: USD
A34: 088-AS Raymond | B34: Admin-Material Management | C34: 009400 | D34: 0088 | E34: 9400 | F34: en_ | G34: USD
... A36: 088-AS Raymond | B36: Admin-Quality | C36: 009500 | D36: 0088 | E36: 9500 | F36: en_ | G36: USD

Sheet Language Map
A1: Language | B1: Language Code | C1: ADP Language
A2: English | B2: 4 | C2: en_ | M2: =RIGHT(O2,2) -> AU | N2: English (Australia) | O2: en_AU | R2: =LEFT(N2,FIND(" ",N2)-1) -> English | S2: =LEFT(O2,3) -> en_
A3: Tamil | B3: 24 | C3: en_ | M3: =RIGHT(O3,2) -> CA | N3: English (Canada) | O3: en_CA | R3: =LEFT(N3,FIND(" ",N3)-1) -> English | S3: =LEFT(O3,3) -> en_
A4: English | C4: en_ | M4: =RIGHT(O4,2) -> IE | N4: English (Ireland) | O4: en_IE | R4: =LEFT(N4,FIND(" ",N4)-1) -> English | S4: =LEFT(O4,3) -> en_
A5: Bulgarian | C5: bg_ | M5: =RIGHT(O5,2) -> IN | N5: English (India) | O5: en_IN | R5: =LEFT(N5,FIND(" ",N5)-1) -> English | S5: =LEFT(O5,3) -> en_
A6: Chinese | C6: zh_ | M6: =RIGHT(O6,2) -> NZ | N6: English (New Zealand) | O6: en_NZ | R6: =LEFT(N6,FIND(" ",N6)-1) -> English | S6: =LEFT(O6,3) -> en_
A7: Croatian | C7: hr_ | M7: =RIGHT(O7,2) -> US | N7: English (United States) | O7: en_US | R7: =LEFT(N7,FIND(" ",N7)-1) -> English | S7: =LEFT(O7,3) -> en_
A8: Czech | C8: cs_ | M8: =RIGHT(O8,2) -> ZA | N8: English (South Africa) | O8: en_ZA | R8: =LEFT(N8,FIND(" ",N8)-1) -> English | S8: =LEFT(O8,3) -> en_
A9: Danish | C9: da_ | M9: =RIGHT(O9,2) -> BG | N9: Bulgarian (Bulgaria) | O9: bg_BG | R9: =LEFT(N9,FIND(" ",N9)-1) -> Bulgarian | S9: =LEFT(O9,3) -> bg_
A10: Dutch | C10: nl_ | M10: =RIGHT(O10,2) -> CN | N10: Chinese (China) | O10: zh_CN | R10: =LEFT(N10,FIND(" ",N10)-1) -> Chinese | S10: =LEFT(O10,3) -> zh_
A11: Finnish | C11: fi_ | M11: =RIGHT(O11,2) -> HK | N11: Chinese (Hong Kong, China) | O11: zh_HK | R11: =LEFT(N11,FIND(" ",N11)-1) -> Chinese | S11: =LEFT(O11,3) -> zh_
A12: French | C12: fr_ | M12: =RIGHT(O12,2) -> TW | N12: Chinese (Taiwan, China) | O12: zh_TW | R12: =LEFT(N12,FIND(" ",N12)-1) -> Chinese | S12: =LEFT(O12,3) -> zh_
A13: German | C13: de_ | M13: =RIGHT(O13,2) -> HR | N13: Croatian (Croatia) | O13: hr_HR | R13: =LEFT(N13,FIND(" ",N13)-1) -> Croatian | S13: =LEFT(O13,3) -> hr_
A14: Greek | C14: el_ | M14: =RIGHT(O14,2) -> CZ | N14: Czech (Czech Republic) | O14: cs_CZ | R14: =LEFT(N14,FIND(" ",N14)-1) -> Czech | S14: =LEFT(O14,3) -> cs_
A15: Hungarian | C15: hu_ | M15: =RIGHT(O15,2) -> DK | N15: Danish (Denmark) | O15: da_DK | R15: =LEFT(N15,FIND(" ",N15)-1) -> Danish | S15: =LEFT(O15,3) -> da_
... A33: Vietnamese | C33: vi_ | M33: =RIGHT(O33,2) -> DE | N33: German (Germany) | O33: de_DE | R33: =LEFT(N33,FIND(" ",N33)-1) -> German | S33: =LEFT(O33,3) -> de_
M34: =RIGHT(O34,2) -> LU | N34: German (Luxembourg) | O34: de_LU | R34: =LEFT(N34,FIND(" ",N34)-1) -> German | S34: =LEFT(O34,3) -> de_
M35: =RIGHT(O35,2) -> CH | N35: German (Switzerland) | O35: de_CH | R35: =LEFT(N35,FIND(" ",N35)-1) -> German | S35: =LEFT(O35,3) -> de_
M36: =RIGHT(O36,2) -> GR | N36: Greek (Greece) | O36: el_GR | R36: =LEFT(N36,FIND(" ",N36)-1) -> Greek | S36: =LEFT(O36,3) -> el_
M37: =RIGHT(O37,2) -> HU | N37: Hungarian (Hungary) | O37: hu_HU | R37: =LEFT(N37,FIND(" ",N37)-1) -> Hungarian | S37: =LEFT(O37,3) -> hu_
M38: =RIGHT(O38,2) -> ID | N38: Indonesian (Indonesia) | O38: id_ID | R38: =LEFT(N38,FIND(" ",N38)-1) -> Indonesian | S38: =LEFT(O38,3) -> id_
M39: =RIGHT(O39,2) -> IT | N39: Italian (Italy) | O39: it_IT | R39: =LEFT(N39,FIND(" ",N39)-1) -> Italian | S39: =LEFT(O39,3) -> it_
M40: =RIGHT(O40,2) -> CH | N40: Italian (Switzerland) | O40: it_CH | R40: =LEFT(N40,FIND(" ",N40)-1) -> Italian | S40: =LEFT(O40,3) -> it_
M41: =RIGHT(O41,2) -> JP | N41: Japanese (Japan) | O41: ja_JP | R41: =LEFT(N41,FIND(" ",N41)-1) -> Japanese | S41: =LEFT(O41,3) -> ja_
M42: =RIGHT(O42,2) -> KP | N42: Korean (North Korea) | O42: ko_KP | R42: =LEFT(N42,FIND(" ",N42)-1) -> Korean | S42: =LEFT(O42,3) -> ko_
M43: =RIGHT(O43,2) -> KR | N43: Korean (South Korea) | O43: ko_KR | R43: =LEFT(N43,FIND(" ",N43)-1) -> Korean | S43: =LEFT(O43,3) -> ko_
M44: =RIGHT(O44,2) -> MY | N44: Malay (Malaysia) | O44: ms_MY | R44: =LEFT(N44,FIND(" ",N44)-1) -> Malay | S44: =LEFT(O44,3) -> ms_
M45: =RIGHT(O45,2) -> NO | N45: Norwegian (Norway) | O45: no_NO | R45: =LEFT(N45,FIND(" ",N45)-1) -> Norwegian | S45: =LEFT(O45,3) -> no_
... M75: =RIGHT(O75,2) -> VN | N75: Vietnamese (Vietnam) | O75: vi_VN | R75: =LEFT(N75,FIND(" ",N75)-1) -> Vietnamese | S75: =LEFT(O75,3) -> vi_

Sheet Salary Map
A1: Pay Grade Code | B1: Pay Grade Description | C1: Expense Map | D1: Travel Map | E1: Invoice Approval
A2: S24 | B2: FMG-S24 | C2: Officers | D2: VIP
A3: S23 | B3: FMG-S23 | C3: Grade 20 | D3: Senior Leadership
A4: S22 | B4: FMG-S22 | C4: Grade 20 | D4: Senior Leadership | E4: 1e+09 | G4: Per conversation/decision Tunde, Dwight, Amy Sept 9, 2026
A5: S21 | B5: FMG-S21 | C5: Grade 20 | D5: Senior Leadership | E5: 1000000 | G5: Per conversation/decision Tunde, Dwight, Amy Sept 9, 2026
A6: S20 | B6: FMG-S20 | C6: Grade 20 | D6: Senior Leadership | E6: 100000
A7: S19 | B7: FMG-S19 | C7: Default | D7: General | E7: 100000
A8: S18 | B8: FMG-S18 | C8: Default | D8: General | E8: 25000
A9: S17 | B9: FMG-S17 | C9: Default | D9: General | E9: 25000
A10: S16 | B10: FMG-S16 | C10: Default | D10: General | E10: 25000
A11: S15 | B11: FMG-S15 | C11: Default | D11: General | E11: 0
A12: S14 | B12: FMG-S14 | C12: Default | D12: General | E12: 0
A13: S13 | B13: FMG-S13 | C13: Default | D13: General | E13: 0
A14: S12 | B14: FMG-S12 | C14: Default | D14: General | E14: 0
A15: S11 | B15: FMG-S11 | C15: Default | D15: General | E15: 0
A16: S10 | B16: FMG-S10 | C16: Default | D16: General | E16: 0
A17: S09 | B17: FMG-S09 | C17: Default | D17: General | E17: 0
... A37: H0000 | B37: FMG-H0000 | C37: Default | D37: General | E37: 0

Sheet Role Assignment Map
A1: Role | B1: Category | C1: Assign Role Automatically
A2: Card Program Administrator | B2: Admin | C2: N
A3: Cognos Business Author | B3: Admin | C3: N
A4: Employee Administrator | B4: Admin | C4: N
A5: Invoice Configuration Administrator (Restricted) | B5: Admin | C5: N
A6: Invoice Proxy Logon | B6: Admin | C6: N
A7: Reimbursement Manager | B7: Admin | C7: N
A8: Role Administrator | B8: Admin | C8: N
A9: Expense User | B9: Expense | C9: Y
A10: Expense Processor | B10: Expense | C10: Y
A11: Expense Processor (Audit) | B11: Expense | C11: Y
A12: Expense Proxy Logon | B12: Expense | C12: Y
... A22: Purchase Request Processor (Audit) | B22: Payables | C22: N

Sheet Invoice Exception Map
A1: Invoice Exception Employee Id | B1: Invoice Exception Employee Name | C1: Invoice Access Value
A2: 007861 | B2: Amy McGuire | C2: Y
A3: 203011 | B3: Babatunde Adewalure | C3: Y
A4: 902437 | B4: Bradley Masters | C4: N
A5: 007630 | B5: Candi Morals | C5: Y
A6: 212478 | B6: Carol Phillips | C6: N
A7: 213331 | B7: Gregory Adams | C7: N
A8: 203036 | B8: Jean-Philippe Duvillard | C8: Y
A9: 210018 | B9: Jeff Raese | C9: N | H9: 901934 | J9: Y | K9: S17 reports to him
A10: 212146 | B10: Joyce Spilza | C10: Y
A11: 209579 | B11: Kirsten Barry | C11: N
A12: 902013 | B12: Kugagini Thineshkumar | C12: Y
A13: 207199 | B13: Mehmet Erdogan | C13: Y
A14: 213333 | B14: Michael Beasley | C14: N | H14: 901934 | I14: William Wilkins | J14: N
A15: 212418 | B15: Michael Jones | C15: N
A16: 901943 | B16: Richard Taiclet | C16: Y
A17: 213174 | B17: Robert Schortz | C17: Y
A18: 201688 | B18: Kim Ashley | C18: Y
A19: 210102 | B19: Nathan Bird | C19: N
A20: 212705 | B20: Bonnetta Warren | C20: Y
A21: 213174 | B21: Robert Schortz | C21: Y

Sheet UKG Company Map
A1: Site Location | B1: Site Location Code | C1: Concur Org Unit | D1: Concur Company Code Description | E1: Expense Group Code | F1: Ledger Code | G1: Custom 5 Code | K1: Division | L1: Description | R1: Expense Group ID | S1: Description
A2: ASI Raymond China | B2: 0083 | C2: 0083 | D2: Raymond China | E2: 0083 | F2: 0083 | G2: 0083 | K2: 0041 | L2: (0041) Singapore MRO | R2: ISG | S2: (00) ISG
A3: NGP China | B3: 0079 | C3: 0079 | D3: NP China | E3: 0079 | F3: 0079 | G3: 0079 | K3: 0096 | L3: (0096) NGP Brecksville | R3: 0035 | S3: (0035) Raymond UK
A4: Barnes Acquisition Group | B4: 0400 | C4: 0400 | E4: 0400 | F4: 0400 | G4: 0400 | K4: 0146 | L4: (0146) Singapore OEM Division | R4: 0041 | S4: (0041) Singapore MRO
A5: ASI Raymond France | B5: 127 | C5: 0055 | D5: Raymond France | E5: 0055 | F5: 0055 | G5: 0055 | K5: 0147 | L5: (0147) Malaysia OEM | R5: 0055 | S5: (0055) Raymond France
A6: ASI Raymond UK | B6: 0035 | C6: 0035 | D6: Raymond - UK | E6: 0035 | F6: 0035 | G6: 0035 | K6: 0148 | L6: (0148) East Granby (MB) | R6: 0057 | S6: (0057) Raymond Singapore
A7: NGP IGS UK | B7: 0218 | C7: 0218 | D7: Industrial Gas Springs Ltd (UK) | E7: 0218 | F7: 0218 | G7: 0218 | K7: 0149 | L7: (0149) Warren (MB) | R7: 0075 | S7: (0075) NGP Mexico
A8: NGP United Kingdom | B8: 0219 | C8: 0114 | D8: Industrial Gas Springs Ltd (UK) | E8: 0114 | F8: 0114 | G8: 0114 | K8: 0150 | L8: (0150) Rzeszow | R8: 0077 | S8: (0077) Stromsholmen
A9: NGP India | B9: 176 | C9: 26 | D9: NP India | E9: 26 | F9: 26 | G9: 0026 | K9: 0151 | L9: (0151) Technologies | R9: 0079 | S9: (0079) NP China
A10: MAI Maenner Japan | B10: 406 | C10: 0406 | D10: Männer Japan | E10: 0406 | F10: 0406 | G10: 0406 | K10: 0155 | L10: (0155) Taoyuan (MB) | R10: 0083 | S10: (0083) Raymond China
A11: SMS Japan | B11: 0463 | C11: 0463 | D11: SMS Japan | E11: 0463 | F11: 0463 | G11: 0463 | K11: 0177 | L11: (0177) East Hartford | R11: 0084 | S11: (0084) Raymond Mexico
A12: NGP Korea | B12: 179 | C12: 34 | D12: NP Korea | E12: 34 | F12: 34 | G12: 0034 | K12: 0443 | L12: (0443) SMS BV (Holland) | R12: 0094 | S12: (0094) Raymond Spain
A13: Raymond Distribution – MX | B13: 0084 | C13: 0084 | D13: Raymond Mexico | E13: 0084 | F13: 0084 | G13: 0084 | K13: 06 | L13: (06) Aerospace Headquarters | R13: 0096 | S13: (0096) NGP Brecksville
A14: MX Nitrogen Division | B14: 0075 | C14: 0075 | D14: NGP Mexico | E14: 0075 | F14: 0075 | G14: 0075 | K14: 30 | L14: AS Asia | R14: 0097 | S14: (0097) Raymond Germany
A15: NGP Sweden | B15: 0077 | C15: 0077 | D15: Stromsholmen | E15: 0077 | F15: 0077 | G15: 0077 | K15: 0048 | L15: AS Brazil | R15: 0114 | S15: (0114) NGP UK
A16: NGP Sweden | B16: 177 | C16: 0077 | D16: Stromsholmen | E16: 0077 | F16: 0077 | G16: 0077 | K16: 36 | L16: AS Mexico | R16: 0143 | S16: (0143) Newton Abbot
A17: ASI Raymond Singapore | B17: 0057 | C17: 0057 | D17: Raymond Singapore | E17: 0057 | F17: 0057 | G17: 0057 | K17: 0173 | L17: AS Thailand | R17: 0146 | S17: (0146) Singapore OEM Division
K18: 33 | L18: AS Trading Brazil | R18: 0148 | S18: (0148) East Granby (MB)
A19: List Management (Invoice): | F19: Requires Concur | K19: 0418 | L19: Automation HQ | R19: 0150 | S19: (0150) Rzeszow
A20: List Management (Expense): | C20: *Division - Department | E20: *Expense Group ID | G20: *UKG Site Locations (Employee) | K20: 169 | L20: Barnes Aerospace - UK | R20: 0151 | S20: (0151) Technologies
K21: Barnes Group - Do Not Use | L21: Barnes Group - Do Not Use | R21: 0153 | S21: (0153) Motherwell
A22: KBD: | K22: 00 | L22: Barnes Group Corporate Office | R22: 0155 | S22: (0155) Taoyuan (MB Taiwan)
K23: 0400 | L23: BG Germany Acq GmbH | R23: 0169 | S23: (0169) European Sales Force
K24: 0470 | L24: BMS Korea | R24: 0170 | S24: (0170) Holdings (MB)
K25: 0175 | L25: Burnley (MB) | R25: 0173 | S25: (0173) AS Thailand
K26: 0169 | L26: European Sales Force | R26: 0175 | S26: (0175) Burnley
K27: 0502 | L27: FOBOHA China | R27: 0177 | S27: (0177) East Hartford
K28: 0501 | L28: FOBOHA Germany | R28: 0218 | S28: (0218) Industrial Gas Springs Ltd (UK)
K29: 0426 | L29: Gammaflux Germany | R29: 0400 | S29: (0400) BG Germany Acq GmbH
K30: GhostCard | L30: Ghost Card | R30: 0401 | S30: (0401) Manner Germany
K31: 0602 | L31: Gimatic S. r. l. | R31: 0404 | S31: (0404) Manner US
K32: GuestTravel | L32: Guest Traveler | R32: 0406 | S32: (0406) Männer Japan
K33: 0196 | L33: Heinz Hänggi | R33: 0420 | S33: (0420) Priamus Switzerland
K34: 0170 | L34: Holdings (MB) | R34: 0421 | S34: (0421) Priamus Germany
... K123: 225 | L123: zSynventive Thailand | R123: 602 | S123: z602
R124: 0612 | S124: zGimatic Balkan d.o.o. Beograd – Savski Venac
R125: 0407 | S125: zMänner Hong Kong

Sheet KN EP Brute Force
A1: Company Code | B1: Name | C1: Department Added
A2: 0035 | B2: Raymond UK | C2: 140102 | H2: 212047 | I2: 901934 | J2: Will Wilking
H3: 210703 | J3: Sebastian Lobner | K3: Made Leave of Absense
A4: 0035 | B4: Raymond UK | C4: 910 | H4: Svetlana | J4: Dwight
A7: 0077 | B7: Stroms | C7: 720000 | D7: Robert S. Bad data in UKG?
A8: 0084 | B8: Raymond Mexico | C8: 800
A9: 26 | B9: NGP India | C9: 0900 | D9: But 900 existed
A10: 0406 | B10: Japan | C10: 0000 | D10: Concur had 3 zeros
H12: Emails changed for ssncharacters
H16: Robert (CFO) Department
H22: Hedborg, Josefine <jhedborg@onebarnes.com>
H24: Not in UKG

Sheet ADP
A1: Employment Profile - Effective Date | B1: Effective as of 08/31/2026 | H1: Non US Temp Employee | I1: Missing work email address | R1: Filter to employee types | T1: Map and Filter | V1: Map based on ERP length | X1: Will be filled in | Y1: Will be filled in | AC1: Fix Supervisor ID | AD1: Assign an Org correctly | AE1: Fix to valid GL Company codes | AF1: Assign Salary Code | AG1: Assign Salary Code | AO1: 88 & 25/92 with $more than 0 | AR1: Where false validate the actual supervisor id is correct
A2: Employment Profile - Time & Attendance - Effective Date | B2: All records independent of date | H2: Missing Supervisor | AO2: Exception List
A3: Employment Profile - Pay Rates - Effective Date | B3: All records independent of date | H3: Top of food chain
A4: Payroll Company Code | B4: Legal First Name | C4: Middle Initial | D4: Legal Last Name | E4: Preferred or Chosen First Name | F4: Preferred or Chosen Last Name | G4: Reports To Legal Name | H4: Supervisor ID | I4: Work Contact: Work Email | J4: Personal Contact: Personal Email | K4: Job Title Description | L4: Hire Date | M4: Termination Date | N4: Rehire Date | O4: Position Status | P4: File Number | Q4: Pay Frequency | R4: Employee Type | S4: Business Unit Code | T4: Business Unit Description | U4: Home Department Description | V4: Home Department Code | W4: Location Description | X4: Language Description | Y4: Language Code | Z4: Legal / Preferred Address: Country Code | AA4: Pay Grade Code | AB4: Pay Grade Description | AC4: Supervisor Id | AD4: Org Unit 1 | AE4: Org Unit 2 | AF4: Concur Profile | AG4: Travel Profile | AH4: Invoice | AI4: Legal Country | AJ4: Local Code | AK4: Reumbursement Currency | AL4: Perferred Name | AM4: Status | AN4: TermDate | AO4: InvoiceAccess
A5: KSX | B5: Tammie | D5: Abitua | G5: Burchell, Mathew | H5: KSY211756 | I5: tabitua1@onebarnes.com | J5: abituatammie@gmail.com | K5: Assistant, Warehouse II | L5: 45733 | O5: Active | P5: 211837 | Q5: Biweekly | R5: Full Time | S5: 088 | T5: 088-AS Raymond | U5: Assembly | V5: 005100 | W5: AS Raymond | Z5: USA | AA5: S05 | AB5: FMG-S05 | AC5: =MID(H5,4,6) -> 211756 | AD5: =IFERROR(VLOOKUP(T5,'Org Map'!A:E,4),"BU Description Not Mapped") -> 0088 | AE5: =IFERROR(VLOOKUP(V5,'Org Map'!C:E,3,FALSE),"Home Department Code Not Mapped") -> 5100 | AF5: =IFERROR(VLOOKUP(AA5,'Salary Map'!A:D,3,FALSE),"Salary Code Not Mapped") -> Default | AG5: =IFERROR(VLOOKUP(AA5,'Salary Map'!A:D,4,FALSE),"Salary Code Not Mapped") -> General | AH5: =IFERROR(VLOOKUP(AA5,'Salary Map'!A:E,5,FALSE),"Invoice Approval Not Mapped") -> 0 | AI5: =IFERROR(VLOOKUP(Z5,'Country Map'!A:B,2,FALSE),"Legal Country Not Mapped") -> US | AJ5: =IFERROR(VLOOKUP(X5,'Language Map'!A:C,3,FALSE),IFERROR(VLOOKUP(T5,'Org Map'!A:F,6,FALSE),"ADP and BU Language Code Not Mapped"))&AI5 -> en_US | AK5: =IFERROR(VLOOKUP(T5,'Org Map'!A:G,7),"BU Currency Not Mapped") -> USD | AL5: =IF(ISBLANK(E5),"",TRIM(E5&" "&F5)) | AM5: =IFERROR(VLOOKUP(O5,'Status Map'!A:B,2,FALSE),"Position Status Not Mapped") -> Y | AN5: =IF(AM5="N",TEXT(M5,"yyyymmdd"),"") | AO5: =IFERROR(VLOOKUP(P5,'Invoice Exception Map'!A:C,3,FALSE),IF(AH5>0,"Y","N")) -> N
A6: KSY | B6: Gregory | C6: S | D6: Adams | G6: Rodriguez, Siobhan | H6: V0U207588 | I6: gadams@onebarnes.com | J6: gdsad.adams@cox.net | K6: Mgr, Sales | L6: 46188 | O6: Active | P6: 213331 | Q6: Monthly | R6: Full Time | S6: 088 | T6: 088-AS Raymond | U6: Outside Sales | V6: 008200 | W6: Work from home - Connecticut | Z6: USA | AA6: S16 | AB6: FMG-S16 | AC6: =IF(ISBLANK(H6),VLOOKUP(P6,'Invoice Exception Map'!A:D,4,FALSE),MID(H6,4,6)) -> 207588 | AD6: =IFERROR(VLOOKUP(T6,'Org Map'!A:E,4),"BU Description Not Mapped") -> 0088 | AE6: =IFERROR(VLOOKUP(V6,'Org Map'!C:E,3,FALSE),"Home Department Code Not Mapped") -> 8200 | AF6: =IFERROR(VLOOKUP(AA6,'Salary Map'!A:D,3,FALSE),"Salary Code Not Mapped") -> Default | AG6: =IFERROR(VLOOKUP(AA6,'Salary Map'!A:D,4,FALSE),"Salary Code Not Mapped") -> General | AH6: =IFERROR(VLOOKUP(AA6,'Salary Map'!A:E,5,FALSE),"Invoice Approval Not Mapped") -> 25000 | AI6: =IFERROR(VLOOKUP(Z6,'Country Map'!A:B,2,FALSE),"Legal Country Not Mapped") -> US | AJ6: =IFERROR(VLOOKUP(X6,'Language Map'!A:C,3,FALSE),IFERROR(VLOOKUP(T6,'Org Map'!A:F,6,FALSE),"ADP and BU Language Code Not Mapped"))&AI6 -> en_US | AK6: =IFERROR(VLOOKUP(T6,'Org Map'!A:G,7),"BU Currency Not Mapped") -> USD | AL6: =IF(ISBLANK(E6),"",TRIM(E6&" "&F6)) | AM6: =IFERROR(VLOOKUP(O6,'Status Map'!A:B,2,FALSE),"Position Status Not Mapped") -> Y | AN6: =IF(AM6="N",TEXT(M6,"yyyymmdd"),"") | AO6: =IFERROR(VLOOKUP(P6,'Invoice Exception Map'!A:C,3,FALSE),IF(AH6>0,"Y","N")) -> N
A7: KSY | B7: Krystle | D7: Agler | G7: Kemenah, Greg | H7: KSY211766 | I7: kagler@onebarnes.com | J7: krystle.agler@gmail.com | K7: Mgr, Marketing II | L7: 46160 | O7: Active | P7: 213226 | Q7: Monthly | R7: Full Time | S7: 088 | T7: 088-AS Raymond | U7: Marketing | V7: 008300 | W7: AS Raymond | Z7: USA | AA7: S16 | AB7: FMG-S16 | AC7: =IF(ISBLANK(H7),VLOOKUP(P7,'Invoice Exception Map'!A:D,4,FALSE),MID(H7,4,6)) -> 211766 | AD7: =IFERROR(VLOOKUP(T7,'Org Map'!A:E,4),"BU Description Not Mapped") -> 0088 | AE7: =IFERROR(VLOOKUP(V7,'Org Map'!C:E,3,FALSE),"Home Department Code Not Mapped") -> 8300 | AF7: =IFERROR(VLOOKUP(AA7,'Salary Map'!A:D,3,FALSE),"Salary Code Not Mapped") -> Default | AG7: =IFERROR(VLOOKUP(AA7,'Salary Map'!A:D,4,FALSE),"Salary Code Not Mapped") -> General | AH7: =IFERROR(VLOOKUP(AA7,'Salary Map'!A:E,5,FALSE),"Invoice Approval Not Mapped") -> 25000 | AI7: =IFERROR(VLOOKUP(Z7,'Country Map'!A:B,2,FALSE),"Legal Country Not Mapped") -> US | AJ7: =IFERROR(VLOOKUP(X7,'Language Map'!A:C,3,FALSE),IFERROR(VLOOKUP(T7,'Org Map'!A:F,6,FALSE),"ADP and BU Language Code Not Mapped"))&AI7 -> en_US | AK7: =IFERROR(VLOOKUP(T7,'Org Map'!A:G,7),"BU Currency Not Mapped") -> USD | AL7: =IF(ISBLANK(E7),"",TRIM(E7&" "&F7)) | AM7: =IFERROR(VLOOKUP(O7,'Status Map'!A:B,2,FALSE),"Position Status Not Mapped") -> Y | AN7: =IF(AM7="N",TEXT(M7,"yyyymmdd"),"") | AO7: =IFERROR(VLOOKUP(P7,'Invoice Exception Map'!A:C,3,FALSE),IF(AH7>0,"Y","N")) -> Y
A8: KSY | B8: Thomas | C8: E | D8: Alexander | G8: Kemenah, Greg | H8: KSY211766 | I8: talexander@onebarnes.com | J8: tom5683alexander@gmail.com | K8: Mgr, Quality II | L8: 45392 | O8: Active | P8: 210892 | Q8: Monthly | R8: Full Time | S8: 088 | T8: 088-AS Raymond | U8: Admin-Quality | V8: 009500 | W8: AS Raymond | Z8: USA | AA8: S16 | AB8: FMG-S16 | AC8: =IF(ISBLANK(H8),VLOOKUP(P8,'Invoice Exception Map'!A:D,4,FALSE),MID(H8,4,6)) -> 211766 | AD8: =IFERROR(VLOOKUP(T8,'Org Map'!A:E,4),"BU Description Not Mapped") -> 0088 | AE8: =IFERROR(VLOOKUP(V8,'Org Map'!C:E,3,FALSE),"Home Department Code Not Mapped") -> 9500 | AF8: =IFERROR(VLOOKUP(AA8,'Salary Map'!A:D,3,FALSE),"Salary Code Not Mapped") -> Default | AG8: =IFERROR(VLOOKUP(AA8,'Salary Map'!A:D,4,FALSE),"Salary Code Not Mapped") -> General | AH8: =IFERROR(VLOOKUP(AA8,'Salary Map'!A:E,5,FALSE),"Invoice Approval Not Mapped") -> 25000 | AI8: =IFERROR(VLOOKUP(Z8,'Country Map'!A:B,2,FALSE),"Legal Country Not Mapped") -> US | AJ8: =IFERROR(VLOOKUP(X8,'Language Map'!A:C,3,FALSE),IFERROR(VLOOKUP(T8,'Org Map'!A:F,6,FALSE),"ADP and BU Language Code Not Mapped"))&AI8 -> en_US | AK8: =IFERROR(VLOOKUP(T8,'Org Map'!A:G,7),"BU Currency Not Mapped") -> USD | AL8: =IF(ISBLANK(E8),"",TRIM(E8&" "&F8)) | AM8: =IFERROR(VLOOKUP(O8,'Status Map'!A:B,2,FALSE),"Position Status Not Mapped") -> Y | AN8: =IF(AM8="N",TEXT(M8,"yyyymmdd"),"") | AO8: =IFERROR(VLOOKUP(P8,'Invoice Exception Map'!A:C,3,FALSE),IF(AH8>0,"Y","N")) -> Y
A9: KSX | B9: Tina | C9: M | D9: Allen | G9: LaPlante, Derek | H9: KSY211736 | I9: TAllen2@onebarnes.com | J9: tinaallen908@gmail.com | K9: Assistant, Warehouse II | L9: 44550 | O9: Active | P9: 206848 | Q9: Biweekly | R9: Full Time | S9: 088 | T9: 088-AS Raymond | U9: FG Warehouse | V9: 005200 | W9: AS Raymond | Z9: USA | AA9: S05 | AB9: FMG-S05 | AC9: =IF(ISBLANK(H9),VLOOKUP(P9,'Invoice Exception Map'!A:D,4,FALSE),MID(H9,4,6)) -> 211736 | AD9: =IFERROR(VLOOKUP(T9,'Org Map'!A:E,4),"BU Description Not Mapped") -> 0088 | AE9: =IFERROR(VLOOKUP(V9,'Org Map'!C:E,3,FALSE),"Home Department Code Not Mapped") -> 5200 | AF9: =IFERROR(VLOOKUP(AA9,'Salary Map'!A:D,3,FALSE),"Salary Code Not Mapped") -> Default | AG9: =IFERROR(VLOOKUP(AA9,'Salary Map'!A:D,4,FALSE),"Salary Code Not Mapped") -> General | AH9: =IFERROR(VLOOKUP(AA9,'Salary Map'!A:E,5,FALSE),"Invoice Approval Not Mapped") -> 0 | AI9: =IFERROR(VLOOKUP(Z9,'Country Map'!A:B,2,FALSE),"Legal Country Not Mapped") -> US | AJ9: =IFERROR(VLOOKUP(X9,'Language Map'!A:C,3,FALSE),IFERROR(VLOOKUP(T9,'Org Map'!A:F,6,FALSE),"ADP and BU Language Code Not Mapped"))&AI9 -> en_US | AK9: =IFERROR(VLOOKUP(T9,'Org Map'!A:G,7),"BU Currency Not Mapped") -> USD | AL9: =IF(ISBLANK(E9),"",TRIM(E9&" "&F9)) | AM9: =IFERROR(VLOOKUP(O9,'Status Map'!A:B,2,FALSE),"Position Status Not Mapped") -> Y | AN9: =IF(AM9="N",TEXT(M9,"yyyymmdd"),"") | AO9: =IFERROR(VLOOKUP(P9,'Invoice Exception Map'!A:C,3,FALSE),IF(AH9>0,"Y","N")) -> N
A10: KSY | B10: Kimberly | D10: Ashley | G10: Warner, Dwight | H10: V0U008750 | I10: KAshley@onebarnes.com | K10: Accountant III | L10: 43710 | O10: Active | P10: 201688 | Q10: Monthly | R10: Full Time | S10: 088 | T10: 088-AS Raymond | U10: Finance General | V10: 009100 | W10: Work from home - Connecticut | Z10: USA | AA10: S13 | AB10: FMG-S13 | AC10: =IF(ISBLANK(H10),VLOOKUP(P10,'Invoice Exception Map'!A:D,4,FALSE),MID(H10,4,6)) -> 008750 | AD10: =IFERROR(VLOOKUP(T10,'Org Map'!A:E,4),"BU Description Not Mapped") -> 0088 | AE10: =IFERROR(VLOOKUP(V10,'Org Map'!C:E,3,FALSE),"Home Department Code Not Mapped") -> 9100 | AF10: =IFERROR(VLOOKUP(AA10,'Salary Map'!A:D,3,FALSE),"Salary Code Not Mapped") -> Default | AG10: =IFERROR(VLOOKUP(AA10,'Salary Map'!A:D,4,FALSE),"Salary Code Not Mapped") -> General | AH10: =IFERROR(VLOOKUP(AA10,'Salary Map'!A:E,5,FALSE),"Invoice Approval Not Mapped") -> 0 | AI10: =IFERROR(VLOOKUP(Z10,'Country Map'!A:B,2,FALSE),"Legal Country Not Mapped") -> US | AJ10: =IFERROR(VLOOKUP(X10,'Language Map'!A:C,3,FALSE),IFERROR(VLOOKUP(T10,'Org Map'!A:F,6,FALSE),"ADP and BU Language Code Not Mapped"))&AI10 -> en_US | AK10: =IFERROR(VLOOKUP(T10,'Org Map'!A:G,7),"BU Currency Not Mapped") -> USD | AL10: =IF(ISBLANK(E10),"",TRIM(E10&" "&F10)) | AM10: =IFERROR(VLOOKUP(O10,'Status Map'!A:B,2,FALSE),"Position Status Not Mapped") -> Y | AN10: =IF(AM10="N",TEXT(M10,"yyyymmdd"),"") | AO10: =IFERROR(VLOOKUP(P10,'Invoice Exception Map'!A:C,3,FALSE),IF(AH10>0,"Y","N")) -> Y
A11: KSY | B11: Jason | C11: J | D11: Bailey | G11: Kemenah, Greg | H11: KSY211766 | I11: jbailey@onebarnes.com | J11: jjbailey08@gmail.com | K11: Senior Mgr, Operations | L11: 46258 | O11: Active | P11: 902688 | Q11: Monthly | R11: Full Time | S11: 088 | T11: 088-AS Raymond | U11: FG Warehouse | V11: 005200 | W11: AS Raymond | Z11: USA | AA11: S18 | AB11: FMG-S18 | AC11: =IF(ISBLANK(H11),VLOOKUP(P11,'Invoice Exception Map'!A:D,4,FALSE),MID(H11,4,6)) -> 211766 | AD11: =IFERROR(VLOOKUP(T11,'Org Map'!A:E,4),"BU Description Not Mapped") -> 0088 | AE11: =IFERROR(VLOOKUP(V11,'Org Map'!C:E,3,FALSE),"Home Department Code Not Mapped") -> 5200 | AF11: =IFERROR(VLOOKUP(AA11,'Salary Map'!A:D,3,FALSE),"Salary Code Not Mapped") -> Default | AG11: =IFERROR(VLOOKUP(AA11,'Salary Map'!A:D,4,FALSE),"Salary Code Not Mapped") -> General | AH11: =IFERROR(VLOOKUP(AA11,'Salary Map'!A:E,5,FALSE),"Invoice Approval Not Mapped") -> 25000 | AI11: =IFERROR(VLOOKUP(Z11,'Country Map'!A:B,2,FALSE),"Legal Country Not Mapped") -> US | AJ11: =IFERROR(VLOOKUP(X11,'Language Map'!A:C,3,FALSE),IFERROR(VLOOKUP(T11,'Org Map'!A:F,6,FALSE),"ADP and BU Language Code Not Mapped"))&AI11 -> en_US | AK11: =IFERROR(VLOOKUP(T11,'Org Map'!A:G,7),"BU Currency Not Mapped") -> USD | AL11: =IF(ISBLANK(E11),"",TRIM(E11&" "&F11)) | AM11: =IFERROR(VLOOKUP(O11,'Status Map'!A:B,2,FALSE),"Position Status Not Mapped") -> Y | AN11: =IF(AM11="N",TEXT(M11,"yyyymmdd"),"") | AO11: =IFERROR(VLOOKUP(P11,'Invoice Exception Map'!A:C,3,FALSE),IF(AH11>0,"Y","N")) -> Y
A12: KSY | B12: Teresa | D12: Bair | I12: TBair@onebarnes.com | K12: President, SBU II | L12: 44732 | O12: Active | P12: 207709 | Q12: Monthly | R12: Full Time | S12: 088 | T12: 088-AS Raymond | U12: Bus Execs CU | V12: 009310 | W12: AS Raymond | Z12: USA | AA12: S22 | AB12: FMG-S22 | AC12: =IF(ISBLANK(H12),VLOOKUP(P12,'Invoice Exception Map'!A:D,4,FALSE),MID(H12,4,6)) | AD12: =IFERROR(VLOOKUP(T12,'Org Map'!A:E,4),"BU Description Not Mapped") -> 0088 | AE12: =IFERROR(VLOOKUP(V12,'Org Map'!C:E,3,FALSE),"Home Department Code Not Mapped") -> 9310 | AF12: =IFERROR(VLOOKUP(AA12,'Salary Map'!A:D,3,FALSE),"Salary Code Not Mapped") -> Grade 20 | AG12: =IFERROR(VLOOKUP(AA12,'Salary Map'!A:D,4,FALSE),"Salary Code Not Mapped") -> Senior Leadership | AH12: =IFERROR(VLOOKUP(AA12,'Salary Map'!A:E,5,FALSE),"Invoice Approval Not Mapped") -> 1e+09 | AI12: =IFERROR(VLOOKUP(Z12,'Country Map'!A:B,2,FALSE),"Legal Country Not Mapped") -> US | AJ12: =IFERROR(VLOOKUP(X12,'Language Map'!A:C,3,FALSE),IFERROR(VLOOKUP(T12,'Org Map'!A:F,6,FALSE),"ADP and BU Language Code Not Mapped"))&AI12 -> en_US | AK12: =IFERROR(VLOOKUP(T12,'Org Map'!A:G,7),"BU Currency Not Mapped") -> USD | AL12: =IF(ISBLANK(E12),"",TRIM(E12&" "&F12)) | AM12: =IFERROR(VLOOKUP(O12,'Status Map'!A:B,2,FALSE),"Position Status Not Mapped") -> Y | AN12: =IF(AM12="N",TEXT(M12,"yyyymmdd"),"") | AO12: =IFERROR(VLOOKUP(P12,'Invoice Exception Map'!A:C,3,FALSE),IF(AH12>0,"Y","N")) -> Y
A13: V0U | B13: Kirsten | C13: V | D13: Barry | G13: Rodriguez, Siobhan | H13: V0U207588 | I13: kbarry@onebarnes.com | K13: Mgr, Project I | L13: 44949 | O13: Active | P13: 209579 | Q13: Monthly | R13: Full Time | S13: 025 | T13: 025-NGP Hyson Products | U13: Outside Sales | V13: 000820 | W13: Hyson Products | Z13: USA | AA13: S15 | AB13: FMG-S15 | AC13: =IF(ISBLANK(H13),VLOOKUP(P13,'Invoice Exception Map'!A:D,4,FALSE),MID(H13,4,6)) -> 207588 | AD13: =IFERROR(VLOOKUP(T13,'Org Map'!A:E,4),"BU Description Not Mapped") -> 0096 | AE13: =IFERROR(VLOOKUP(V13,'Org Map'!C:E,3,FALSE),"Home Department Code Not Mapped") -> 820 | AF13: =IFERROR(VLOOKUP(AA13,'Salary Map'!A:D,3,FALSE),"Salary Code Not Mapped") -> Default | AG13: =IFERROR(VLOOKUP(AA13,'Salary Map'!A:D,4,FALSE),"Salary Code Not Mapped") -> General | AH13: =IFERROR(VLOOKUP(AA13,'Salary Map'!A:E,5,FALSE),"Invoice Approval Not Mapped") -> 0 | AI13: =IFERROR(VLOOKUP(Z13,'Country Map'!A:B,2,FALSE),"Legal Country Not Mapped") -> US | AJ13: =IFERROR(VLOOKUP(X13,'Language Map'!A:C,3,FALSE),IFERROR(VLOOKUP(T13,'Org Map'!A:F,6,FALSE),"ADP and BU Language Code Not Mapped"))&AI13 -> en_US | AK13: =IFERROR(VLOOKUP(T13,'Org Map'!A:G,7),"BU Currency Not Mapped") -> USD | AL13: =IF(ISBLANK(E13),"",TRIM(E13&" "&F13)) | AM13: =IFERROR(VLOOKUP(O13,'Status Map'!A:B,2,FALSE),"Position Status Not Mapped") -> Y | AN13: =IF(AM13="N",TEXT(M13,"yyyymmdd"),"") | AO13: =IFERROR(VLOOKUP(P13,'Invoice Exception Map'!A:C,3,FALSE),IF(AH13>0,"Y","N")) -> N
A14: V0U | B14: Natalie | D14: Bate | G14: Bair, Teresa | H14: KSY207709 | I14: nbate@onebarnes.com | J14: natalie.m.bate@gmail.com | K14: Mgr, Division II | L14: 46083 | O14: Active | P14: 213037 | Q14: Monthly | R14: Full Time | S14: 025 | T14: 025-NGP Hyson Products | U14: Administration | V14: 000917 | W14: Hyson Products | Z14: USA | AA14: S19 | AB14: FMG-S19 | AC14: =IF(ISBLANK(H14),VLOOKUP(P14,'Invoice Exception Map'!A:D,4,FALSE),MID(H14,4,6)) -> 207709 | AD14: =IFERROR(VLOOKUP(T14,'Org Map'!A:E,4),"BU Description Not Mapped") -> 0096 | AE14: =IFERROR(VLOOKUP(V14,'Org Map'!C:E,3,FALSE),"Home Department Code Not Mapped") -> 917 | AF14: =IFERROR(VLOOKUP(AA14,'Salary Map'!A:D,3,FALSE),"Salary Code Not Mapped") -> Default | AG14: =IFERROR(VLOOKUP(AA14,'Salary Map'!A:D,4,FALSE),"Salary Code Not Mapped") -> General | AH14: =IFERROR(VLOOKUP(AA14,'Salary Map'!A:E,5,FALSE),"Invoice Approval Not Mapped") -> 100000 | AI14: =IFERROR(VLOOKUP(Z14,'Country Map'!A:B,2,FALSE),"Legal Country Not Mapped") -> US | AJ14: =IFERROR(VLOOKUP(X14,'Language Map'!A:C,3,FALSE),IFERROR(VLOOKUP(T14,'Org Map'!A:F,6,FALSE),"ADP and BU Language Code Not Mapped"))&AI14 -> en_US | AK14: =IFERROR(VLOOKUP(T14,'Org Map'!A:G,7),"BU Currency Not Mapped") -> USD | AL14: =IF(ISBLANK(E14),"",TRIM(E14&" "&F14)) | AM14: =IFERROR(VLOOKUP(O14,'Status Map'!A:B,2,FALSE),"Position Status Not Mapped") -> Y | AN14: =IF(AM14="N",TEXT(M14,"yyyymmdd"),"") | AO14: =IFERROR(VLOOKUP(P14,'Invoice Exception Map'!A:C,3,FALSE),IF(AH14>0,"Y","N")) -> Y
