Workbook

Sheet PLP05
A1: Supplier | B1: Column1
A2: AAA001 | B2: =VLOOKUP(A2,Sheet1!A:A,1,0) -> AAA001
A3: AAASTAMP | B3: =VLOOKUP(A3,Sheet1!A:A,1,0) -> AAASTAMP
A4: ABBT01 | B4: =VLOOKUP(A4,Sheet1!A:A,1,0) -> ABBT01
A5: ACCMFG | B5: =VLOOKUP(A5,Sheet1!A:A,1,0) -> ACCMFG
A6: ACCUTURN | B6: =VLOOKUP(A6,Sheet1!A:A,1,0) -> ACCUTURN
A7: ACOM01 | B7: =VLOOKUP(A7,Sheet1!A:A,1,0) -> ACOM01
A8: ACTTEST | B8: =VLOOKUP(A8,Sheet1!A:A,1,0) -> ACTTEST
A9: ADCONSUL | B9: =VLOOKUP(A9,Sheet1!A:A,1,0) -> ADCONSUL
A10: ADECCO | B10: =VLOOKUP(A10,Sheet1!A:A,1,0) -> ADECCO
A11: ADVANCEH | B11: =VLOOKUP(A11,Sheet1!A:A,1,0) -> ADVANCEH
A12: ADVANTAG | B12: =VLOOKUP(A12,Sheet1!A:A,1,0) -> ADVANTAG
A13: AER001 | B13: =VLOOKUP(A13,Sheet1!A:A,1,0) -> AER001
... A311: YOST | B311: =VLOOKUP(A311,Sheet1!A:A,1,0) -> YOST

Sheet SupplierMasterList
A1: Supplier | B1: SUNO
A2: IGS | B2: 10001 | D2: start with 2
A3: SUMAX | B3: 10002
A4: NING70 | B4: 10003
A5: ASBRAZIL | B5: 10004
A6: LDK | B6: 10005
A7: RAINBOW | B7: 10006
A8: XIAMEN | B8: 10007
A9: SUNZO | B9: 10008
A10: DURABLE | B10: 10009
A11: FANGXING | B11: 10010
A12: LONGXIAN | B12: 10011
A13: CREATCOM | B13: 10012
A14: PROHOS | B14: 10013
... A445: REFKNT | B445: 10444

Sheet Sheet1
A1: SUPN05 | B1: SUNO | C1: SUCL | D1: ORTY | E1: TEDL | F1: MODL | G1: CFI1 | H1: BUYE
A2: RAINBOW | B2: 20001 | C2: ZZZ | D2: D01 | E2: FOB | F2: 001 | H2: USSXU
A3: IGS | B3: 20002 | C3: INT | D3: D01 | E3: FOB | F3: 001 | G3: INT0218 | H3: USSPATE
A4: NING70 | B4: 20003 | C4: ZZZ | D4: D01 | E4: FOB | F4: 001 | H4: USAPALI
A5: SUMAX | B5: 20004 | C5: ZZZ | D5: D01 | E5: FOB | F5: 001 | H5: USAPALI
A6: PROHOS | B6: 20005 | C6: ZZZ | D6: D01 | E6: DAP | F6: 003 | H6: USAPALI
A7: COHESION | B7: 20006 | C7: ZZZ | D7: D01 | E7: FOB | F7: 001 | H7: USKOUTH
A8: DURABLE | B8: 20007 | C8: ZZZ | D8: D01 | E8: FOB | F8: 001 | H8: USKOUTH
A9: SUNZO | B9: 20008 | C9: ZZZ | D9: D01 | E9: FOB | F9: 001 | H9: USSXU
A10: KAPCO | B10: 20009 | C10: ZZZ | D10: D01 | E10: FOB | F10: 001
A11: LDK | B11: 20010 | C11: ZZZ | D11: D01 | E11: FOB | F11: 001 | H11: USAPALI
A12: REMESA | B12: 20011 | C12: ZZZ | D12: D01 | E12: DAP | F12: 003 | H12: USSXU
A13: LONGXIAN | B13: 20012 | C13: ZZZ | D13: D01 | E13: FOB | F13: 001 | H13: USSPATE
A14: MAR002 | B14: 20013 | C14: ZZZ | D14: D01 | E14: DAP | F14: 003 | H14: USAPALI
A15: STU001 | B15: 20014 | C15: ZZZ | D15: D01 | E15: FOB | F15: 001
A16: XIAMEN | B16: 20015 | C16: ZZZ | D16: D01 | E16: FOB | F16: 001 | H16: USAPALI
A17: PENGCHEN | B17: 20016 | C17: ZZZ | D17: D01 | E17: FOB | F17: 001 | H17: USAPALI
A18: MEGAHOO | B18: 20017 | C18: ZZZ | D18: D01 | E18: FOB | F18: 001 | H18: ???
A19: HUBBARD | B19: 20018 | C19: ZZZ | D19: D01 | E19: DAP | F19: 003 | H19: USSXU
A20: POL001 | B20: 20019 | C20: ZZZ | D20: D01 | E20: DAP | F20: 003 | H20: USAPALI
A21: ASTIANJ | B21: 20020 | C21: ZZZ | D21: D01 | E21: FOB | F21: 001 | H21: USAPALI
A22: MINICUT | B22: 20021 | C22: ZZZ | D22: D01 | E22: FOB | F22: 001 | H22: USAPALI
A23: SCH001 | B23: 20022 | C23: ZZZ | D23: D01 | E23: DAP | F23: 003 | H23: USSXU
A24: SCH002 | B24: 20023 | C24: ZZZ | D24: D01 | E24: DAP | F24: 003 | H24: USSXU
A25: SPRAY | B25: 20024 | C25: SUB | D25: D70 | E25: DAP | F25: 003
A26: NEWLAND | B26: 20025 | C26: ZZZ | D26: D01 | E26: FOB | F26: 001 | H26: USAPALI
A27: MAR001 | B27: 20026 | C27: ZZZ | D27: D01 | E27: DAP | F27: 003
A28: KALLER | B28: 20027 | C28: INT | D28: D01 | E28: DAP | F28: 003 | G28: INT0096
A29: OLYMCO | B29: 20028 | C29: SUB | D29: D70 | E29: DAP | F29: 003
A30: IPSGROUP | B30: 20029 | C30: SUB | D30: D70 | E30: DAP | F30: 003
A31: PAC003 | B31: 20030 | C31: MRO | D31: D04 | E31: DAP | F31: 003
A32: ASTI | B32: 20031 | C32: ZZZ | D32: D01 | E32: DAP | F32: 003 | H32: USAPALI
A33: TECUMSEH | B33: 20032 | C33: MRO | D33: D04 | E33: DAP | F33: 003
A34: WELCH | B34: 20033 | C34: MRO | D34: D04 | E34: DAP | F34: 003
A35: SEEGER | B35: 20034 | C35: ZZZ | D35: D01 | E35: FOB | F35: 001
A36: CROWNLIF | B36: 20035 | C36: MRO | D36: D04 | E36: DAP | F36: 003
A37: ALL001 | B37: 20036 | C37: SUB | D37: D70 | E37: DAP | F37: 003
A38: NOVI | B38: 20037 | C38: ZZZ | D38: D01 | E38: DAP | F38: 003
A39: CARRDAN | B39: 20038 | C39: ZZZ | D39: D01 | E39: DAP | F39: 003
A40: CREATCOM | B40: 20039 | C40: ZZZ | D40: D01 | E40: FOB | F40: 001 | H40: USAPALI
...
